Workbook

Sheet HSD Consumption Master Seet
A1: HSD CONSUMPTION REPORT
A2: MONTH :- | C2: 46235 | E2: RIG NAME :- | G2: GTC-100-1
B3: OPERATIONAL HOURS | G3: Rig Carrier CAT (C-15) | J3: Mud Pump CAT (C-15) | M3: DG SET -1 (125 KVA SUPERNOVA) | P3: DG SET -2 ( 125 KVA SUPERNOVA) | S3: DG SET- 3 (30 KVA SUPERNOVA) | V3: Electrical Air Compressor (Kirloskar) | Y3: Fire Pump (Kirloskar) | AB3: Water Tanker (GJ-08 v - 2430) | AE3: Water Tanker (GJ-18-AZ-1825) | AH3: WATER TANKER ( GJ-01-BY-5368) | AK3: OTHERS (CLEANING & SERVICING) | AL3: TRANSFERRED
A4: Date | B4: R1 | C4: R2 | D4: R3 | E4: ILM/IPM | F4: TOTAL HOURS | G4: Total Consu. HSD | H4: Total running HRS | I4: Day Average | J4: Total Consu. HSD | K4: Total running HRS | L4: Day Average | M4: Total Consu. HSD | N4: Total running HRS | O4: Day Average | P4: Total Consu. HSD | Q4: Total running HRS | R4: Day Average | S4: Total Consu. HSD | T4: Total running HRS | U4: Day Average | V4: Total Consu. HSD | W4: Total running HRS | X4: Day Average | Y4: Total Consu. HSD | Z4: Total running HRS | AA4: Day Average | AB4: Total Consu. HSD | AC4: Total running HRS | AD4: Day Average | AE4: Total Consu. HSD | AF4: Total running HRS | AG4: Day Average | AH4: Total Consu. HSD | AI4: Total running HRS | AJ4: Day Average | AK4: Total Consu. HSD | AL4: Total Consu. HSD | AM4: Total Consu. HSD | AN4: Total running HRS | AO4: Day Average | AP4: TRANSFER GTC 200-01 | AQ4: Total running HRS | AR4: Day Average | AS4: Total Consu. HSD | AT4: Total Consu. HSD | AU4: Total running HRS | AV4: Day Average | AW4: Total Consu. HSD | AX4: Total running HRS | AY4: Day Average | AZ4: Total Consu. HSD | BA4: Total running HRS | BB4: Day Average | BC4: Total Consu. HSD | BD4: Total running HRS | BE4: Day Average | BF4: Total Consu. HSD | BG4: Total running HRS | BH4: Day Average | BI4: Total Consu. HSD | BJ4: Total running HRS | BK4: Day Average | BL4: RIG CONSUMPTION | BM4: TOTAL CONSUMPTION
A5: 46235 | B5: ='1'!C4 -> 7.5 | C5: ='1'!D4 -> 9.5 | D5: ='1'!E4 -> 0 | E5: ='1'!F4 -> 0 | F5: =SUM(B5:E5) -> 17 | G5: ='1'!E6 -> 22 | H5: ='1'!F6 -> 3.5 | I5: =G5/H5 -> 6.2857143 | J5: ='1'!E7 -> 78 | K5: ='1'!F7 -> 5.5 | L5: =J5/K5 -> 14.181818 | M5: ='1'!E8 -> 0 | N5: ='1'!F8 -> 0 | O5: =AVERAGE(M5/N5) -> #DIV/0! | P5: ='1'!E9 -> 144 | Q5: ='1'!F9 -> 24 | R5: =AVERAGE(P5/Q5) -> 6 | S5: ='1'!E10 -> 0 | T5: ='1'!F10 -> 0 | U5: =AVERAGE(S5/T5) -> #DIV/0! | V5: ='1'!E11 -> 0 | W5: ='1'!F11 -> 0 | X5: =V5/W5 -> #DIV/0! | Y5: ='1'!E12 -> 0 | Z5: ='1'!F12 -> 0 | AA5: =Y5/Z5 -> #DIV/0! | AB5: ='1'!E13 -> 0 | AC5: ='1'!F13 -> 0 | AD5: =AB5/AC5 -> #DIV/0! | AE5: ='1'!E14 -> 0 | AF5: ='1'!F14 -> 0 | AG5: =AE5/AF5 -> #DIV/0! | AH5: ='1'!E15 -> 0 | AI5: ='1'!F15 -> 0 | AJ5: =AH5/AI5 -> #DIV/0! | AK5: ='1'!E16 -> 10 | AL5: ='1'!E17 -> 0 | AM5: ='1'!E18 -> 0 | AN5: ='1'!F18 -> 0 | AO5: =AM5/AN5 -> #DIV/0! | AP5: ='1'!E19 -> 0 | AQ5: ='1'!F19 -> 0 | AR5: =AP5/AQ5 -> #DIV/0! | AS5: ='1'!E20 -> 0 | AT5: ='1'!E21 -> 0 | AU5: ='1'!F21 -> 0 | AV5: =AT5/AU5 -> #DIV/0! | AW5: ='1'!E22 -> 0 | AX5: ='1'!F22 -> 0 | AY5: =AW5/AX5 -> #DIV/0! | AZ5: ='1'!E23 -> 0 | BA5: ='1'!F23 -> 0 | BB5: =AZ5/BA5 -> #DIV/0! | BC5: ='1'!E24 -> 0 | BD5: ='1'!F24 -> 0 | BE5: =BC5/BD5 -> #DIV/0! | BF5: ='1'!E25 -> 0 | BG5: ='1'!F25 -> 0 | BH5: =BF5/BG5 -> #DIV/0! | BI5: ='1'!E26 -> 0 | BJ5: ='1'!F26 -> 0 | BK5: =BI5/BJ5 -> #DIV/0! | BL5: =G5+J5+M5+P5+S5+V5+Y5 -> 244 | BM5: =BL5+BI5+BF5+BC5+AZ5+AW5+AS5+AP5+AM5+AL5+AK5+AH5+AE5+AB5 -> 254
A6: 46236 | B6: ='2'!C4 -> 20 | C6: ='2'!D4 -> 4 | D6: ='2'!E4 -> 0 | E6: ='2'!F4 -> 0 | F6: =SUM(B6:E6) -> 24 | G6: ='2'!E6 -> 135 | H6: ='2'!F6 -> 18 | I6: =G6/H6 -> 7.5 | J6: ='2'!E7 -> 80 | K6: ='2'!F7 -> 4.5 | L6: =J6/K6 -> 17.777778 | M6: ='2'!E8 -> 0 | N6: ='2'!F8 -> 0 | O6: =AVERAGE(M6/N6) -> #DIV/0! | P6: ='2'!E9 -> 143 | Q6: ='2'!F9 -> 24 | R6: =AVERAGE(P6/Q6) -> 5.9583333 | S6: ='2'!E10 -> 0 | T6: ='2'!F10 -> 0 | U6: =AVERAGE(S6/T6) -> #DIV/0! | V6: ='2'!E11 -> 0 | W6: ='2'!F11 -> 0 | X6: =V6/W6 -> #DIV/0! | Y6: ='2'!E12 -> 3 | Z6: ='2'!F12 -> 1 | AA6: =Y6/Z6 -> 3 | AB6: ='2'!E13 -> 0 | AC6: ='2'!F13 -> 0 | AD6: =AB6/AC6 -> #DIV/0! | AE6: ='2'!E14 -> 0 | AF6: ='2'!F14 -> 0 | AG6: =AE6/AF6 -> #DIV/0! | AH6: ='2'!E15 -> 0 | AI6: ='2'!F15 -> 0 | AJ6: =AH6/AI6 -> #DIV/0! | AK6: ='2'!E16 -> 0 | AL6: ='2'!E17 -> 0 | AM6: ='2'!E18 -> 0 | AN6: ='2'!F18 -> 0 | AO6: =AM6/AN6 -> #DIV/0! | AP6: ='2'!E19 -> 0 | AQ6: ='2'!F19 -> 0 | AR6: =AP6/AQ6 -> #DIV/0! | AS6: ='2'!E20 -> 0 | AT6: ='2'!E21 -> 0 | AU6: ='2'!F21 -> 0 | AV6: =AT6/AU6 -> #DIV/0! | AW6: ='2'!E22 -> 0 | AX6: ='2'!F22 -> 0 | AY6: =AW6/AX6 -> #DIV/0! | AZ6: ='2'!E23 -> 0 | BA6: ='2'!F23 -> 0 | BB6: =AZ6/BA6 -> #DIV/0! | BC6: ='2'!E24 -> 0 | BD6: ='2'!F24 -> 0 | BE6: =BC6/BD6 -> #DIV/0! | BF6: ='2'!E25 -> 0 | BG6: ='2'!F25 -> 0 | BH6: =BF6/BG6 -> #DIV/0! | BI6: ='2'!E26 -> 0 | BJ6: ='2'!F26 -> 0 | BK6: =BI6/BJ6 -> #DIV/0! | BL6: =G6+J6+M6+P6+S6+V6+Y6 -> 361 | BM6: =BL6+BI6+BF6+BC6+AZ6+AW6+AS6+AP6+AM6+AL6+AK6+AH6+AE6+AB6 -> 361
A7: 46237 | B7: ='3'!C4 -> 7.5 | C7: ='3'!D4 -> 1 | D7: ='3'!E4 -> 15.5 | E7: ='3'!F4 -> 0 | F7: =SUM(B7:E7) -> 24 | G7: ='3'!E6 -> 58 | H7: ='3'!F6 -> 10 | I7: =G7/H7 -> 5.8 | J7: ='3'!E7 -> 0 | K7: ='3'!F7 -> 0 | L7: =J7/K7 -> #DIV/0! | M7: ='3'!E8 -> 0 | N7: ='3'!F8 -> 0 | O7: =AVERAGE(M7/N7) -> #DIV/0! | P7: ='3'!E9 -> 150 | Q7: ='3'!F9 -> 24 | R7: =AVERAGE(P7/Q7) -> 6.25 | S7: ='3'!E10 -> 0 | T7: ='3'!F10 -> 0 | U7: =AVERAGE(S7/T7) -> #DIV/0! | V7: ='3'!E11 -> 0 | W7: ='3'!F11 -> 0 | X7: =V7/W7 -> #DIV/0! | Y7: ='3'!E12 -> 0 | Z7: ='3'!F12 -> 0 | AA7: =Y7/Z7 -> #DIV/0! | AB7: ='3'!E13 -> 0 | AC7: ='3'!F13 -> 0 | AD7: =AB7/AC7 -> #DIV/0! | AE7: ='3'!E14 -> 0 | AF7: ='3'!F14 -> 0 | AG7: =AE7/AF7 -> #DIV/0! | AH7: ='3'!E15 -> 0 | AI7: ='3'!F15 -> 0 | AJ7: =AH7/AI7 -> #DIV/0! | AK7: ='3'!E16 -> 0 | AL7: ='3'!E17 -> 0 | AM7: ='3'!E18 -> 0 | AN7: ='3'!F18 -> 0 | AO7: =AM7/AN7 -> #DIV/0! | AP7: ='3'!E19 -> 0 | AQ7: ='3'!F19 -> 0 | AR7: =AP7/AQ7 -> #DIV/0! | AS7: ='3'!E20 -> 0 | AT7: ='3'!E21 -> 0 | AU7: ='3'!F21 -> 0 | AV7: =AT7/AU7 -> #DIV/0! | AW7: ='3'!E22 -> 0 | AX7: ='3'!F22 -> 0 | AY7: =AW7/AX7 -> #DIV/0! | AZ7: ='3'!E23 -> 0 | BA7: ='3'!F23 -> 0 | BB7: =AZ7/BA7 -> #DIV/0! | BC7: ='3'!E24 -> 0 | BD7: ='3'!F24 -> 0 | BE7: =BC7/BD7 -> #DIV/0! | BF7: ='3'!E25 -> 0 | BG7: ='3'!F25 -> 0 | BH7: =BF7/BG7 -> #DIV/0! | BI7: ='3'!E26 -> 0 | BJ7: ='3'!F26 -> 0 | BK7: =BI7/BJ7 -> #DIV/0! | BL7: =G7+J7+M7+P7+S7+V7+Y7 -> 208 | BM7: =BL7+BI7+BF7+BC7+AZ7+AW7+AS7+AP7+AM7+AL7+AK7+AH7+AE7+AB7 -> 208
A8: 46238 | B8: ='4'!C4 -> 12.5 | C8: ='4'!D4 -> 9 | D8: ='4'!E4 -> 2.5 | E8: ='4'!F4 -> 0 | F8: =SUM(B8:E8) -> 24 | G8: ='4'!E6 -> 110 | H8: ='4'!F6 -> 18 | I8: =G8/H8 -> 6.1111111 | J8: ='4'!E7 -> 75 | K8: ='4'!F7 -> 6 | L8: =J8/K8 -> 12.5 | M8: ='4'!E8 -> 70 | N8: ='4'!F8 -> 12 | O8: =AVERAGE(M8/N8) -> 5.8333333 | P8: ='4'!E9 -> 74 | Q8: ='4'!F9 -> 12 | R8: =AVERAGE(P8/Q8) -> 6.1666667 | S8: ='4'!E10 -> 0 | T8: ='4'!F10 -> 0 | U8: =AVERAGE(S8/T8) -> #DIV/0! | V8: ='4'!E11 -> 0 | W8: ='4'!F11 -> 0 | X8: =V8/W8 -> #DIV/0! | Y8: ='4'!E12 -> 3 | Z8: ='4'!F12 -> 1 | AA8: =Y8/Z8 -> 3 | AB8: ='4'!E13 -> 0 | AC8: ='4'!F13 -> 0 | AD8: =AB8/AC8 -> #DIV/0! | AE8: ='4'!E14 -> 0 | AF8: ='4'!F14 -> 0 | AG8: =AE8/AF8 -> #DIV/0! | AH8: ='4'!E15 -> 0 | AI8: ='4'!F15 -> 0 | AJ8: =AH8/AI8 -> #DIV/0! | AK8: ='4'!E16 -> 0 | AL8: ='4'!E17 -> 0 | AM8: ='4'!E18 -> 0 | AN8: ='4'!F18 -> 0 | AO8: =AM8/AN8 -> #DIV/0! | AP8: ='4'!E19 -> 0 | AQ8: ='4'!F19 -> 0 | AR8: =AP8/AQ8 -> #DIV/0! | AS8: ='4'!E20 -> 0 | AT8: ='4'!E21 -> 0 | AU8: ='4'!F21 -> 0 | AV8: =AT8/AU8 -> #DIV/0! | AW8: ='4'!E22 -> 0 | AX8: ='4'!F22 -> 0 | AY8: =AW8/AX8 -> #DIV/0! | AZ8: ='4'!E23 -> 0 | BA8: ='4'!F23 -> 0 | BB8: =AZ8/BA8 -> #DIV/0! | BC8: ='4'!E24 -> 0 | BD8: ='4'!F24 -> 0 | BE8: =BC8/BD8 -> #DIV/0! | BF8: ='4'!E25 -> 0 | BG8: ='4'!F25 -> 0 | BH8: =BF8/BG8 -> #DIV/0! | BI8: ='4'!E26 -> 0 | BJ8: ='4'!F26 -> 0 | BK8: =BI8/BJ8 -> #DIV/0! | BL8: =G8+J8+M8+P8+S8+V8+Y8 -> 332 | BM8: =BL8+BI8+BF8+BC8+AZ8+AW8+AS8+AP8+AM8+AL8+AK8+AH8+AE8+AB8 -> 332
A9: 46239 | B9: ='5'!C4 -> 13.5 | C9: ='5'!D4 -> 10.5 | D9: ='5'!E4 -> 0 | E9: ='5'!F4 -> 0 | F9: =SUM(B9:E9) -> 24 | G9: ='5'!E6 -> 105 | H9: ='5'!F6 -> 15 | I9: =G9/H9 -> 7 | J9: ='5'!E7 -> 0 | K9: ='5'!F7 -> 0 | L9: =J9/K9 -> #DIV/0! | M9: ='5'!E8 -> 148 | N9: ='5'!F8 -> 24 | O9: =AVERAGE(M9/N9) -> 6.1666667 | P9: ='5'!E9 -> 0 | Q9: ='5'!F9 -> 0 | R9: =AVERAGE(P9/Q9) -> #DIV/0! | S9: ='5'!E10 -> 0 | T9: ='5'!F10 -> 0 | U9: =AVERAGE(S9/T9) -> #DIV/0! | V9: ='5'!E12 -> 0 | W9: ='5'!F12 -> 0 | X9: =V9/W9 -> #DIV/0! | Y9: ='5'!E13 -> 0 | Z9: ='5'!F13 -> 0 | AA9: =Y9/Z9 -> #DIV/0! | AB9: ='5'!E14 -> 0 | AC9: ='5'!F14 -> 0 | AD9: =AB9/AC9 -> #DIV/0! | AE9: ='5'!E15 -> 0 | AF9: ='5'!F15 -> 0 | AG9: =AE9/AF9 -> #DIV/0! | AH9: ='5'!E16 -> 0 | AI9: ='5'!F16 -> 0 | AJ9: =AH9/AI9 -> #DIV/0! | AK9: ='5'!E17 -> 0 | AL9: ='5'!E18 -> 0 | AM9: ='5'!E19 -> 0 | AN9: ='5'!F19 -> 0 | AO9: =AM9/AN9 -> #DIV/0! | AP9: ='5'!E20 -> 0 | AQ9: ='5'!F20 -> 0 | AR9: =AP9/AQ9 -> #DIV/0! | AS9: ='5'!E21 -> 0 | AT9: ='5'!E22 -> 0 | AU9: ='5'!F22 -> 0 | AV9: =AT9/AU9 -> #DIV/0! | AW9: ='5'!E23 -> 0 | AX9: ='5'!F23 -> 0 | AY9: =AW9/AX9 -> #DIV/0! | AZ9: ='5'!E24 -> 0 | BA9: ='5'!F24 -> 0 | BB9: =AZ9/BA9 -> #DIV/0! | BC9: ='5'!E25 -> 0 | BD9: ='5'!F25 -> 0 | BE9: =BC9/BD9 -> #DIV/0! | BF9: ='5'!E26 -> 0 | BG9: ='5'!F26 -> 0 | BH9: =BF9/BG9 -> #DIV/0! | BI9: ='5'!E27 -> 0 | BJ9: ='5'!F27 -> 0 | BK9: =BI9/BJ9 -> #DIV/0! | BL9: =G9+J9+M9+P9+S9+V9+Y9 -> 253 | BM9: =BL9+BI9+BF9+BC9+AZ9+AW9+AS9+AP9+AM9+AL9+AK9+AH9+AE9+AB9 -> 253
A10: 46240 | B10: ='6'!C4 -> 0 | C10: ='6'!D4 -> 1 | D10: ='6'!E4 -> 23 | E10: ='6'!F4 -> 0 | F10: =SUM(B10:E10) -> 24 | G10: ='6'!E6 -> 12 | H10: ='6'!F6 -> 2 | I10: =G10/H10 -> 6 | J10: ='6'!E7 -> 0 | K10: ='6'!F7 -> 0 | L10: =J10/K10 -> #DIV/0! | M10: ='6'!E8 -> 0 | N10: ='6'!F8 -> 0 | O10: =AVERAGE(M10/N10) -> #DIV/0! | P10: ='6'!E9 -> 155 | Q10: ='6'!F9 -> 24 | R10: =AVERAGE(P10/Q10) -> 6.4583333 | S10: ='6'!E10 -> 0 | T10: ='6'!F10 -> 0 | U10: =AVERAGE(S10/T10) -> #DIV/0! | V10: ='6'!E11 -> 0 | W10: ='6'!F11 -> 0 | X10: =V10/W10 -> #DIV/0! | Y10: ='6'!E12 -> 0 | Z10: ='6'!F12 -> 0 | AA10: =Y10/Z10 -> #DIV/0! | AB10: ='6'!E13 -> 0 | AC10: ='6'!F13 -> 0 | AD10: =AB10/AC10 -> #DIV/0! | AE10: ='6'!E14 -> 0 | AF10: ='6'!F14 -> 0 | AG10: =AE10/AF10 -> #DIV/0! | AH10: ='6'!E15 -> 0 | AI10: ='6'!F15 -> 0 | AJ10: =AH10/AI10 -> #DIV/0! | AK10: ='6'!E16 -> 0 | AL10: ='6'!E17 -> 0 | AM10: ='6'!E18 -> 0 | AN10: ='6'!F18 -> 0 | AO10: =AM10/AN10 -> #DIV/0! | AP10: ='6'!E19 -> 0 | AQ10: ='6'!F19 -> 0 | AR10: =AP10/AQ10 -> #DIV/0! | AS10: ='6'!E20 -> 0 | AT10: ='6'!E21 -> 0 | AU10: ='6'!F21 -> 0 | AV10: =AT10/AU10 -> #DIV/0! | AW10: ='6'!E22 -> 0 | AX10: ='6'!F22 -> 0 | AY10: =AW10/AX10 -> #DIV/0! | AZ10: ='6'!E23 -> 0 | BA10: ='6'!F23 -> 0 | BB10: =AZ10/BA10 -> #DIV/0! | BC10: ='6'!E24 -> 0 | BD10: ='6'!F24 -> 0 | BE10: =BC10/BD10 -> #DIV/0! | BF10: ='6'!E25 -> 0 | BG10: ='6'!F25 -> 0 | BH10: =BF10/BG10 -> #DIV/0! | BI10: ='6'!E26 -> 0 | BJ10: ='6'!F26 -> 0 | BK10: =BI10/BJ10 -> #DIV/0! | BL10: =G10+J10+M10+P10+S10+V10+Y10 -> 167 | BM10: =BL10+BI10+BF10+BC10+AZ10+AW10+AS10+AP10+AM10+AL10+AK10+AH10+AE10+AB10 -> 167
A11: 46241 | B11: ='7'!C4 -> 19.5 | C11: ='7'!D4 -> 1 | D11: ='7'!E4 -> 3.5 | E11: ='7'!F4 -> 0 | F11: =SUM(B11:E11) -> 24 | G11: ='7'!E6 -> 130 | H11: ='7'!F6 -> 20.5 | I11: =G11/H11 -> 6.3414634 | J11: ='7'!E7 -> 60 | K11: ='7'!F7 -> 3.5 | L11: =J11/K11 -> 17.142857 | M11: ='7'!E8 -> 148 | N11: ='7'!F8 -> 24 | O11: =AVERAGE(M11/N11) -> 6.1666667 | P11: ='7'!E9 -> 0 | Q11: ='7'!F9 -> 0 | R11: =AVERAGE(P11/Q11) -> #DIV/0! | S11: ='7'!E10 -> 0 | T11: ='7'!F10 -> 0 | U11: =AVERAGE(S11/T11) -> #DIV/0! | V11: ='7'!E12 -> 0 | W11: ='7'!F12 -> 0 | X11: =V11/W11 -> #DIV/0! | Y11: ='7'!E13 -> 0 | Z11: ='7'!F13 -> 0 | AA11: =Y11/Z11 -> #DIV/0! | AB11: ='7'!E14 -> 0 | AC11: ='7'!F14 -> 0 | AD11: =AB11/AC11 -> #DIV/0! | AE11: ='7'!E15 -> 0 | AF11: ='7'!F15 -> 0 | AG11: =AE11/AF11 -> #DIV/0! | AH11: ='7'!E16 -> 0 | AI11: ='7'!F16 -> 0 | AJ11: =AH11/AI11 -> #DIV/0! | AK11: ='7'!E17 -> 0 | AL11: ='7'!E18 -> 0 | AM11: ='7'!E19 -> 0 | AN11: ='7'!F19 -> 0 | AO11: =AM11/AN11 -> #DIV/0! | AP11: ='7'!E20 -> 0 | AQ11: ='7'!F20 -> 0 | AR11: =AP11/AQ11 -> #DIV/0! | AS11: ='7'!E21 -> 0 | AT11: ='7'!E22 -> 0 | AU11: ='7'!F22 -> 0 | AV11: =AT11/AU11 -> #DIV/0! | AW11: ='7'!E23 -> 0 | AX11: ='7'!F23 -> 0 | AY11: =AW11/AX11 -> #DIV/0! | AZ11: ='7'!E24 -> 0 | BA11: ='7'!F24 -> 0 | BB11: =AZ11/BA11 -> #DIV/0! | BC11: ='7'!E25 -> 0 | BD11: ='7'!F25 -> 0 | BE11: =BC11/BD11 -> #DIV/0! | BF11: ='7'!E26 -> 0 | BG11: ='7'!F26 -> 0 | BH11: =BF11/BG11 -> #DIV/0! | BI11: ='7'!E27 -> 0 | BJ11: ='7'!F27 -> 0 | BK11: =BI11/BJ11 -> #DIV/0! | BL11: =G11+J11+M11+P11+S11+V11+Y11 -> 338 | BM11: =BL11+BI11+BF11+BC11+AZ11+AW11+AS11+AP11+AM11+AL11+AK11+AH11+AE11+AB11 -> 338
A12: 46242 | B12: ='8'!C4 -> 14.5 | C12: ='8'!D4 -> 1 | D12: ='8'!E4 -> 8.5 | E12: ='8'!F4 -> 0 | F12: =SUM(B12:E12) -> 24 | G12: ='8'!E6 -> 190 | H12: ='8'!F6 -> 22 | I12: =G12/H12 -> 8.6363636 | J12: ='8'!E7 -> 155 | K12: ='8'!F7 -> 8.5 | L12: =J12/K12 -> 18.235294 | M12: ='8'!E8 -> 0 | N12: ='8'!F8 -> 0 | O12: =AVERAGE(M12/N12) -> #DIV/0! | P12: ='8'!E9 -> 148 | Q12: ='8'!F9 -> 24 | R12: =AVERAGE(P12/Q12) -> 6.1666667 | S12: ='8'!E10 -> 0 | T12: ='8'!F10 -> 0 | U12: =AVERAGE(S12/T12) -> #DIV/0! | V12: ='8'!E12 -> 0 | W12: ='8'!F12 -> 0 | X12: =V12/W12 -> #DIV/0! | Y12: ='8'!E13 -> 3 | Z12: ='8'!F13 -> 1 | AA12: =Y12/Z12 -> 3 | AB12: ='8'!E14 -> 0 | AC12: ='8'!F14 -> 0 | AD12: =AB12/AC12 -> #DIV/0! | AE12: ='8'!E15 -> 0 | AF12: ='8'!F15 -> 0 | AG12: =AE12/AF12 -> #DIV/0! | AH12: ='8'!E16 -> 0 | AI12: ='8'!F16 -> 0 | AJ12: =AH12/AI12 -> #DIV/0! | AK12: ='8'!E17 -> 0 | AL12: ='8'!E18 -> 0 | AM12: ='8'!E19 -> 0 | AN12: ='8'!F19 -> 0 | AO12: =AM12/AN12 -> #DIV/0! | AP12: ='8'!E20 -> 0 | AQ12: ='8'!F20 -> 0 | AR12: =AP12/AQ12 -> #DIV/0! | AS12: ='8'!E21 -> 0 | AT12: ='8'!E22 -> 0 | AU12: ='8'!F22 -> 0 | AV12: =AT12/AU12 -> #DIV/0! | AW12: ='8'!E23 -> 0 | AX12: ='8'!F23 -> 0 | AY12: =AW12/AX12 -> #DIV/0! | AZ12: ='8'!E24 -> 0 | BA12: ='8'!F24 -> 0 | BB12: =AZ12/BA12 -> #DIV/0! | BC12: ='8'!E25 -> 0 | BD12: ='8'!F25 -> 0 | BE12: =BC12/BD12 -> #DIV/0! | BF12: ='8'!E26 -> 0 | BG12: ='8'!F26 -> 0 | BH12: =BF12/BG12 -> #DIV/0! | BI12: ='8'!E27 -> 0 | BJ12: ='8'!F27 -> 0 | BK12: =BI12/BJ12 -> #DIV/0! | BL12: =G12+J12+M12+P12+S12+V12+Y12 -> 496 | BM12: =BL12+BI12+BF12+BC12+AZ12+AW12+AS12+AP12+AM12+AL12+AK12+AH12+AE12+AB12 -> 496
A13: 46243 | B13: ='9'!C4 -> 15.25 | C13: ='9'!D4 -> 1.5 | D13: ='9'!E4 -> 7.25 | E13: ='9'!F4 -> 0 | F13: =SUM(B13:E13) -> 24 | G13: ='9'!E6 -> 138 | H13: ='9'!F6 -> 16.3 | I13: =G13/H13 -> 8.4662577 | J13: ='9'!E7 -> 292 | K13: ='9'!F7 -> 14.5 | L13: =J13/K13 -> 20.137931 | M13: ='9'!E8 -> 160 | N13: ='9'!F8 -> 24 | O13: =AVERAGE(M13/N13) -> 6.6666667 | P13: ='9'!E9 -> 0 | Q13: ='9'!F9 -> 0 | R13: =AVERAGE(P13/Q13) -> #DIV/0! | S13: ='9'!E10 -> 0 | T13: ='9'!F10 -> 0 | U13: =AVERAGE(S13/T13) -> #DIV/0! | V13: ='9'!E12 -> 0 | W13: ='9'!F12 -> 0 | X13: =V13/W13 -> #DIV/0! | Y13: ='9'!E13 -> 0 | Z13: ='9'!F13 -> 0 | AA13: =Y13/Z13 -> #DIV/0! | AB13: ='9'!E14 -> 0 | AC13: ='9'!F14 -> 0 | AD13: =AB13/AC13 -> #DIV/0! | AE13: ='9'!E15 -> 0 | AF13: ='9'!F15 -> 0 | AG13: =AE13/AF13 -> #DIV/0! | AH13: ='9'!E16 -> 0 | AI13: ='9'!F16 -> 0 | AJ13: =AH13/AI13 -> #DIV/0! | AK13: ='9'!E17 -> 0 | AL13: ='9'!E18 -> 0 | AM13: ='9'!E19 -> 0 | AN13: ='9'!F19 -> 0 | AO13: =AM13/AN13 -> #DIV/0! | AP13: ='9'!E20 -> 0 | AQ13: ='9'!F20 -> 0 | AR13: =AP13/AQ13 -> #DIV/0! | AS13: ='9'!E21 -> 0 | AT13: ='9'!E22 -> 0 | AU13: ='9'!F22 -> 0 | AV13: =AT13/AU13 -> #DIV/0! | AW13: ='9'!E23 -> 0 | AX13: ='9'!F23 -> 0 | AY13: =AW13/AX13 -> #DIV/0! | AZ13: ='9'!E24 -> 0 | BA13: ='9'!F24 -> 0 | BB13: =AZ13/BA13 -> #DIV/0! | BC13: ='9'!E25 -> 0 | BD13: ='9'!F25 -> 0 | BE13: =BC13/BD13 -> #DIV/0! | BF13: ='9'!E26 -> 0 | BG13: ='9'!F26 -> 0 | BH13: =BF13/BG13 -> #DIV/0! | BI13: ='9'!E27 -> 0 | BJ13: ='9'!F27 -> 0 | BK13: =BI13/BJ13 -> #DIV/0! | BL13: =G13+J13+M13+P13+S13+V13+Y13 -> 590 | BM13: =BL13+BI13+BF13+BC13+AZ13+AW13+AS13+AP13+AM13+AL13+AK13+AH13+AE13+AB13 -> 590
A14: 46244 | B14: ='10'!C4 -> 11 | C14: ='10'!D4 -> 2 | D14: ='10'!E4 -> 11 | E14: ='10'!F4 -> 0 | F14: =SUM(B14:E14) -> 24 | G14: ='10'!E6 -> 90 | H14: ='10'!F6 -> 14.5 | I14: =G14/H14 -> 6.2068966 | J14: ='10'!E7 -> 13 | K14: ='10'!F7 -> 1 | L14: =J14/K14 -> 13 | M14: ='10'!E8 -> 0 | N14: ='10'!F8 -> 0 | O14: =AVERAGE(M14/N14) -> #DIV/0! | P14: ='10'!E9 -> 144 | Q14: ='10'!F9 -> 24 | R14: =AVERAGE(P14/Q14) -> 6 | S14: ='10'!E10 -> 0 | T14: ='10'!F10 -> 0 | U14: =AVERAGE(S14/T14) -> #DIV/0! | V14: ='10'!E12 -> 0 | W14: ='10'!F12 -> 0 | X14: =V14/W14 -> #DIV/0! | Y14: ='10'!E13 -> 0 | Z14: ='10'!F13 -> 0 | AA14: =Y14/Z14 -> #DIV/0! | AB14: ='10'!E14 -> 0 | AC14: ='10'!F14 -> 0 | AD14: =AB14/AC14 -> #DIV/0! | AE14: ='10'!E15 -> 0 | AF14: ='10'!F15 -> 0 | AG14: =AE14/AF14 -> #DIV/0! | AH14: ='10'!E16 -> 0 | AI14: ='10'!F16 -> 0 | AJ14: =AH14/AI14 -> #DIV/0! | AK14: ='10'!E17 -> 0 | AL14: ='10'!E18 -> 0 | AM14: ='10'!E19 -> 0 | AN14: ='10'!F19 -> 0 | AO14: =AM14/AN14 -> #DIV/0! | AP14: ='10'!E20 -> 0 | AQ14: ='10'!F20 -> 0 | AR14: =AP14/AQ14 -> #DIV/0! | AS14: ='10'!E21 -> 0 | AT14: ='10'!E22 -> 0 | AU14: ='10'!F22 -> 0 | AV14: =AT14/AU14 -> #DIV/0! | AW14: ='10'!E23 -> 0 | AX14: ='10'!F23 -> 0 | AY14: =AW14/AX14 -> #DIV/0! | AZ14: ='10'!E24 -> 0 | BA14: ='10'!F24 -> 0 | BB14: =AZ14/BA14 -> #DIV/0! | BC14: ='10'!E25 -> 0 | BD14: ='10'!F25 -> 0 | BE14: =BC14/BD14 -> #DIV/0! | BF14: ='10'!E26 -> 0 | BG14: ='10'!F26 -> 0 | BH14: =BF14/BG14 -> #DIV/0! | BI14: ='10'!E27 -> 0 | BJ14: ='10'!F27 -> 0 | BK14: =BI14/BJ14 -> #DIV/0! | BL14: =G14+J14+M14+P14+S14+V14+Y14 -> 247 | BM14: =BL14+BI14+BF14+BC14+AZ14+AW14+AS14+AP14+AM14+AL14+AK14+AH14+AE14+AB14 -> 247
A15: 46245 | B15: ='11'!C4 -> 16 | C15: ='11'!D4 -> 1 | D15: ='11'!E4 -> 7 | E15: ='11'!F4 -> 0 | F15: =SUM(B15:E15) -> 24 | G15: ='11'!E6 -> 135 | H15: ='11'!F6 -> 18 | I15: =G15/H15 -> 7.5 | J15: ='11'!E7 -> 190 | K15: ='11'!F7 -> 10.5 | L15: =J15/K15 -> 18.095238 | M15: ='11'!E8 -> 150 | N15: ='11'!F8 -> 24 | O15: =AVERAGE(M15/N15) -> 6.25 | P15: ='11'!E9 -> 0 | Q15: ='11'!F9 -> 0 | R15: =AVERAGE(P15/Q15) -> #DIV/0! | S15: ='11'!E10 -> 0 | T15: ='11'!F10 -> 0 | U15: =AVERAGE(S15/T15) -> #DIV/0! | V15: ='11'!E12 -> 0 | W15: ='11'!F12 -> 0 | X15: =V15/W15 -> #DIV/0! | Y15: ='11'!E13 -> 0 | Z15: ='11'!F13 -> 0 | AA15: =Y15/Z15 -> #DIV/0! | AB15: ='11'!E14 -> 0 | AC15: ='11'!F14 -> 0 | AD15: =AB15/AC15 -> #DIV/0! | AE15: ='11'!E15 -> 0 | AF15: ='11'!F15 -> 0 | AG15: =AE15/AF15 -> #DIV/0! | AH15: ='11'!E16 -> 0 | AI15: ='11'!F16 -> 0 | AJ15: =AH15/AI15 -> #DIV/0! | AK15: ='11'!E17 -> 0 | AL15: ='11'!E18 -> 0 | AM15: ='11'!E19 -> 0 | AN15: ='11'!F19 -> 0 | AO15: =AM15/AN15 -> #DIV/0! | AP15: ='11'!E20 -> 0 | AQ15: ='11'!F20 -> 0 | AR15: =AP15/AQ15 -> #DIV/0! | AS15: ='11'!E21 -> 0 | AT15: ='11'!E22 -> 0 | AU15: ='11'!F22 -> 0 | AV15: =AT15/AU15 -> #DIV/0! | AW15: ='11'!E23 -> 0 | AX15: ='11'!F23 -> 0 | AY15: =AW15/AX15 -> #DIV/0! | AZ15: ='11'!E24 -> 0 | BA15: ='11'!F24 -> 0 | BB15: =AZ15/BA15 -> #DIV/0! | BC15: ='11'!E25 -> 0 | BD15: ='11'!F25 -> 0 | BE15: =BC15/BD15 -> #DIV/0! | BF15: ='11'!E26 -> 0 | BG15: ='11'!F26 -> 0 | BH15: =BF15/BG15 -> #DIV/0! | BI15: ='11'!E27 -> 0 | BJ15: ='11'!F27 -> 0 | BK15: =BI15/BJ15 -> #DIV/0! | BL15: =G15+J15+M15+P15+S15+V15+Y15 -> 475 | BM15: =BL15+BI15+BF15+BC15+AZ15+AW15+AS15+AP15+AM15+AL15+AK15+AH15+AE15+AB15 -> 475
A16: 46246 | B16: ='12'!C4 -> 15 | C16: ='12'!D4 -> 1 | D16: ='12'!E4 -> 8 | E16: ='12'!F4 -> 0 | F16: =SUM(B16:E16) -> 24 | G16: ='12'!E6 -> 155 | H16: ='12'!F6 -> 20.4 | I16: =G16/H16 -> 7.5980392 | J16: ='12'!E7 -> 37 | K16: ='12'!F7 -> 2 | L16: =J16/K16 -> 18.5 | M16: ='12'!E8 -> 0 | N16: ='12'!F8 -> 0 | O16: =AVERAGE(M16/N16) -> #DIV/0! | P16: ='12'!E9 -> 148 | Q16: ='12'!F9 -> 24 | R16: =AVERAGE(P16/Q16) -> 6.1666667 | S16: ='12'!E10 -> 0 | T16: ='12'!F10 -> 0 | U16: =AVERAGE(S16/T16) -> #DIV/0! | V16: ='12'!E12 -> 0 | W16: ='12'!F12 -> 0 | X16: =V16/W16 -> #DIV/0! | Y16: ='12'!E13 -> 0 | Z16: ='12'!F13 -> 0 | AA16: =Y16/Z16 -> #DIV/0! | AB16: ='12'!E14 -> 0 | AC16: ='12'!F14 -> 0 | AD16: =AB16/AC16 -> #DIV/0! | AE16: ='12'!E15 -> 0 | AF16: ='12'!F15 -> 0 | AG16: =AE16/AF16 -> #DIV/0! | AH16: ='12'!E16 -> 0 | AI16: ='12'!F16 -> 0 | AJ16: =AH16/AI16 -> #DIV/0! | AK16: ='12'!E17 -> 0 | AL16: ='12'!E18 -> 0 | AM16: ='12'!E19 -> 0 | AN16: ='12'!F19 -> 0 | AO16: =AM16/AN16 -> #DIV/0! | AP16: ='12'!E20 -> 0 | AQ16: ='12'!F20 -> 0 | AR16: =AP16/AQ16 -> #DIV/0! | AS16: ='12'!E21 -> 0 | AT16: ='12'!E22 -> 0 | AU16: ='12'!F22 -> 0 | AV16: =AT16/AU16 -> #DIV/0! | AW16: ='12'!E23 -> 0 | AX16: ='12'!F23 -> 0 | AY16: =AW16/AX16 -> #DIV/0! | AZ16: ='12'!E24 -> 0 | BA16: ='12'!F24 -> 0 | BB16: =AZ16/BA16 -> #DIV/0! | BC16: ='12'!E25 -> 0 | BD16: ='12'!F25 -> 0 | BE16: =BC16/BD16 -> #DIV/0! | BF16: ='12'!E26 -> 0 | BG16: ='12'!F26 -> 0 | BH16: =BF16/BG16 -> #DIV/0! | BI16: ='12'!E27 -> 0 | BJ16: ='12'!F27 -> 0 | BK16: =BI16/BJ16 -> #DIV/0! | BL16: =G16+J16+M16+P16+S16+V16+Y16 -> 340 | BM16: =BL16+BI16+BF16+BC16+AZ16+AW16+AS16+AP16+AM16+AL16+AK16+AH16+AE16+AB16 -> 340
A17: 46247 | B17: ='13'!C4 -> 18.25 | C17: ='13'!D4 -> 1 | D17: ='13'!E4 -> 4.75 | E17: ='13'!F4 -> 0 | F17: =SUM(B17:E17) -> 24 | G17: ='13'!E6 -> 180 | H17: ='13'!F6 -> 21.5 | I17: =G17/H17 -> 8.372093 | J17: ='13'!E7 -> 98 | K17: ='13'!F7 -> 5 | L17: =J17/K17 -> 19.6 | M17: ='13'!E8 -> 143 | N17: ='13'!F8 -> 24 | O17: =AVERAGE(M17/N17) -> 5.9583333 | P17: ='13'!E9 -> 0 | Q17: ='13'!F9 -> 0 | R17: =AVERAGE(P17/Q17) -> #DIV/0! | S17: ='13'!E10 -> 0 | T17: ='13'!F10 -> 0 | U17: =AVERAGE(S17/T17) -> #DIV/0! | V17: ='13'!E12 -> 0 | W17: ='13'!F12 -> 0 | X17: =V17/W17 -> #DIV/0! | Y17: ='13'!E13 -> 0 | Z17: ='13'!F13 -> 0 | AA17: =Y17/Z17 -> #DIV/0! | AB17: ='13'!E14 -> 0 | AC17: ='13'!F14 -> 0 | AD17: =AB17/AC17 -> #DIV/0! | AE17: ='13'!E15 -> 0 | AF17: ='13'!F15 -> 0 | AG17: =AE17/AF17 -> #DIV/0! | AH17: ='13'!E16 -> 0 | AI17: ='13'!F16 -> 0 | AJ17: =AH17/AI17 -> #DIV/0! | AK17: ='13'!E17 -> 0 | AL17: ='13'!E18 -> 0 | AM17: ='13'!E19 -> 0 | AN17: ='13'!F19 -> 0 | AO17: =AM17/AN17 -> #DIV/0! | AP17: ='13'!E20 -> 0 | AQ17: ='13'!F20 -> 0 | AR17: =AP17/AQ17 -> #DIV/0! | AS17: ='13'!E21 -> 0 | AT17: ='13'!E22 -> 0 | AU17: ='13'!F22 -> 0 | AV17: =AT17/AU17 -> #DIV/0! | AW17: ='13'!E23 -> 0 | AX17: ='13'!F23 -> 0 | AY17: =AW17/AX17 -> #DIV/0! | AZ17: ='13'!E24 -> 0 | BA17: ='13'!F24 -> 0 | BB17: =AZ17/BA17 -> #DIV/0! | BC17: ='13'!E25 -> 0 | BD17: ='13'!F25 -> 0 | BE17: =BC17/BD17 -> #DIV/0! | BF17: ='13'!E26 -> 0 | BG17: ='13'!F26 -> 0 | BH17: =BF17/BG17 -> #DIV/0! | BI17: ='13'!E27 -> 0 | BJ17: ='13'!F27 -> 0 | BK17: =BI17/BJ17 -> #DIV/0! | BL17: =G17+J17+M17+P17+S17+V17+Y17 -> 421 | BM17: =BL17+BI17+BF17+BC17+AZ17+AW17+AS17+AP17+AM17+AL17+AK17+AH17+AE17+AB17 -> 421
A18: 46248 | B18: ='14'!C4 -> 10 | C18: ='14'!D4 -> 2 | D18: ='14'!E4 -> 12 | E18: ='14'!F4 -> 0 | F18: =SUM(B18:E18) -> 24 | G18: ='14'!E6 -> 110 | H18: ='14'!F6 -> 15.4 | I18: =G18/H18 -> 7.1428571 | J18: ='14'!E7 -> 0 | K18: ='14'!F7 -> 0 | L18: =J18/K18 -> #DIV/0! | M18: ='14'!E8 -> 0 | N18: ='14'!F8 -> 0 | O18: =AVERAGE(M18/N18) -> #DIV/0! | P18: ='14'!E9 -> 143 | Q18: ='14'!F9 -> 24 | R18: =AVERAGE(P18/Q18) -> 5.9583333 | S18: ='14'!E10 -> 0 | T18: ='14'!F10 -> 0 | U18: =AVERAGE(S18/T18) -> #DIV/0! | V18: ='14'!E12 -> 0 | W18: ='14'!F12 -> 0 | X18: =V18/W18 -> #DIV/0! | Y18: ='14'!E13 -> 0 | Z18: ='14'!F13 -> 0 | AA18: =Y18/Z18 -> #DIV/0! | AB18: ='14'!E1 -> 0 | AC18: ='14'!F14 -> 0 | AD18: =AB18/AC18 -> #DIV/0! | AE18: ='14'!E15 -> 0 | AF18: ='14'!F15 -> 0 | AG18: =AE18/AF18 -> #DIV/0! | AH18: ='14'!E16 -> 0 | AI18: ='14'!F16 -> 0 | AJ18: =AH18/AI18 -> #DIV/0! | AK18: ='14'!E17 -> 0 | AL18: ='14'!E18 -> 0 | AM18: ='14'!E19 -> 0 | AN18: ='14'!F19 -> 0 | AO18: =AM18/AN18 -> #DIV/0! | AP18: ='14'!E20 -> 0 | AQ18: ='14'!F20 -> 0 | AR18: =AP18/AQ18 -> #DIV/0! | AS18: ='14'!E21 -> 0 | AT18: ='14'!E22 -> 0 | AU18: ='14'!F22 -> 0 | AV18: =AT18/AU18 -> #DIV/0! | AW18: ='14'!E23 -> 0 | AX18: ='14'!F23 -> 0 | AY18: =AW18/AX18 -> #DIV/0! | AZ18: ='14'!E24 -> 0 | BA18: ='14'!F24 -> 0 | BB18: =AZ18/BA18 -> #DIV/0! | BC18: ='14'!E25 -> 0 | BD18: ='14'!F25 -> 0 | BE18: =BC18/BD18 -> #DIV/0! | BF18: ='14'!E26 -> 0 | BG18: ='14'!F26 -> 0 | BH18: =BF18/BG18 -> #DIV/0! | BI18: ='14'!E27 -> 0 | BJ18: ='14'!F27 -> 0 | BK18: =BI18/BJ18 -> #DIV/0! | BL18: =G18+J18+M18+P18+S18+V18+Y18 -> 253 | BM18: =BL18+BI18+BF18+BC18+AZ18+AW18+AS18+AP18+AM18+AL18+AK18+AH18+AE18+AB18 -> 253
A19: 46249 | B19: ='15'!C4 -> 12.5 | C19: ='15'!D4 -> 7.5 | D19: ='15'!E4 -> 4 | E19: ='15'!F4 -> 0 | F19: =SUM(B19:E19) -> 24 | G19: ='15'!E6 -> 130 | H19: ='15'!F6 -> 15.5 | I19: =G19/H19 -> 8.3870968 | J19: ='15'!E7 -> 25 | K19: ='15'!F7 -> 1.5 | L19: =J19/K19 -> 16.666667 | M19: ='15'!E8 -> 147 | N19: ='15'!F8 -> 24 | O19: =AVERAGE(M19/N19) -> 6.125 | P19: ='15'!E9 -> 0 | Q19: ='15'!F9 -> 0 | R19: =AVERAGE(P19/Q19) -> #DIV/0! | S19: ='15'!E10 -> 0 | T19: ='15'!F10 -> 0 | U19: =AVERAGE(S19/T19) -> #DIV/0! | V19: ='15'!E12 -> 0 | W19: ='15'!F12 -> 0 | X19: =V19/W19 -> #DIV/0! | Y19: ='15'!E13 -> 6 | Z19: ='15'!F13 -> 2 | AA19: =Y19/Z19 -> 3 | AB19: ='15'!E14 -> 0 | AC19: ='15'!F14 -> 0 | AD19: =AB19/AC19 -> #DIV/0! | AE19: ='15'!E15 -> 0 | AF19: ='15'!F15 -> 0 | AG19: =AE19/AF19 -> #DIV/0! | AH19: ='15'!E16 -> 0 | AI19: ='15'!F16 -> 0 | AJ19: =AH19/AI19 -> #DIV/0! | AK19: ='15'!E17 -> 0 | AL19: ='15'!E18 -> 0 | AM19: ='15'!E19 -> 0 | AN19: ='15'!F19 -> 0 | AO19: =AM19/AN19 -> #DIV/0! | AP19: ='15'!E20 -> 0 | AQ19: ='15'!F20 -> 0 | AR19: =AP19/AQ19 -> #DIV/0! | AS19: ='15'!E21 -> 0 | AT19: ='15'!E22 -> 0 | AU19: ='15'!F22 -> 0 | AV19: =AT19/AU19 -> #DIV/0! | AW19: ='15'!E23 -> 0 | AX19: ='15'!F23 -> 0 | AY19: =AW19/AX19 -> #DIV/0! | AZ19: ='15'!E24 -> 0 | BA19: ='15'!F24 -> 0 | BB19: =AZ19/BA19 -> #DIV/0! | BC19: ='15'!E25 -> 0 | BD19: ='15'!F25 -> 0 | BE19: =BC19/BD19 -> #DIV/0! | BF19: ='15'!E26 -> 0 | BG19: ='15'!F26 -> 0 | BH19: =BF19/BG19 -> #DIV/0! | BI19: ='15'!E27 -> 0 | BJ19: ='15'!F27 -> 0 | BK19: =BI19/BJ19 -> #DIV/0! | BL19: =G19+J19+M19+P19+S19+V19+Y19 -> 308 | BM19: =BL19+BI19+BF19+BC19+AZ19+AW19+AS19+AP19+AM19+AL19+AK19+AH19+AE19+AB19 -> 308
A20: TOTAL:- | B20: =SUM(B5:B19) -> 193 | C20: =SUM(C5:C19) -> 53 | D20: =SUM(D5:D19) -> 107 | E20: =SUM(E5:E19) -> 0 | F20: =SUM(F5:F19) -> 353 | G20: =SUM(G5:G19) -> 1700 | H20: =SUM(H5:H19) -> 230.6 | I20: =G20/H20 -> 7.3720729 | J20: =SUM(J5:J19) -> 1103 | K20: =SUM(K5:K19) -> 62.5 | L20: =J20/K20 -> 17.648 | M20: =SUM(M5:M19) -> 966 | N20: =SUM(N5:N19) -> 156 | O20: =M20/N20 -> 6.1923077 | P20: =SUM(P5:P19) -> 1249 | Q20: =SUM(Q5:Q19) -> 204 | R20: =P20/Q20 -> 6.122549 | S20: =SUM(S5:S19) -> 0 | T20: =SUM(T5:T19) -> 0 | U20: =S20/T20 -> #DIV/0! | V20: =SUM(V5:V19) -> 0 | W20: =SUM(W5:W19) -> 0 | X20: =V20/W20 -> #DIV/0! | Y20: =SUM(Y5:Y19) -> 15 | Z20: =SUM(Z5:Z19) -> 5 | AA20: =Y20/Z20 -> 3 | AB20: =AB5+AB6+AB7+AB8+AB9+AB10+AB11+AB12+AB13+AB14+AB15+AB16+AB17+AB18+AB19 -> 0 | AC20: =AC5+AC6+AC7+AC8+AC9+AC10+AC11+AC12+AC13+AC14+AC15+AC16+AC17+AC18+AC19 -> 0 | AD20: =AB20/AC20 -> #DIV/0! | AE20: =SUM(AE5:AE19) -> 0 | AF20: =SUM(AF5:AF19) -> 0 | AG20: =AE20/AF20 -> #DIV/0! | AH20: =SUM(AH5:AH19) -> 0 | AI20: =SUM(AI5:AI19) -> 0 | AJ20: =AH20/AI20 -> #DIV/0! | AK20: =SUM(AK5:AK19) -> 10 | AL20: =SUM(AL5:AL19) -> 0 | AM20: =SUM(AM5:AM19) -> 0 | AN20: =SUM(AN5:AN19) -> 0 | AO20: =AM20/AN20 -> #DIV/0! | AQ20: =SUM(AQ5:AQ19) -> 0 | AR20: =AP20/AQ20 -> #DIV/0! | AS20: =SUM(AS5:AS19) -> 0 | AT20: =SUM(AT5:AT19) -> 0 | AU20: =SUM(AU5:AU19) -> 0 | AV20: =AT20/AU20 -> #DIV/0! | AW20: =SUM(AW5:AW19) -> 0 | AX20: =SUM(AX5:AX19) -> 0 | AY20: =AW20/AX20 -> #DIV/0! | AZ20: =SUM(AZ5:AZ19) -> 0 | BA20: =SUM(BA5:BA19) -> 0 | BB20: =AZ20/BA20 -> #DIV/0! | BC20: =SUM(BC5:BC19) -> 0 | BD20: =SUM(BD5:BD19) -> 0 | BE20: =BC20/BD20 -> #DIV/0! | BF20: =SUM(BF5:BF19) -> 0 | BG20: =SUM(BG5:BG19) -> 0 | BH20: =BF20/BG20 -> #DIV/0! | BI20: =SUM(BI5:BI19) -> 0 | BJ20: =SUM(BJ5:BJ19) -> 0 | BK20: =BI20/BJ20 -> #DIV/0! | BL20: =BL5+BL6+BL7+BL8+BL9+BL10+BL11+BL12+BL13+BL14+BL15+BL16+BL17+BL18+BL19 -> 5033 | BM20: =BM5+BM6+BM7+BM8+BM9+BM10+BM11+BM12+BM13+BM14+BM15+BM16+BM17+BM18+BM19 -> 5043
A21: 46250 | B21: ='16'!C4 -> 23 | C21: ='16'!D4 -> 1 | D21: ='16'!E4 -> 0 | E21: ='16'!F4 -> 0 | F21: =SUM(B21:E21) -> 24 | G21: ='16'!E6 -> 202 | H21: ='16'!F6 -> 23.5 | I21: =G21/H21 -> 8.5957447 | J21: ='16'!E7 -> 33 | K21: ='16'!F7 -> 2 | L21: =J21/K21 -> 16.5 | M21: ='16'!E8 -> 145 | N21: ='16'!F8 -> 24 | O21: =M21/N21 -> 6.0416667 | P21: ='16'!E9 -> 0 | Q21: ='16'!F9 -> 0 | R21: =AVERAGE(P21/Q21) -> #DIV/0! | S21: ='16'!E10 -> 0 | T21: ='16'!F10 -> 0 | U21: =AVERAGE(S21/T21) -> #DIV/0! | V21: ='16'!E12 -> 0 | W21: ='16'!F12 -> 0 | X21: =V21/W21 -> #DIV/0! | Y21: ='16'!E13 -> 0 | Z21: ='16'!F13 -> 0 | AA21: =Y21/Z21 -> #DIV/0! | AB21: ='16'!E14 -> 0 | AC21: ='16'!F14 -> 0 | AD21: =AB21/AC21 -> #DIV/0! | AE21: ='16'!E15 -> 0 | AF21: ='16'!F15 -> 0 | AG21: =AE21/AF21 -> #DIV/0! | AH21: ='16'!E16 -> 0 | AI21: ='16'!F16 -> 0 | AJ21: =AH21/AI21 -> #DIV/0! | AK21: ='16'!E17 -> 0 | AL21: ='16'!E18 -> 0 | AM21: ='16'!E19 -> 0 | AN21: ='16'!F19 -> 0 | AO21: =AM21/AN21 -> #DIV/0! | AP21: ='16'!E20 -> 0 | AQ21: ='16'!F20 -> 0 | AR21: =AP21/AQ21 -> #DIV/0! | AS21: ='16'!E21 -> 0 | AT21: ='16'!E22 -> 0 | AU21: ='16'!F22 -> 0 | AV21: =AT21/AU21 -> #DIV/0! | AW21: ='16'!E23 -> 0 | AX21: ='16'!F23 -> 0 | AY21: =AW21/AX21 -> #DIV/0! | AZ21: ='16'!E24 -> 0 | BA21: ='16'!F24 -> 0 | BB21: =AZ21/BA21 -> #DIV/0! | BC21: ='16'!E25 -> 0 | BD21: ='16'!F25 -> 0 | BE21: =BC21/BD21 -> #DIV/0! | BF21: ='16'!E26 -> 0 | BG21: ='16'!F26 -> 0 | BH21: =BF21/BG21 -> #DIV/0! | BI21: ='16'!E27 -> 0 | BJ21: ='16'!F27 -> 0 | BK21: =BI21/BJ21 -> #DIV/0! | BL21: =G21+J21+M21+P21+S21+V21+Y21 -> 380 | BM21: =BL21+BI21+BF21+BC21+AZ21+AW21+AS21+AP21+AM21+AL21+AK21+AH21+AE21+AB21 -> 380
A22: 46251 | B22: ='17'!C4 -> 23 | C22: ='17'!D4 -> 1 | D22: ='17'!E4 -> 0 | E22: ='17'!F4 -> 0 | F22: =SUM(B22:E22) -> 24 | G22: ='17'!E6 -> 225 | H22: ='17'!F6 -> 24 | I22: =G22/H22 -> 9.375 | J22: ='17'!E7 -> 40 | K22: ='17'!F7 -> 2.5 | L22: =J22/K22 -> 16 | M22: ='17'!E8 -> 150 | N22: ='17'!F8 -> 20 | O22: =M22/N22 -> 7.5 | P22: ='17'!E9 -> 28 | Q22: ='17'!F9 -> 4 | R22: =AVERAGE(P22/Q22) -> 7 | S22: ='17'!E10 -> 0 | T22: ='17'!F10 -> 0 | U22: =AVERAGE(S22/T22) -> #DIV/0! | V22: ='17'!E12 -> 0 | W22: ='17'!F12 -> 0 | X22: =V22/W22 -> #DIV/0! | Y22: ='17'!E13 -> 6 | Z22: ='17'!F13 -> 2 | AA22: =Y22/Z22 -> 3 | AB22: ='17'!E14 -> 0 | AC22: ='17'!F14 -> 0 | AD22: =AB22/AC22 -> #DIV/0! | AE22: ='17'!E15 -> 0 | AF22: ='17'!F15 -> 0 | AG22: =AE22/AF22 -> #DIV/0! | AH22: ='17'!E16 -> 0 | AI22: ='17'!F16 -> 0 | AJ22: =AH22/AI22 -> #DIV/0! | AK22: ='17'!E17 -> 0 | AL22: ='17'!E18 -> 0 | AM22: ='17'!E19 -> 0 | AN22: ='17'!F19 -> 0 | AO22: =AM22/AN22 -> #DIV/0! | AP22: ='17'!E20 -> 0 | AQ22: ='17'!F20 -> 0 | AR22: =AP22/AQ22 -> #DIV/0! | AS22: ='17'!E21 -> 0 | AT22: ='17'!E22 -> 0 | AU22: ='17'!F22 -> 0 | AV22: =AT22/AU22 -> #DIV/0! | AW22: ='17'!E23 -> 0 | AX22: ='17'!F23 -> 0 | AY22: =AW22/AX22 -> #DIV/0! | AZ22: ='17'!E24 -> 0 | BA22: ='17'!F24 -> 0 | BB22: =AZ22/BA22 -> #DIV/0! | BC22: ='17'!E25 -> 0 | BD22: ='17'!F25 -> 0 | BE22: =BC22/BD22 -> #DIV/0! | BF22: ='17'!E26 -> 0 | BG22: ='17'!F26 -> 0 | BH22: =BF22/BG22 -> #DIV/0! | BI22: ='17'!E27 -> 0 | BJ22: ='17'!F27 -> 0 | BK22: =BI22/BJ22 -> #DIV/0! | BL22: =G22+J22+M22+P22+S22+V22+Y22 -> 449 | BM22: =BL22+BI22+BF22+BC22+AZ22+AW22+AS22+AP22+AM22+AL22+AK22+AH22+AE22+AB22 -> 449
A23: 46252 | B23: ='18'!C4 -> 23 | C23: ='18'!D4 -> 1 | D23: ='18'!E4 -> 0 | E23: ='18'!F4 -> 0 | F23: =SUM(B23:E23) -> 24 | G23: ='18'!E6 -> 200 | H23: ='18'!F6 -> 23.5 | I23: =G23/H23 -> 8.5106383 | J23: ='18'!E7 -> 17 | K23: ='18'!F7 -> 1 | L23: =J23/K23 -> 17 | M23: ='18'!E8 -> 83 | N23: ='18'!F8 -> 12 | O23: =M23/N23 -> 6.9166667 | P23: ='18'!E9 -> 75 | Q23: ='18'!F9 -> 12 | R23: =AVERAGE(P23/Q23) -> 6.25 | S23: ='18'!E10 -> 0 | T23: ='18'!F10 -> 0 | U23: =AVERAGE(S23/T23) -> #DIV/0! | V23: ='18'!E12 -> 0 | W23: ='18'!F12 -> 0 | X23: =V23/W23 -> #DIV/0! | Y23: ='18'!E13 -> 0 | Z23: ='18'!F13 -> 0 | AA23: =Y23/Z23 -> #DIV/0! | AB23: ='18'!E14 -> 0 | AC23: ='18'!F14 -> 0 | AD23: =AB23/AC23 -> #DIV/0! | AE23: ='18'!E15 -> 0 | AF23: ='18'!F15 -> 0 | AG23: =AE23/AF23 -> #DIV/0! | AH23: ='18'!E16 -> 0 | AI23: ='18'!F16 -> 0 | AJ23: =AH23/AI23 -> #DIV/0! | AK23: ='18'!E17 -> 0 | AL23: ='18'!E18 -> 0 | AM23: ='18'!E19 -> 0 | AN23: ='18'!F19 -> 0 | AO23: =AM23/AN23 -> #DIV/0! | AP23: ='18'!E20 -> 0 | AQ23: ='18'!F20 -> 0 | AR23: =AP23/AQ23 -> #DIV/0! | AS23: ='18'!E21 -> 0 | AT23: ='18'!E22 -> 0 | AU23: ='18'!F22 -> 0 | AV23: =AT23/AU23 -> #DIV/0! | AW23: ='18'!E23 -> 0 | AX23: ='18'!F23 -> 0 | AY23: =AW23/AX23 -> #DIV/0! | AZ23: ='18'!E24 -> 0 | BA23: ='18'!F24 -> 0 | BB23: =AZ23/BA23 -> #DIV/0! | BC23: ='18'!E25 -> 0 | BD23: ='18'!F25 -> 0 | BE23: =BC23/BD23 -> #DIV/0! | BF23: ='18'!E26 -> 0 | BG23: ='18'!F26 -> 0 | BH23: =BF23/BG23 -> #DIV/0! | BI23: ='18'!E27 -> 0 | BJ23: ='18'!F27 -> 0 | BK23: =BI23/BJ23 -> #DIV/0! | BL23: =G23+J23+M23+P23+S23+V23+Y23 -> 375 | BM23: =BL23+BI23+BF23+BC23+AZ23+AW23+AS23+AP23+AM23+AL23+AK23+AH23+AE23+AB23 -> 375
A24: 46253 | B24: ='19'!C4 -> 23 | C24: ='19'!D4 -> 1 | D24: ='19'!E4 -> 0 | E24: ='19'!F4 -> 0 | F24: =SUM(B24:E24) -> 24 | G24: ='19'!E6 -> 215 | H24: ='19'!F6 -> 23.5 | I24: =G24/H24 -> 9.1489362 | J24: ='19'!E7 -> 140 | K24: ='19'!F7 -> 6.5 | L24: =J24/K24 -> 21.538462 | M24: ='19'!E8 -> 80 | N24: ='19'!F8 -> 12 | O24: =M24/N24 -> 6.6666667 | P24: ='19'!E9 -> 70 | Q24: ='19'!F9 -> 12 | R24: =AVERAGE(P24/Q24) -> 5.8333333 | S24: ='19'!E10 -> 0 | T24: ='19'!F10 -> 0 | U24: =AVERAGE(S24/T24) -> #DIV/0! | V24: ='19'!E12 -> 0 | W24: ='19'!F12 -> 0 | X24: =V24/W24 -> #DIV/0! | Y24: ='19'!E13 -> 0 | Z24: ='19'!F13 -> 0 | AA24: =Y24/Z24 -> #DIV/0! | AB24: ='19'!E14 -> 0 | AC24: ='19'!F14 -> 0 | AD24: =AB24/AC24 -> #DIV/0! | AE24: ='19'!E15 -> 0 | AF24: ='19'!F15 -> 0 | AG24: =AE24/AF24 -> #DIV/0! | AH24: ='19'!E16 -> 0 | AI24: ='19'!F16 -> 0 | AJ24: =AH24/AI24 -> #DIV/0! | AK24: ='19'!E17 -> 0 | AL24: ='19'!E18 -> 0 | AM24: ='19'!E19 -> 0 | AN24: ='19'!F19 -> 0 | AO24: =AM24/AN24 -> #DIV/0! | AP24: ='19'!E20 -> 0 | AQ24: ='19'!F20 -> 0 | AR24: =AP24/AQ24 -> #DIV/0! | AS24: ='19'!E21 -> 0 | AT24: ='19'!E22 -> 0 | AU24: ='19'!F22 -> 0 | AV24: =AT24/AU24 -> #DIV/0! | AW24: ='19'!E23 -> 0 | AX24: ='19'!F23 -> 0 | AY24: =AW24/AX24 -> #DIV/0! | AZ24: ='19'!E24 -> 0 | BA24: ='19'!F24 -> 0 | BB24: =AZ24/BA24 -> #DIV/0! | BC24: ='19'!E25 -> 0 | BD24: ='19'!F25 -> 0 | BE24: =BC24/BD24 -> #DIV/0! | BF24: ='19'!E26 -> 0 | BG24: ='19'!F26 -> 0 | BH24: =BF24/BG24 -> #DIV/0! | BI24: ='19'!E27 -> 0 | BJ24: ='19'!F27 -> 0 | BK24: =BI24/BJ24 -> #DIV/0! | BL24: =G24+J24+M24+P24+S24+V24+Y24 -> 505 | BM24: =BL24+BI24+BF24+BC24+AZ24+AW24+AS24+AP24+AM24+AL24+AK24+AH24+AE24+AB24 -> 505
A25: 46254 | B25: ='20'!C4 -> 23.5 | C25: ='20'!D4 -> 0.5 | D25: ='20'!E4 -> 0 | E25: ='20'!F4 -> 0 | F25: =SUM(B25:E25) -> 24 | G25: ='20'!E6 -> 250 | H25: ='20'!F6 -> 24 | I25: =G25/H25 -> 10.416667 | J25: ='20'!E7 -> 71 | K25: ='20'!F7 -> 3.5 | L25: =J25/K25 -> 20.285714 | M25: ='20'!E8 -> 80 | N25: ='20'!F8 -> 12 | O25: =M25/N25 -> 6.6666667 | P25: ='20'!E9 -> 74 | Q25: ='20'!F9 -> 12 | R25: =AVERAGE(P25/Q25) -> 6.1666667 | S25: ='20'!E10 -> 0 | T25: ='20'!F10 -> 0 | U25: =AVERAGE(S25/T25) -> #DIV/0! | V25: ='20'!E12 -> 0 | W25: ='20'!F12 -> 0 | X25: =V25/W25 -> #DIV/0! | Y25: ='20'!E13 -> 3 | Z25: ='20'!F13 -> 1 | AA25: =Y25/Z25 -> 3 | AB25: ='20'!E14 -> 0 | AC25: ='20'!F14 -> 0 | AD25: =AB25/AC25 -> #DIV/0! | AE25: ='20'!E15 -> 0 | AF25: ='20'!F15 -> 0 | AG25: =AE25/AF25 -> #DIV/0! | AH25: ='20'!E16 -> 0 | AI25: ='20'!F16 -> 0 | AJ25: =AH25/AI25 -> #DIV/0! | AK25: ='20'!E17 -> 25 | AL25: ='20'!E18 -> 0 | AM25: ='20'!E19 -> 0 | AN25: ='20'!F19 -> 0 | AO25: =AM25/AN25 -> #DIV/0! | AP25: ='20'!E20 -> 0 | AQ25: ='20'!F20 -> 0 | AR25: =AP25/AQ25 -> #DIV/0! | AS25: ='20'!E21 -> 0 | AT25: ='20'!E22 -> 0 | AU25: ='20'!F22 -> 0 | AV25: =AT25/AU25 -> #DIV/0! | AW25: ='20'!E23 -> 0 | AX25: ='20'!F23 -> 0 | AY25: =AW25/AX25 -> #DIV/0! | AZ25: ='20'!E24 -> 0 | BA25: ='20'!F24 -> 0 | BB25: =AZ25/BA25 -> #DIV/0! | BC25: ='20'!E25 -> 0 | BD25: ='20'!F25 -> 0 | BE25: =BC25/BD25 -> #DIV/0! | BF25: ='20'!E26 -> 0 | BG25: ='20'!F26 -> 0 | BH25: =BF25/BG25 -> #DIV/0! | BI25: ='20'!E27 -> 0 | BJ25: ='20'!F27 -> 0 | BK25: =BI25/BJ25 -> #DIV/0! | BL25: =G25+J25+M25+P25+S25+V25+Y25 -> 478 | BM25: =BL25+BI25+BF25+BC25+AZ25+AW25+AS25+AP25+AM25+AL25+AK25+AH25+AE25+AB25 -> 503
A26: 46255 | B26: ='21'!C4 -> 0 | C26: ='21'!D4 -> 0 | D26: ='21'!E4 -> 0 | E26: ='21'!F4 -> 0 | F26: =SUM(B26:E26) -> 0 | G26: ='21'!E6 -> 0 | H26: ='21'!F6 -> 0 | I26: =G26/H26 -> #DIV/0! | J26: ='21'!E7 -> 0 | K26: ='21'!F7 -> 0 | L26: =J26/K26 -> #DIV/0! | M26: ='21'!E8 -> 0 | N26: ='21'!F8 -> 0 | O26: =M26/N26 -> #DIV/0! | P26: ='21'!E9 -> 0 | Q26: ='21'!F9 -> 0 | R26: =AVERAGE(P26/Q26) -> #DIV/0! | S26: ='21'!E10 -> 0 | T26: ='21'!F10 -> 0 | U26: =AVERAGE(S26/T26) -> #DIV/0! | V26: ='21'!E12 -> 0 | W26: ='21'!F12 -> 0 | X26: =V26/W26 -> #DIV/0! | Y26: ='21'!E13 -> 0 | Z26: ='21'!F13 -> 0 | AA26: =Y26/Z26 -> #DIV/0! | AB26: ='21'!E14 -> 0 | AC26: ='21'!F14 -> 0 | AD26: =AB26/AC26 -> #DIV/0! | AE26: ='21'!E15 -> 0 | AF26: ='21'!F15 -> 0 | AG26: =AE26/AF26 -> #DIV/0! | AH26: ='21'!E16 -> 0 | AI26: ='21'!F16 -> 0 | AJ26: =AH26/AI26 -> #DIV/0! | AK26: ='21'!E17 -> 0 | AL26: ='21'!E18 -> 0 | AM26: ='21'!E19 -> 0 | AN26: ='21'!F19 -> 0 | AO26: =AM26/AN26 -> #DIV/0! | AP26: ='21'!E20 -> 0 | AQ26: ='21'!F20 -> 0 | AR26: =AP26/AQ26 -> #DIV/0! | AS26: ='21'!E21 -> 0 | AT26: ='21'!E22 -> 0 | AU26: ='21'!F22 -> 0 | AV26: =AT26/AU26 -> #DIV/0! | AW26: ='21'!E23 -> 0 | AX26: ='21'!F23 -> 0 | AY26: =AW26/AX26 -> #DIV/0! | AZ26: ='21'!E24 -> 0 | BA26: ='21'!F24 -> 0 | BB26: =AZ26/BA26 -> #DIV/0! | BC26: ='21'!E25 -> 0 | BD26: ='21'!F25 -> 0 | BE26: =BC26/BD26 -> #DIV/0! | BF26: ='21'!E26 -> 0 | BG26: ='21'!F26 -> 0 | BH26: =BF26/BG26 -> #DIV/0! | BI26: ='21'!E27 -> 0 | BJ26: ='21'!F27 -> 0 | BK26: =BI26/BJ26 -> #DIV/0! | BL26: =G26+J26+M26+P26+S26+V26+Y26 -> 0 | BM26: =BL26+BI26+BF26+BC26+AZ26+AW26+AS26+AP26+AM26+AL26+AK26+AH26+AE26+AB26 -> 0
A27: 46256 | B27: ='22'!C4 -> 0 | C27: ='22'!D4 -> 0 | D27: ='22'!E4 -> 0 | E27: ='22'!F4 -> 0 | F27: =SUM(B27:E27) -> 0 | G27: ='22'!E6 -> 0 | H27: ='22'!F6 -> 0 | I27: =G27/H27 -> #DIV/0! | J27: ='22'!E7 -> 0 | K27: ='22'!F7 -> 0 | L27: =J27/K27 -> #DIV/0! | M27: ='22'!E8 -> 0 | N27: ='22'!F8 -> 0 | O27: =M27/N27 -> #DIV/0! | P27: ='22'!E9 -> 0 | Q27: ='22'!F9 -> 0 | R27: =AVERAGE(P27/Q27) -> #DIV/0! | S27: ='22'!E10 -> 0 | T27: ='22'!F10 -> 0 | U27: =AVERAGE(S27/T27) -> #DIV/0! | V27: ='22'!E12 -> 0 | W27: ='22'!F12 -> 0 | X27: =V27/W27 -> #DIV/0! | Y27: ='22'!E13 -> 0 | Z27: ='22'!F13 -> 0 | AA27: =Y27/Z27 -> #DIV/0! | AB27: ='22'!E14 -> 0 | AC27: ='22'!F14 -> 0 | AD27: =AB27/AC27 -> #DIV/0! | AE27: ='22'!E15 -> 0 | AF27: ='22'!F15 -> 0 | AG27: =AE27/AF27 -> #DIV/0! | AH27: ='22'!E16 -> 0 | AI27: ='22'!F16 -> 0 | AJ27: =AH27/AI27 -> #DIV/0! | AK27: ='22'!E17 -> 0 | AL27: ='22'!E18 -> 0 | AM27: ='22'!E19 -> 0 | AN27: ='22'!F19 -> 0 | AO27: =AM27/AN27 -> #DIV/0! | AP27: ='22'!E20 -> 0 | AQ27: ='22'!F20 -> 0 | AR27: =AP27/AQ27 -> #DIV/0! | AS27: ='22'!E21 -> 0 | AT27: ='22'!E22 -> 0 | AU27: ='22'!F22 -> 0 | AV27: =AT27/AU27 -> #DIV/0! | AW27: ='22'!E23 -> 0 | AX27: ='22'!F23 -> 0 | AY27: =AW27/AX27 -> #DIV/0! | AZ27: ='22'!E24 -> 0 | BA27: ='22'!F24 -> 0 | BB27: =AZ27/BA27 -> #DIV/0! | BC27: ='22'!E25 -> 0 | BD27: ='22'!F25 -> 0 | BE27: =BC27/BD27 -> #DIV/0! | BF27: ='22'!E26 -> 0 | BG27: ='22'!F26 -> 0 | BH27: =BF27/BG27 -> #DIV/0! | BI27: ='22'!E27 -> 0 | BJ27: ='22'!F27 -> 0 | BK27: =BI27/BJ27 -> #DIV/0! | BL27: =G27+J27+M27+P27+S27+V27+Y27 -> 0 | BM27: =BL27+BI27+BF27+BC27+AZ27+AW27+AS27+AP27+AM27+AL27+AK27+AH27+AE27+AB27 -> 0
A28: 46257 | B28: ='23'!C4 -> 0 | C28: ='23'!D4 -> 0 | D28: ='23'!E4 -> 0 | E28: ='23'!F4 -> 0 | F28: =SUM(B28:E28) -> 0 | G28: ='23'!E6 -> 0 | H28: ='23'!F6 -> 0 | I28: =G28/H28 -> #DIV/0! | J28: ='23'!E7 -> 0 | K28: ='23'!F7 -> 0 | L28: =J28/K28 -> #DIV/0! | M28: ='23'!E8 -> 0 | N28: ='23'!F8 -> 0 | O28: =M28/N28 -> #DIV/0! | P28: ='23'!E9 -> 0 | Q28: ='23'!F9 -> 0 | R28: =AVERAGE(P28/Q28) -> #DIV/0! | S28: ='23'!E10 -> 0 | T28: ='23'!F10 -> 0 | U28: =AVERAGE(S28/T28) -> #DIV/0! | V28: ='23'!E12 -> 0 | W28: ='23'!F12 -> 0 | X28: =V28/W28 -> #DIV/0! | Y28: ='23'!E13 -> 0 | Z28: ='23'!F13 -> 0 | AA28: =Y28/Z28 -> #DIV/0! | AB28: ='23'!E14 -> 0 | AC28: ='23'!F14 -> 0 | AD28: =AB28/AC28 -> #DIV/0! | AE28: ='23'!E15 -> 0 | AF28: ='23'!F15 -> 0 | AG28: =AE28/AF28 -> #DIV/0! | AH28: ='23'!E16 -> 0 | AI28: ='23'!F16 -> 0 | AJ28: =AH28/AI28 -> #DIV/0! | AK28: ='23'!E17 -> 0 | AL28: ='23'!E18 -> 0 | AM28: ='23'!E19 -> 0 | AN28: ='23'!F19 -> 0 | AO28: =AM28/AN28 -> #DIV/0! | AP28: ='23'!E20 -> 0 | AQ28: ='23'!F20 -> 0 | AR28: =AP28/AQ28 -> #DIV/0! | AS28: ='23'!E21 -> 0 | AT28: ='23'!E22 -> 0 | AU28: ='23'!F22 -> 0 | AV28: =AT28/AU28 -> #DIV/0! | AW28: ='23'!E23 -> 0 | AX28: ='23'!F23 -> 0 | AY28: =AW28/AX28 -> #DIV/0! | AZ28: ='23'!E24 -> 0 | BA28: ='23'!F24 -> 0 | BB28: =AZ28/BA28 -> #DIV/0! | BC28: ='23'!E25 -> 0 | BD28: ='23'!F25 -> 0 | BE28: =BC28/BD28 -> #DIV/0! | BF28: ='23'!E26 -> 0 | BG28: ='23'!F26 -> 0 | BH28: =BF28/BG28 -> #DIV/0! | BI28: ='23'!E27 -> 0 | BJ28: ='23'!F27 -> 0 | BK28: =BI28/BJ28 -> #DIV/0! | BL28: =G28+J28+M28+P28+S28+V28+Y28 -> 0 | BM28: =BL28+BI28+BF28+BC28+AZ28+AW28+AS28+AP28+AM28+AL28+AK28+AH28+AE28+AB28 -> 0
A29: 46258 | B29: ='24'!C4 -> 0 | C29: ='24'!D4 -> 0 | D29: ='24'!E4 -> 0 | E29: ='24'!F4 -> 0 | F29: =SUM(B29:E29) -> 0 | G29: ='24'!E6 -> 0 | H29: ='24'!F6 -> 0 | I29: =G29/H29 -> #DIV/0! | J29: ='24'!E7 -> 0 | K29: ='24'!F7 -> 0 | L29: =J29/K29 -> #DIV/0! | M29: ='24'!E8 -> 0 | N29: ='24'!F8 -> 0 | O29: =M29/N29 -> #DIV/0! | P29: ='24'!E9 -> 0 | Q29: ='24'!F9 -> 0 | R29: =AVERAGE(P29/Q29) -> #DIV/0! | S29: ='24'!E10 -> 0 | T29: ='24'!F10 -> 0 | U29: =AVERAGE(S29/T29) -> #DIV/0! | V29: ='24'!E12 -> 0 | W29: ='24'!F12 -> 0 | X29: =V29/W29 -> #DIV/0! | Y29: ='24'!E13 -> 0 | Z29: ='24'!F13 -> 0 | AA29: =Y29/Z29 -> #DIV/0! | AB29: ='24'!E14 -> 0 | AC29: ='24'!F14 -> 0 | AD29: =AB29/AC29 -> #DIV/0! | AE29: ='24'!E15 -> 0 | AF29: ='24'!F15 -> 0 | AG29: =AE29/AF29 -> #DIV/0! | AH29: ='24'!E16 -> 0 | AI29: ='24'!F16 -> 0 | AJ29: =AH29/AI29 -> #DIV/0! | AK29: ='24'!E17 -> 0 | AL29: ='24'!E18 -> 0 | AM29: ='24'!E19 -> 0 | AN29: ='24'!F19 -> 0 | AO29: =AM29/AN29 -> #DIV/0! | AP29: ='24'!E20 -> 0 | AQ29: ='24'!F20 -> 0 | AR29: =AP29/AQ29 -> #DIV/0! | AS29: ='24'!E21 -> 0 | AT29: ='24'!E22 -> 0 | AU29: ='24'!F22 -> 0 | AV29: =AT29/AU29 -> #DIV/0! | AW29: ='24'!E23 -> 0 | AX29: ='24'!F23 -> 0 | AY29: =AW29/AX29 -> #DIV/0! | AZ29: ='24'!E24 -> 0 | BA29: ='24'!F24 -> 0 | BB29: =AZ29/BA29 -> #DIV/0! | BC29: ='24'!E25 -> 0 | BD29: ='24'!F25 -> 0 | BE29: =BC29/BD29 -> #DIV/0! | BF29: ='24'!E26 -> 0 | BG29: ='24'!F26 -> 0 | BH29: =BF29/BG29 -> #DIV/0! | BI29: ='24'!E27 -> 0 | BJ29: ='24'!F27 -> 0 | BK29: =BI29/BJ29 -> #DIV/0! | BL29: =G29+J29+M29+P29+S29+V29+Y29 -> 0 | BM29: =BL29+BI29+BF29+BC29+AZ29+AW29+AS29+AP29+AM29+AL29+AK29+AH29+AE29+AB29 -> 0
A30: 46259 | B30: ='25'!C4 -> 0 | C30: ='25'!D4 -> 0 | D30: ='25'!E4 -> 0 | E30: ='25'!F4 -> 0 | F30: =SUM(B30:E30) -> 0 | G30: ='25'!E6 -> 0 | H30: ='25'!F6 -> 0 | I30: =G30/H30 -> #DIV/0! | J30: ='25'!E7 -> 0 | K30: ='25'!F7 -> 0 | L30: =J30/K30 -> #DIV/0! | M30: ='25'!E8 -> 0 | N30: ='25'!F8 -> 0 | O30: =M30/N30 -> #DIV/0! | P30: ='25'!E9 -> 0 | Q30: ='25'!F9 -> 0 | R30: =AVERAGE(P30/Q30) -> #DIV/0! | S30: ='25'!E10 -> 0 | T30: ='25'!F10 -> 0 | U30: =AVERAGE(S30/T30) -> #DIV/0! | V30: ='25'!E12 -> 0 | W30: ='25'!F12 -> 0 | X30: =V30/W30 -> #DIV/0! | Y30: ='25'!E13 -> 0 | Z30: ='25'!F13 -> 0 | AA30: =Y30/Z30 -> #DIV/0! | AB30: ='25'!E14 -> 0 | AC30: ='25'!F14 -> 0 | AD30: =AB30/AC30 -> #DIV/0! | AE30: ='25'!E15 -> 0 | AF30: ='25'!F15 -> 0 | AG30: =AE30/AF30 -> #DIV/0! | AH30: ='25'!E16 -> 0 | AI30: ='25'!F16 -> 0 | AJ30: =AH30/AI30 -> #DIV/0! | AK30: ='25'!E17 -> 0 | AL30: ='25'!E18 -> 0 | AM30: ='25'!E19 -> 0 | AN30: ='25'!F19 -> 0 | AO30: =AM30/AN30 -> #DIV/0! | AP30: ='25'!E20 -> 0 | AQ30: ='25'!F20 -> 0 | AR30: =AP30/AQ30 -> #DIV/0! | AS30: ='25'!E21 -> 0 | AT30: ='25'!E22 -> 0 | AU30: ='25'!F22 -> 0 | AV30: =AT30/AU30 -> #DIV/0! | AW30: ='25'!E23 -> 0 | AX30: ='25'!F23 -> 0 | AY30: =AW30/AX30 -> #DIV/0! | AZ30: ='25'!E24 -> 0 | BA30: ='25'!F24 -> 0 | BB30: =AZ30/BA30 -> #DIV/0! | BC30: ='25'!E25 -> 0 | BD30: ='25'!F25 -> 0 | BE30: =BC30/BD30 -> #DIV/0! | BF30: ='25'!E26 -> 0 | BG30: ='25'!F26 -> 0 | BH30: =BF30/BG30 -> #DIV/0! | BI30: ='25'!E27 -> 0 | BJ30: ='25'!F27 -> 0 | BK30: =BI30/BJ30 -> #DIV/0! | BL30: =G30+J30+M30+P30+S30+V30+Y30 -> 0 | BM30: =BL30+BI30+BF30+BC30+AZ30+AW30+AS30+AP30+AM30+AL30+AK30+AH30+AE30+AB30 -> 0
A31: 46260 | B31: ='26'!C4 -> 0 | C31: ='26'!D4 -> 0 | D31: ='26'!E4 -> 0 | E31: ='26'!F4 -> 0 | F31: =SUM(B31:E31) -> 0 | G31: ='26'!E6 -> 0 | H31: ='26'!F6 -> 0 | I31: =G31/H31 -> #DIV/0! | J31: ='26'!E7 -> 0 | K31: ='26'!F7 -> 0 | L31: =J31/K31 -> #DIV/0! | M31: ='26'!E8 -> 0 | N31: ='26'!F8 -> 0 | O31: =M31/N31 -> #DIV/0! | P31: ='26'!E9 -> 0 | Q31: ='26'!F9 -> 0 | R31: =AVERAGE(P31/Q31) -> #DIV/0! | S31: ='26'!E10 -> 0 | T31: ='26'!F10 -> 0 | U31: =AVERAGE(S31/T31) -> #DIV/0! | V31: ='26'!E12 -> 0 | W31: ='26'!F12 -> 0 | X31: =V31/W31 -> #DIV/0! | Y31: ='26'!E13 -> 0 | Z31: ='26'!F13 -> 0 | AA31: =Y31/Z31 -> #DIV/0! | AB31: ='26'!E14 -> 0 | AC31: ='26'!F14 -> 0 | AD31: =AB31/AC31 -> #DIV/0! | AE31: ='26'!E15 -> 0 | AF31: ='26'!F15 -> 0 | AG31: =AE31/AF31 -> #DIV/0! | AH31: ='26'!E16 -> 0 | AI31: ='26'!F16 -> 0 | AJ31: =AH31/AI31 -> #DIV/0! | AK31: ='26'!E17 -> 0 | AL31: ='26'!E18 -> 0 | AM31: ='26'!E19 -> 0 | AN31: ='26'!F19 -> 0 | AO31: =AM31/AN31 -> #DIV/0! | AP31: ='26'!E20 -> 0 | AQ31: ='26'!F20 -> 0 | AR31: =AP31/AQ31 -> #DIV/0! | AS31: ='26'!E21 -> 0 | AT31: ='26'!E22 -> 0 | AU31: ='26'!F22 -> 0 | AV31: =AT31/AU31 -> #DIV/0! | AW31: ='26'!E23 -> 0 | AX31: ='26'!F23 -> 0 | AY31: =AW31/AX31 -> #DIV/0! | AZ31: ='26'!E24 -> 0 | BA31: ='26'!F24 -> 0 | BB31: =AZ31/BA31 -> #DIV/0! | BC31: ='26'!E25 -> 0 | BD31: ='26'!F25 -> 0 | BE31: =BC31/BD31 -> #DIV/0! | BF31: ='26'!E26 -> 0 | BG31: ='26'!F26 -> 0 | BH31: =BF31/BG31 -> #DIV/0! | BI31: ='26'!E27 -> 0 | BJ31: ='26'!F27 -> 0 | BK31: =BI31/BJ31 -> #DIV/0! | BL31: =G31+J31+M31+P31+S31+V31+Y31 -> 0 | BM31: =BL31+BI31+BF31+BC31+AZ31+AW31+AS31+AP31+AM31+AL31+AK31+AH31+AE31+AB31 -> 0
A32: 46261 | B32: ='27'!C4 -> 0 | C32: ='27'!D4 -> 0 | D32: ='27'!E4 -> 0 | E32: ='27'!F4 -> 0 | F32: =SUM(B32:E32) -> 0 | G32: ='27'!E6 -> 0 | H32: ='27'!F6 -> 0 | I32: =G32/H32 -> #DIV/0! | J32: ='27'!E7 -> 0 | K32: ='27'!F7 -> 0 | L32: =J32/K32 -> #DIV/0! | M32: ='27'!E8 -> 0 | N32: ='27'!F8 -> 0 | O32: =M32/N32 -> #DIV/0! | P32: ='27'!E9 -> 0 | Q32: ='27'!F9 -> 0 | R32: =AVERAGE(P32/Q32) -> #DIV/0! | S32: ='27'!E10 -> 0 | T32: ='27'!F10 -> 0 | U32: =AVERAGE(S32/T32) -> #DIV/0! | V32: ='27'!E12 -> 0 | W32: ='27'!F12 -> 0 | X32: =V32/W32 -> #DIV/0! | Y32: ='27'!E13 -> 0 | Z32: ='27'!F13 -> 0 | AA32: =Y32/Z32 -> #DIV/0! | AB32: ='27'!E14 -> 0 | AC32: ='27'!F14 -> 0 | AD32: =AB32/AC32 -> #DIV/0! | AE32: ='27'!E15 -> 0 | AF32: ='27'!F15 -> 0 | AG32: =AE32/AF32 -> #DIV/0! | AH32: ='27'!E16 -> 0 | AI32: ='27'!F16 -> 0 | AJ32: =AH32/AI32 -> #DIV/0! | AK32: ='27'!E17 -> 0 | AL32: ='27'!E18 -> 0 | AM32: ='27'!E19 -> 0 | AN32: ='27'!F19 -> 0 | AO32: =AM32/AN32 -> #DIV/0! | AP32: ='27'!E20 -> 0 | AQ32: ='27'!F20 -> 0 | AR32: =AP32/AQ32 -> #DIV/0! | AS32: ='27'!E21 -> 0 | AT32: ='27'!E22 -> 0 | AU32: ='27'!F22 -> 0 | AV32: =AT32/AU32 -> #DIV/0! | AW32: ='27'!E23 -> 0 | AX32: ='27'!F23 -> 0 | AY32: =AW32/AX32 -> #DIV/0! | AZ32: ='27'!E24 -> 0 | BA32: ='27'!F24 -> 0 | BB32: =AZ32/BA32 -> #DIV/0! | BC32: ='27'!E25 -> 0 | BD32: ='27'!F25 -> 0 | BE32: =BC32/BD32 -> #DIV/0! | BF32: ='27'!E26 -> 0 | BG32: ='27'!F26 -> 0 | BH32: =BF32/BG32 -> #DIV/0! | BI32: ='27'!E27 -> 0 | BJ32: ='27'!F27 -> 0 | BK32: =BI32/BJ32 -> #DIV/0! | BL32: =G32+J32+M32+P32+S32+V32+Y32 -> 0 | BM32: =BL32+BI32+BF32+BC32+AZ32+AW32+AS32+AP32+AM32+AL32+AK32+AH32+AE32+AB32 -> 0
A33: 46262 | B33: ='28'!C4 -> 0 | C33: ='28'!D4 -> 0 | D33: ='28'!E4 -> 0 | E33: ='28'!F4 -> 0 | F33: =SUM(B33:E33) -> 0 | G33: ='28'!E6 -> 0 | H33: ='28'!F6 -> 0 | I33: =G33/H33 -> #DIV/0! | J33: ='28'!E7 -> 0 | K33: ='28'!F7 -> 0 | L33: =J33/K33 -> #DIV/0! | M33: ='28'!E8 -> 0 | N33: ='28'!F8 -> 0 | O33: =M33/N33 -> #DIV/0! | P33: ='28'!E9 -> 0 | Q33: ='28'!F9 -> 0 | R33: =AVERAGE(P33/Q33) -> #DIV/0! | S33: ='28'!E10 -> 0 | T33: ='28'!F10 -> 0 | U33: =AVERAGE(S33/T33) -> #DIV/0! | V33: ='28'!E12 -> 0 | W33: ='28'!F12 -> 0 | X33: =V33/W33 -> #DIV/0! | Y33: ='28'!E13 -> 0 | Z33: ='28'!F13 -> 0 | AA33: =Y33/Z33 -> #DIV/0! | AB33: ='28'!E14 -> 0 | AC33: ='28'!F14 -> 0 | AD33: =AB33/AC33 -> #DIV/0! | AE33: ='28'!E15 -> 0 | AF33: ='28'!F15 -> 0 | AG33: =AE33/AF33 -> #DIV/0! | AH33: ='28'!E16 -> 0 | AI33: ='28'!F16 -> 0 | AJ33: =AH33/AI33 -> #DIV/0! | AK33: ='28'!E17 -> 0 | AL33: ='28'!E18 -> 0 | AM33: ='28'!E19 -> 0 | AN33: ='28'!F19 -> 0 | AO33: =AM33/AN33 -> #DIV/0! | AP33: ='28'!E20 -> 0 | AQ33: ='28'!F20 -> 0 | AR33: =AP33/AQ33 -> #DIV/0! | AS33: ='28'!E21 -> 0 | AT33: ='28'!E22 -> 0 | AU33: ='28'!F22 -> 0 | AV33: =AT33/AU33 -> #DIV/0! | AW33: ='28'!E26 -> 0 | AX33: ='28'!F26 -> 0 | AY33: =AW33/AX33 -> #DIV/0! | AZ33: ='28'!E24 -> 0 | BA33: ='28'!F24 -> 0 | BB33: =AZ33/BA33 -> #DIV/0! | BC33: ='28'!E25 -> 0 | BD33: ='28'!F25 -> 0 | BE33: =BC33/BD33 -> #DIV/0! | BF33: ='28'!E26 -> 0 | BG33: ='28'!F26 -> 0 | BH33: =BF33/BG33 -> #DIV/0! | BI33: ='28'!E27 -> 0 | BJ33: ='28'!F27 -> 0 | BK33: =BI33/BJ33 -> #DIV/0! | BL33: =G33+J33+M33+P33+S33+V33+Y33 -> 0 | BM33: =BL33+BI33+BF33+BC33+AZ33+AW33+AS33+AP33+AM33+AL33+AK33+AH33+AE33+AB33 -> 0
A34: 46263 | B34: ='29'!C4 -> 0 | C34: ='29'!D4 -> 0 | D34: ='29'!E4 -> 0 | E34: ='29'!F4 -> 0 | F34: =SUM(B34:E34) -> 0 | G34: ='29'!E6 -> 0 | H34: ='29'!F6 -> 0 | I34: =G34/H34 -> #DIV/0! | J34: ='29'!E7 -> 0 | K34: ='29'!F7 -> 0 | L34: =J34/K34 -> #DIV/0! | M34: ='29'!E8 -> 0 | N34: ='29'!F8 -> 0 | O34: =M34/N34 -> #DIV/0! | P34: ='29'!E9 -> 0 | Q34: ='29'!F9 -> 0 | R34: =AVERAGE(P34/Q34) -> #DIV/0! | S34: ='29'!E10 -> 0 | T34: ='29'!F10 -> 0 | U34: =AVERAGE(S34/T34) -> #DIV/0! | V34: ='29'!E12 -> 0 | W34: ='29'!F12 -> 0 | X34: =V34/W34 -> #DIV/0! | Y34: ='29'!E13 -> 0 | Z34: ='29'!F13 -> 0 | AA34: =Y34/Z34 -> #DIV/0! | AB34: ='29'!E14 -> 0 | AC34: ='29'!F14 -> 0 | AD34: =AB34/AC34 -> #DIV/0! | AE34: ='29'!E15 -> 0 | AF34: ='29'!F15 -> 0 | AG34: =AE34/AF34 -> #DIV/0! | AH34: ='29'!E16 -> 0 | AI34: ='29'!F16 -> 0 | AJ34: =AH34/AI34 -> #DIV/0! | AK34: ='29'!E17 -> 0 | AL34: ='29'!E18 -> 0 | AM34: ='29'!E19 -> 0 | AN34: ='29'!F19 -> 0 | AO34: =AM34/AN34 -> #DIV/0! | AP34: ='29'!E20 -> 0 | AQ34: ='29'!F20 -> 0 | AR34: =AP34/AQ34 -> #DIV/0! | AS34: ='29'!E21 -> 0 | AT34: ='29'!E22 -> 0 | AU34: ='29'!F22 -> 0 | AV34: =AT34/AU34 -> #DIV/0! | AW34: ='29'!E23 -> 0 | AX34: ='29'!F23 -> 0 | AY34: =AW34/AX34 -> #DIV/0! | AZ34: ='29'!E24 -> 0 | BA34: ='29'!F24 -> 0 | BB34: =AZ34/BA34 -> #DIV/0! | BC34: ='29'!E25 -> 0 | BD34: ='29'!F25 -> 0 | BE34: =BC34/BD34 -> #DIV/0! | BF34: ='29'!E26 -> 0 | BG34: ='29'!F26 -> 0 | BH34: =BF34/BG34 -> #DIV/0! | BI34: ='29'!E27 -> 0 | BJ34: ='29'!F27 -> 0 | BK34: =BI34/BJ34 -> #DIV/0! | BL34: =G34+J34+M34+P34+S34+V34+Y34 -> 0 | BM34: =BL34+BI34+BF34+BC34+AZ34+AW34+AS34+AP34+AM34+AL34+AK34+AH34+AE34+AB34 -> 0
A35: 46264 | B35: ='30'!C4 -> 0 | C35: ='30'!D4 -> 0 | D35: ='30'!E4 -> 0 | E35: ='30'!F4 -> 0 | F35: =SUM(B35:E35) -> 0 | G35: ='30'!E6 -> 0 | H35: ='30'!F6 -> 0 | I35: =G35/H35 -> #DIV/0! | J35: ='30'!E7 -> 0 | K35: ='30'!F7 -> 0 | L35: =J35/K35 -> #DIV/0! | M35: ='30'!E8 -> 0 | N35: ='30'!F8 -> 0 | O35: =M35/N35 -> #DIV/0! | P35: ='30'!E9 -> 0 | Q35: ='30'!F9 -> 0 | R35: =AVERAGE(P35/Q35) -> #DIV/0! | S35: ='30'!E10 -> 0 | T35: ='30'!F10 -> 0 | U35: =AVERAGE(S35/T35) -> #DIV/0! | V35: ='30'!E12 -> 0 | W35: ='30'!F12 -> 0 | X35: =V35/W35 -> #DIV/0! | Y35: ='30'!E13 -> 0 | Z35: ='30'!F13 -> 0 | AA35: =Y35/Z35 -> #DIV/0! | AB35: ='30'!E14 -> 0 | AC35: ='30'!F14 -> 0 | AD35: =AB35/AC35 -> #DIV/0! | AE35: ='30'!E15 -> 0 | AF35: ='30'!F15 -> 0 | AG35: =AE35/AF35 -> #DIV/0! | AH35: ='30'!E16 -> 0 | AI35: ='30'!F16 -> 0 | AJ35: =AH35/AI35 -> #DIV/0! | AK35: ='30'!E17 -> 0 | AL35: ='30'!E18 -> 0 | AM35: ='30'!E19 -> 0 | AN35: ='30'!F19 -> 0 | AO35: =AM35/AN35 -> #DIV/0! | AP35: ='30'!E20 -> 0 | AQ35: ='30'!F20 -> 0 | AR35: =AP35/AQ35 -> #DIV/0! | AS35: ='30'!E21 -> 0 | AT35: ='30'!E22 -> 0 | AU35: ='30'!F22 -> 0 | AV35: =AT35/AU35 -> #DIV/0! | AW35: ='30'!E23 -> 0 | AX35: ='30'!F23 -> 0 | AY35: =AW35/AX35 -> #DIV/0! | AZ35: ='30'!E24 -> 0 | BA35: ='30'!F24 -> 0 | BB35: =AZ35/BA35 -> #DIV/0! | BC35: ='30'!E25 -> 0 | BD35: ='30'!F25 -> 0 | BE35: =BC35/BD35 -> #DIV/0! | BF35: ='30'!E26 -> 0 | BG35: ='30'!F26 -> 0 | BH35: =BF35/BG35 -> #DIV/0! | BI35: ='30'!E27 -> 0 | BJ35: ='30'!F27 -> 0 | BK35: =BI35/BJ35 -> #DIV/0! | BL35: =G35+J35+M35+P35+S35+#REF!+V35+Y35 -> #REF! | BM35: =BL35+BI35+BF35+BC35+AZ35+AW35+AS35+AP35+AM35+AL35+AK35+AH35+AE35+AB35 -> #REF!
A36: 46265 | B36: ='31'!C4 -> 0 | C36: ='31'!D4 -> 0 | D36: ='31'!E4 -> 0 | E36: ='31'!F4 -> 0 | F36: =SUM(B36:E36) -> 0 | G36: ='31'!E6 -> 0 | H36: ='31'!F6 -> 0 | I36: =G36/H36 -> #DIV/0! | J36: ='31'!E7 -> 0 | K36: ='31'!F7 -> 0 | L36: =J36/K36 -> #DIV/0! | M36: ='31'!E8 -> 0 | N36: ='31'!F8 -> 0 | O36: =M36/N36 -> #DIV/0! | P36: ='31'!E9 -> 0 | Q36: ='31'!F9 -> 0 | R36: =AVERAGE(P36/Q36) -> #DIV/0! | S36: ='31'!E10 -> 0 | T36: ='31'!F10 -> 0 | U36: =AVERAGE(S36/T36) -> #DIV/0! | V36: ='31'!E11 -> 0 | W36: ='31'!F11 -> 0 | X36: =V36/W36 -> #DIV/0! | Y36: ='31'!E12 -> 0 | Z36: ='31'!F12 -> 0 | AA36: =Y36/Z36 -> #DIV/0! | AB36: ='31'!E13 -> 0 | AC36: ='31'!F13 -> 0 | AD36: =AB36/AC36 -> #DIV/0! | AE36: ='31'!E14 -> 0 | AF36: ='31'!F14 -> 0 | AG36: =AE36/AF36 -> #DIV/0! | AH36: ='31'!E15 -> 0 | AI36: ='31'!F15 -> 0 | AJ36: =AH36/AI36 -> #DIV/0! | AK36: ='31'!E16 -> 0 | AL36: ='31'!E17 -> 0 | AM36: ='31'!E18 -> 0 | AN36: ='31'!F18 -> 0 | AO36: =AM36/AN36 -> #DIV/0! | AP36: ='31'!E19 -> 0 | AQ36: ='31'!F19 -> 0 | AR36: =AP36/AQ36 -> #DIV/0! | AS36: ='31'!E20 -> 0 | AT36: ='31'!E21 -> 0 | AU36: ='31'!F21 -> 0 | AV36: =AT36/AU36 -> #DIV/0! | AW36: ='31'!E22 -> 0 | AX36: ='31'!F22 -> 0 | AY36: =AW36/AX36 -> #DIV/0! | AZ36: ='31'!E23 -> 0 | BA36: ='31'!F23 -> 0 | BB36: =AZ36/BA36 -> #DIV/0! | BC36: ='31'!E24 -> 0 | BD36: ='31'!F24 -> 0 | BE36: =BC36/BD36 -> #DIV/0! | BF36: ='31'!E25 -> 0 | BG36: ='31'!F25 -> 0 | BH36: =BF36/BG36 -> #DIV/0! | BI36: ='31'!E26 -> 0 | BJ36: ='31'!F26 -> 0 | BK36: =BI36/BJ36 -> #DIV/0! | BL36: =G36+J36+M36+P36+S36+#REF!+V36+Y36 -> #REF! | BM36: =BL36+BI36+BF36+BC36+AZ36+AW36+AS36+AP36+AM36+AL36+AK36+AH36+AE36+AB36 -> #REF!
A37: TOTAL:- | B37: =SUM(B21:B36) -> 115.5 | C37: =SUM(C21:C36) -> 4.5 | D37: =SUM(D21:D36) -> 0 | E37: =SUM(E21:E36) -> 0 | F37: =SUM(F21:F36) -> 120 | G37: =SUM(G21:G36) -> 1092 | H37: =SUM(H21:H36) -> 118.5 | I37: =G37/H37 -> 9.2151899 | J37: =SUM(J21:J36) -> 301 | K37: =SUM(K21:K36) -> 15.5 | L37: =J37/K37 -> 19.419355 | M37: =SUM(M21:M36) -> 538 | N37: =SUM(N21:N36) -> 80 | O37: =M37/N37 -> 6.725 | P37: =SUM(P21:P36) -> 247 | Q37: =SUM(Q21:Q36) -> 40 | R37: =P37/Q37 -> 6.175 | S37: =SUM(S21:S36) -> 0 | T37: =SUM(T21:T36) -> 0 | U37: =S37/T37 -> #DIV/0! | V37: =SUM(V21:V36) -> 0 | W37: =SUM(W21:W36) -> 0 | X37: =V37/W37 -> #DIV/0! | Y37: =SUM(Y21:Y36) -> 9 | Z37: =SUM(Z21:Z36) -> 3 | AA37: =Y37/Z37 -> 3 | AB37: =AB21+AB22+AB23+AB24+AB25+AB26+AB27+AB28+AB29+AB30+AB31+AB32+AB33+AB34+AB35+AB36 -> 0 | AC37: =AC21+AC22+AC23+AC24+AC25+AC26+AC27+AC28+AC29+AC30+AC31+AC32+AC33+AC34+AC35+AC36 -> 0 | AD37: =AB37/AC37 -> #DIV/0! | AE37: =SUM(AE21:AE36) -> 0 | AF37: =SUM(AF21:AF36) -> 0 | AG37: =AE37/AF37 -> #DIV/0! | AH37: =SUM(AH21:AH36) -> 0 | AI37: =SUM(AI21:AI36) -> 0 | AJ37: =AH37/AI37 -> #DIV/0! | AK37: =SUM(AK21:AK36) -> 25 | AL37: =SUM(AL21:AL36) -> 0 | AM37: =SUM(AM21:AM36) -> 0 | AN37: =SUM(AN21:AN36) -> 0 | AO37: =AM37/AN37 -> #DIV/0! | AP37: =SUM(AP21:AP36) -> 0 | AQ37: =SUM(AQ21:AQ36) -> 0 | AR37: =AP37/AQ37 -> #DIV/0! | AS37: =SUM(AS21:AS36) -> 0 | AT37: =SUM(AT21:AT36) -> 0 | AU37: =SUM(AU21:AU36) -> 0 | AV37: =AT37/AU37 -> #DIV/0! | AW37: =SUM(AW21:AW36) -> 0 | AX37: =SUM(AX21:AX36) -> 0 | AY37: =AW37/AX37 -> #DIV/0! | AZ37: =SUM(AZ21:AZ36) -> 0 | BA37: =SUM(BA21:BA36) -> 0 | BB37: =AZ37/BA37 -> #DIV/0! | BC37: =SUM(BC21:BC36) -> 0 | BD37: =SUM(BD21:BD36) -> 0 | BE37: =BC37/BD37 -> #DIV/0! | BF37: =SUM(BF21:BF36) -> 0 | BG37: =SUM(BG21:BG36) -> 0 | BH37: =BF37/BG37 -> #DIV/0! | BI37: =SUM(BI21:BI36) -> 0 | BJ37: =SUM(BJ21:BJ36) -> 0 | BK37: =BI37/BJ37 -> #DIV/0! | BL37: =BL21+BL22+BL23+BL24+BL25+BL26+BL27+BL28+BL29+BL30+BL31+BL32+BL33+BL34+BL35+BL36 -> #REF! | BM37: =BM21+BM22+BM23+BM24+BM25+BM26+BM27+BM28+BM29+BM30+BM31+BM32+BM33+BM34+BM35+BM36 -> #REF!
A38: GRAND TOTAL:- | B38: =SUM(B37,B20) -> 308.5 | C38: =SUM(C37,C20) -> 57.5 | D38: =SUM(D37,D20) -> 107 | E38: =SUM(E37,E20) -> 0 | F38: =SUM(F37,F20) -> 473 | G38: =SUM(G37,G20) -> 2792 | H38: =SUM(H37,H20) -> 349.1 | I38: =G38/H38 -> 7.9977084 | J38: =SUM(J37,J20) -> 1404 | K38: =SUM(K37,K20) -> 78 | L38: =J38/K38 -> 18 | M38: =SUM(M37,M20) -> 1504 | N38: =SUM(N37,N20) -> 236 | O38: =M38/N38 -> 6.3728814 | P38: =SUM(P37,P20) -> 1496 | Q38: =SUM(Q37,Q20) -> 244 | R38: =P38/Q38 -> 6.1311475 | S38: =SUM(S37,S20) -> 0 | T38: =SUM(T37,T20) -> 0 | U38: =S38/T38 -> #DIV/0! | V38: =SUM(V37,V20) -> 0 | W38: =SUM(W37,W20) -> 0 | X38: =V38/W38 -> #DIV/0! | Y38: =SUM(Y37,Y20) -> 24 | Z38: =SUM(Z37,Z20) -> 8 | AA38: =Y38/Z38 -> 3 | AB38: =AB20+AB37 -> 0 | AC38: =AC20+AC37 -> 0 | AD38: =AB38/AC38 -> #DIV/0! | AE38: =SUM(AE37,AE20) -> 0 | AF38: =SUM(AF37,AF20) -> 0 | AG38: =AE38/AF38 -> #DIV/0! | AH38: =SUM(AH37,AH20) -> 0 | AI38: =SUM(AI37,AI20) -> 0 | AJ38: =AH38/AI38 -> #DIV/0! | AK38: =SUM(AK37,AK20) -> 35 | AL38: =SUM(AL37,AL20) -> 0 | AM38: =SUM(AM37,AM20) -> 0 | AN38: =SUM(AN37,AN20) -> 0 | AO38: =AM38/AN38 -> #DIV/0! | AP38: =SUM(AP37,AP20) -> 0 | AQ38: =SUM(AQ37,AQ20) -> 0 | AR38: =AP38/AQ38 -> #DIV/0! | AS38: =SUM(AS37,AS20) -> 0 | AT38: =SUM(AT37,AT20) -> 0 | AU38: =SUM(AU37,AU20) -> 0 | AV38: =SUM(AV37,AV20) -> #DIV/0! | AW38: =SUM(AW37,AW20) -> 0 | AX38: =SUM(AX37,AX20) -> 0 | AY38: =SUM(AY37,AY20) -> #DIV/0! | AZ38: =SUM(AZ37,AZ20) -> 0 | ... BK38: =SUM(BK37,BK20) -> #DIV/0! | BL38: =BL20+BL37 -> #REF! | BM38: =BM20+BM37 -> #REF!

Sheet Oil Tracking Sheet
A1: OIL TRACKING SHEET
A2: RIG NO: | C2: GTC-100-1 | E2: OPERATOR: | G2: ONGC.ANKLESHWAR ASSET | H2: FIELD: | K2: ONGC.ANKLESHWAR | M2: MONTH:- | P2: 46235
A3: NOTE:- PLEASE FILL OIL QTY IN LITER'S ONLY
A4: OIL TYPE | B4: DATE | C4: OPENING STOCK | D4: RECEIVED QTY | E4: QTY CONSUMPTION OF OIL | G4: CONSUMED FOR EQUIPMENT ASSET CODE | H4: TOTAL CONSUMED | I4: CLOSING BALANCE | J4: BURNT OIL OPENING BALANCE | K4: BURNT OIL EXTRACTED QTY | L4: BURNT OIL CONSUMED QTY | M4: BURNT OIL QTY SENT | N4: DETAILS OF BURNT OIL SENT | Q4: TOTAL BALANCE BURNT OIL AT SITE
E5: FOR SERVICE | F5: FOR TOP-UP | N5: DATE | O5: GATE PASS NO | P5: LOCATION
A6: ENGINE OIL (15W40) | B6: 46235 | C6: ='1'!B35 -> 107 | D6: ='1'!C35 -> 0 | H6: =SUM(E6,F6) -> 0 | I6: =SUM(C6,D6-H6) -> 107 | J6: 0 | Q6: =SUM(J6+K6-L6-M6) -> 0
B7: 46236 | C7: =I6 -> 107 | D7: ='2'!C35 -> 0 | H7: =SUM(E7,F7) -> 0 | I7: =SUM(C7,D7-H7) -> 107 | J7: =Q6 -> 0 | Q7: =SUM(J7+K7-L7-M7) -> 0
B8: 46237 | C8: =I7 -> 107 | D8: ='3'!C35 -> 0 | F8: 15 | G8: 5 ltr top up In rig engine & 10 ltr top up in mud pump engine. | H8: =SUM(E8,F8) -> 15 | I8: =SUM(C8,D8-H8) -> 92 | J8: =Q7 -> 0 | Q8: =SUM(J8+K8-L8-M8) -> 0
B9: 46238 | C9: =I8 -> 92 | D9: ='4'!C35 -> 0 | H9: =SUM(E9,F9) -> 0 | I9: =SUM(C9,D9-H9) -> 92 | J9: =Q8 -> 0 | Q9: =SUM(J9+K9-L9-M9) -> 0
