Workbook

Sheet 1
A1: Rig No: | B1: Rig 50-02 | C1: Daily Mechanical Report | P1: Date: | Q1: 01-08-2026
A2: Well No: | B2: PLAN
A3: Diesel Engines
A4: Sr No | B4: Equipment | C4: Make/Model | D4: M/C Serial No | E4: Is in Use | F4: Hours Run | H4: Lube Oil Pressure | I4: Lube Oil Added | J4: Opning Running HRS | K4: Total Run Hours | L4: Closing HRS | M4: Last Service Hours | N4: Running HRS after last service | O4: Define hours | P4: Hours Remaining For Next Service. | Q4: Preventive /Predictive Maintenance Details | R4: Remarks | S4: LAST SERVICE DONE
E5: Yes/No | F5: DAY | G5: NIGHT | H5: psi/bar | I5: Liters
A6: 1 | B6: Rig Engine | C6: CAT 09 | D6: JSC08784 | E6: Yes | J6: 35228 | K6: =F6+G6 -> #VALUE! | L6: =J6+K6 -> #VALUE! | M6: 35028 | N6: =L6-M6 -> #VALUE! | O6: 500 | P6: =O6-N6 -> #VALUE! | S6: LAST SERVICE DONE @ 35028 HRS. DT- 2026-07-01
A7: 2 | B7: Rig Carrier Transmission | C7: CAT 09 | D7: 8620008307 | E7: Yes | J7: 35224 | K7: =F7+G7 -> #VALUE! | L7: =J7+K7 -> #VALUE! | M7: 35024 | N7: =L7-M7 -> #VALUE! | O7: 500 | P7: =O7-N7 -> #VALUE! | S7: LAST SERVICE DONE @ 35024 HRS. DT- 2026-07-01
A8: 3 | B8: Mud Pump Engine | C8: CAT 15 | D8: BEM00178 | E8: Yes | J8: 28530 | K8: =F8+G8 -> #VALUE! | L8: =J8+K8 -> #VALUE! | M8: 28330 | N8: =L8-M8 -> #VALUE! | O8: 1500 | P8: =O8-N8 -> #VALUE! | S8: LAST SERVICE DONE @ 28330 HRS. DT- 2026-07-01
A9: 4 | B9: Mud pump transmission | C9: CAT 15 | D9: 2901750 | E9: Yes | J9: 28530 | K9: =F9+G9 -> #VALUE! | L9: =J9+K9 -> #VALUE! | M9: 28330 | N9: =L9-M9 -> #VALUE! | O9: 1500 | P9: =O9-N9 -> #VALUE! | S9: LAST SERVICE DONE @ 28330 HRS. DT- 2026-07-01
A10: 5 | B10: Air Compressor Electrical | C10: KIRLOSKAR | D10: PT 300 T | E10: Yes | J10: 0 | K10: =F10+G10 -> #VALUE! | L10: =J10+K10 -> #VALUE! | M10: -200 | N10: =L10-M10 -> #VALUE! | O10: 500 | P10: =O10-N10 -> #VALUE! | S10: LAST SERVICE DONE @ -200 HRS. DT- 2026-07-01
A11: 6 | B11: Air Compressor Mechanical | C11: KIRLOSKAR | D11: 02.1281/2420149 | E11: Yes | J11: 1107 | K11: =F11+G11 -> #VALUE! | L11: =J11+K11 -> #VALUE! | M11: 907 | N11: =L11-M11 -> #VALUE! | O11: 500 | P11: =O11-N11 -> #VALUE! | S11: LAST SERVICE DONE @ 907 HRS. DT- 2026-07-01
A12: 7 | B12: Fire Pump | C12: KIRLOSKAR | D12: 4H.2709.20/1220003 | E12: Yes | J12: 1753 | K12: =F12+G12 -> #VALUE! | L12: =J12+K12 -> #VALUE! | M12: 1553 | N12: =L12-M12 -> #VALUE! | O12: 1500 | P12: =O12-N12 -> #VALUE! | S12: LAST SERVICE DONE @ 1553 HRS. DT- 2026-07-01
A25: Generator
A26: Sr No | B26: Equipment | C26: Make/Model | D26: M/C Serial No | E26: Is in Use | F26: Hours Run | H26: Lube Oil Pressure | I26: Lube Oil Added | J26: Opning Running HRS | K26: Total Run Hours | L26: Closing HRS | M26: Last Service Hours | N26: Running HRS after last service | O26: Define hours | P26: Hours Remaining For Next Service. | Q26: Preventive /Predictive Maintenance Details | R26: Remarks | S26: LAST SERVICE DONE
E27: Yes/No | F27: DAY | G27: NIGHT | H27: psi/bar | I27: Liters
A28: 1 | B28: Rig Site Generator Set 1, 125 KVA | C28: Cummins | D28: P84089603 | E28: Yes | J28: 25566 | K28: =F28+G28 -> #VALUE! | L28: =J28+K28 -> #VALUE! | M28: 25366 | N28: =L28-M28 -> #VALUE! | O28: 500 | P28: =O28-N28 -> #VALUE! | S28: LAST SERVICE DONE @ 25366 HRS. DT- 2026-07-01
A29: 2 | B29: Rig Site Generator Set 2, 125 KVA | C29: Cummins | D29: P84089932 | E29: Yes | J29: 27583 | K29: =F29+G29 -> #VALUE! | L29: =J29+K29 -> #VALUE! | M29: 27383 | N29: =L29-M29 -> #VALUE! | O29: 500 | P29: =O29-N29 -> #VALUE! | S29: LAST SERVICE DONE @ 27383 HRS. DT- 2026-07-01
A30: 3 | B30: Rig Site Generator Set 3, 15 KVA | C30: Cummins | D30: 31295 | E30: Yes | J30: 837 | K30: =F30+G30 -> #VALUE! | L30: =J30+K30 -> #VALUE! | M30: 637 | N30: =L30-M30 -> #VALUE! | O30: 500 | P30: =O30-N30 -> #VALUE! | S30: LAST SERVICE DONE @ 637 HRS. DT- 2026-07-01
A31: 4 | B31: DG-125 KVA SUPERNOVA | C31: SUPERNOVS | D31: SN-6003 | E31: Yes | J31: 1249 | K31: =F31+G31 -> #VALUE! | L31: =J31+K31 -> #VALUE! | M31: 1049 | N31: =L31-M31 -> #VALUE! | O31: 500 | P31: =O31-N31 -> #VALUE! | S31: LAST SERVICE DONE @ 1049 HRS. DT- 2026-07-01

Sheet 2
A1: Rig No: | B1: Rig 50-02 | C1: Daily Mechanical Report | P1: Date: | Q1: 02-08-2026
A2: Well No: | B2: PLAN
A3: Diesel Engines
A4: Sr No | B4: Equipment | C4: Make/Model | D4: M/C Serial No | E4: Is in Use | F4: Hours Run | H4: Lube Oil Pressure | I4: Lube Oil Added | J4: Opning Running HRS | K4: Total Run Hours | L4: Closing HRS | M4: Last Service Hours | N4: Running HRS after last service | O4: Define hours | P4: Hours Remaining For Next Service. | Q4: Preventive /Predictive Maintenance Details | R4: Remarks | S4: LAST SERVICE DONE
E5: Yes/No | F5: DAY | G5: NIGHT | H5: psi/bar | I5: Liters
A6: 1 | B6: Rig Engine | C6: CAT 09 | D6: JSC08784 | E6: Yes | J6: ='1'!L6 -> #VALUE! | K6: =F6+G6 -> #VALUE! | L6: =J6+K6 -> #VALUE! | M6: 35028 | N6: =L6-M6 -> #VALUE! | O6: 500 | P6: =O6-N6 -> #VALUE! | S6: LAST SERVICE DONE @ 35028 HRS. DT- 2026-07-01
A7: 2 | B7: Rig Carrier Transmission | C7: CAT 09 | D7: 8620008307 | E7: Yes | J7: ='1'!L7 -> #VALUE! | K7: =F7+G7 -> #VALUE! | L7: =J7+K7 -> #VALUE! | M7: 35024 | N7: =L7-M7 -> #VALUE! | O7: 500 | P7: =O7-N7 -> #VALUE! | S7: LAST SERVICE DONE @ 35024 HRS. DT- 2026-07-01
A8: 3 | B8: Mud Pump Engine | C8: CAT 15 | D8: BEM00178 | E8: Yes | J8: ='1'!L8 -> #VALUE! | K8: =F8+G8 -> #VALUE! | L8: =J8+K8 -> #VALUE! | M8: 28330 | N8: =L8-M8 -> #VALUE! | O8: 1500 | P8: =O8-N8 -> #VALUE! | S8: LAST SERVICE DONE @ 28330 HRS. DT- 2026-07-01
A9: 4 | B9: Mud pump transmission | C9: CAT 15 | D9: 2901750 | E9: Yes | J9: ='1'!L9 -> #VALUE! | K9: =F9+G9 -> #VALUE! | L9: =J9+K9 -> #VALUE! | M9: 28330 | N9: =L9-M9 -> #VALUE! | O9: 1500 | P9: =O9-N9 -> #VALUE! | S9: LAST SERVICE DONE @ 28330 HRS. DT- 2026-07-01
A10: 5 | B10: Air Compressor Electrical | C10: KIRLOSKAR | D10: PT 300 T | E10: Yes | J10: ='1'!L10 -> #VALUE! | K10: =F10+G10 -> #VALUE! | L10: =J10+K10 -> #VALUE! | M10: -200 | N10: =L10-M10 -> #VALUE! | O10: 500 | P10: =O10-N10 -> #VALUE! | S10: LAST SERVICE DONE @ -200 HRS. DT- 2026-07-01
A11: 6 | B11: Air Compressor Mechanical | C11: KIRLOSKAR | D11: 02.1281/2420149 | E11: Yes | J11: ='1'!L11 -> #VALUE! | K11: =F11+G11 -> #VALUE! | L11: =J11+K11 -> #VALUE! | M11: 907 | N11: =L11-M11 -> #VALUE! | O11: 500 | P11: =O11-N11 -> #VALUE! | S11: LAST SERVICE DONE @ 907 HRS. DT- 2026-07-01
A12: 7 | B12: Fire Pump | C12: KIRLOSKAR | D12: 4H.2709.20/1220003 | E12: Yes | J12: ='1'!L12 -> #VALUE! | K12: =F12+G12 -> #VALUE! | L12: =J12+K12 -> #VALUE! | M12: 1553 | N12: =L12-M12 -> #VALUE! | O12: 1500 | P12: =O12-N12 -> #VALUE! | S12: LAST SERVICE DONE @ 1553 HRS. DT- 2026-07-01
A25: Generator
A26: Sr No | B26: Equipment | C26: Make/Model | D26: M/C Serial No | E26: Is in Use | F26: Hours Run | H26: Lube Oil Pressure | I26: Lube Oil Added | J26: Opning Running HRS | K26: Total Run Hours | L26: Closing HRS | M26: Last Service Hours | N26: Running HRS after last service | O26: Define hours | P26: Hours Remaining For Next Service. | Q26: Preventive /Predictive Maintenance Details | R26: Remarks | S26: LAST SERVICE DONE
E27: Yes/No | F27: DAY | G27: NIGHT | H27: psi/bar | I27: Liters
A28: 1 | B28: Rig Site Generator Set 1, 125 KVA | C28: Cummins | D28: P84089603 | E28: Yes | J28: ='1'!L28 -> #VALUE! | K28: =F28+G28 -> #VALUE! | L28: =J28+K28 -> #VALUE! | M28: 25366 | N28: =L28-M28 -> #VALUE! | O28: 500 | P28: =O28-N28 -> #VALUE! | S28: LAST SERVICE DONE @ 25366 HRS. DT- 2026-07-01
A29: 2 | B29: Rig Site Generator Set 2, 125 KVA | C29: Cummins | D29: P84089932 | E29: Yes | J29: ='1'!L29 -> #VALUE! | K29: =F29+G29 -> #VALUE! | L29: =J29+K29 -> #VALUE! | M29: 27383 | N29: =L29-M29 -> #VALUE! | O29: 500 | P29: =O29-N29 -> #VALUE! | S29: LAST SERVICE DONE @ 27383 HRS. DT- 2026-07-01
A30: 3 | B30: Rig Site Generator Set 3, 15 KVA | C30: Cummins | D30: 31295 | E30: Yes | J30: ='1'!L30 -> #VALUE! | K30: =F30+G30 -> #VALUE! | L30: =J30+K30 -> #VALUE! | M30: 637 | N30: =L30-M30 -> #VALUE! | O30: 500 | P30: =O30-N30 -> #VALUE! | S30: LAST SERVICE DONE @ 637 HRS. DT- 2026-07-01
A31: 4 | B31: DG-125 KVA SUPERNOVA | C31: SUPERNOVS | D31: SN-6003 | E31: Yes | J31: ='1'!L31 -> #VALUE! | K31: =F31+G31 -> #VALUE! | L31: =J31+K31 -> #VALUE! | M31: 1049 | N31: =L31-M31 -> #VALUE! | O31: 500 | P31: =O31-N31 -> #VALUE! | S31: LAST SERVICE DONE @ 1049 HRS. DT- 2026-07-01

Sheet 3
A1: Rig No: | B1: Rig 50-02 | C1: Daily Mechanical Report | P1: Date: | Q1: 03-08-2026
A2: Well No: | B2: PLAN
A3: Diesel Engines
A4: Sr No | B4: Equipment | C4: Make/Model | D4: M/C Serial No | E4: Is in Use | F4: Hours Run | H4: Lube Oil Pressure | I4: Lube Oil Added | J4: Opning Running HRS | K4: Total Run Hours | L4: Closing HRS | M4: Last Service Hours | N4: Running HRS after last service | O4: Define hours | P4: Hours Remaining For Next Service. | Q4: Preventive /Predictive Maintenance Details | R4: Remarks | S4: LAST SERVICE DONE
E5: Yes/No | F5: DAY | G5: NIGHT | H5: psi/bar | I5: Liters
A6: 1 | B6: Rig Engine | C6: CAT 09 | D6: JSC08784 | E6: Yes | J6: ='2'!L6 -> #VALUE! | K6: =F6+G6 -> #VALUE! | L6: =J6+K6 -> #VALUE! | M6: 35028 | N6: =L6-M6 -> #VALUE! | O6: 500 | P6: =O6-N6 -> #VALUE! | S6: LAST SERVICE DONE @ 35028 HRS. DT- 2026-07-01
A7: 2 | B7: Rig Carrier Transmission | C7: CAT 09 | D7: 8620008307 | E7: Yes | J7: ='2'!L7 -> #VALUE! | K7: =F7+G7 -> #VALUE! | L7: =J7+K7 -> #VALUE! | M7: 35024 | N7: =L7-M7 -> #VALUE! | O7: 500 | P7: =O7-N7 -> #VALUE! | S7: LAST SERVICE DONE @ 35024 HRS. DT- 2026-07-01
A8: 3 | B8: Mud Pump Engine | C8: CAT 15 | D8: BEM00178 | E8: Yes | J8: ='2'!L8 -> #VALUE! | K8: =F8+G8 -> #VALUE! | L8: =J8+K8 -> #VALUE! | M8: 28330 | N8: =L8-M8 -> #VALUE! | O8: 1500 | P8: =O8-N8 -> #VALUE! | S8: LAST SERVICE DONE @ 28330 HRS. DT- 2026-07-01
A9: 4 | B9: Mud pump transmission | C9: CAT 15 | D9: 2901750 | E9: Yes | J9: ='2'!L9 -> #VALUE! | K9: =F9+G9 -> #VALUE! | L9: =J9+K9 -> #VALUE! | M9: 28330 | N9: =L9-M9 -> #VALUE! | O9: 1500 | P9: =O9-N9 -> #VALUE! | S9: LAST SERVICE DONE @ 28330 HRS. DT- 2026-07-01
A10: 5 | B10: Air Compressor Electrical | C10: KIRLOSKAR | D10: PT 300 T | E10: Yes | J10: ='2'!L10 -> #VALUE! | K10: =F10+G10 -> #VALUE! | L10: =J10+K10 -> #VALUE! | M10: -200 | N10: =L10-M10 -> #VALUE! | O10: 500 | P10: =O10-N10 -> #VALUE! | S10: LAST SERVICE DONE @ -200 HRS. DT- 2026-07-01
A11: 6 | B11: Air Compressor Mechanical | C11: KIRLOSKAR | D11: 02.1281/2420149 | E11: Yes | J11: ='2'!L11 -> #VALUE! | K11: =F11+G11 -> #VALUE! | L11: =J11+K11 -> #VALUE! | M11: 907 | N11: =L11-M11 -> #VALUE! | O11: 500 | P11: =O11-N11 -> #VALUE! | S11: LAST SERVICE DONE @ 907 HRS. DT- 2026-07-01
A12: 7 | B12: Fire Pump | C12: KIRLOSKAR | D12: 4H.2709.20/1220003 | E12: Yes | J12: ='2'!L12 -> #VALUE! | K12: =F12+G12 -> #VALUE! | L12: =J12+K12 -> #VALUE! | M12: 1553 | N12: =L12-M12 -> #VALUE! | O12: 1500 | P12: =O12-N12 -> #VALUE! | S12: LAST SERVICE DONE @ 1553 HRS. DT- 2026-07-01
A25: Generator
A26: Sr No | B26: Equipment | C26: Make/Model | D26: M/C Serial No | E26: Is in Use | F26: Hours Run | H26: Lube Oil Pressure | I26: Lube Oil Added | J26: Opning Running HRS | K26: Total Run Hours | L26: Closing HRS | M26: Last Service Hours | N26: Running HRS after last service | O26: Define hours | P26: Hours Remaining For Next Service. | Q26: Preventive /Predictive Maintenance Details | R26: Remarks | S26: LAST SERVICE DONE
E27: Yes/No | F27: DAY | G27: NIGHT | H27: psi/bar | I27: Liters
A28: 1 | B28: Rig Site Generator Set 1, 125 KVA | C28: Cummins | D28: P84089603 | E28: Yes | J28: ='2'!L28 -> #VALUE! | K28: =F28+G28 -> #VALUE! | L28: =J28+K28 -> #VALUE! | M28: 25366 | N28: =L28-M28 -> #VALUE! | O28: 500 | P28: =O28-N28 -> #VALUE! | S28: LAST SERVICE DONE @ 25366 HRS. DT- 2026-07-01
A29: 2 | B29: Rig Site Generator Set 2, 125 KVA | C29: Cummins | D29: P84089932 | E29: Yes | J29: ='2'!L29 -> #VALUE! | K29: =F29+G29 -> #VALUE! | L29: =J29+K29 -> #VALUE! | M29: 27383 | N29: =L29-M29 -> #VALUE! | O29: 500 | P29: =O29-N29 -> #VALUE! | S29: LAST SERVICE DONE @ 27383 HRS. DT- 2026-07-01
A30: 3 | B30: Rig Site Generator Set 3, 15 KVA | C30: Cummins | D30: 31295 | E30: Yes | J30: ='2'!L30 -> #VALUE! | K30: =F30+G30 -> #VALUE! | L30: =J30+K30 -> #VALUE! | M30: 637 | N30: =L30-M30 -> #VALUE! | O30: 500 | P30: =O30-N30 -> #VALUE! | S30: LAST SERVICE DONE @ 637 HRS. DT- 2026-07-01
A31: 4 | B31: DG-125 KVA SUPERNOVA | C31: SUPERNOVS | D31: SN-6003 | E31: Yes | J31: ='2'!L31 -> #VALUE! | K31: =F31+G31 -> #VALUE! | L31: =J31+K31 -> #VALUE! | M31: 1049 | N31: =L31-M31 -> #VALUE! | O31: 500 | P31: =O31-N31 -> #VALUE! | S31: LAST SERVICE DONE @ 1049 HRS. DT- 2026-07-01

Sheet 4
A1: Rig No: | B1: Rig 50-02 | C1: Daily Mechanical Report | P1: Date: | Q1: 04-08-2026
A2: Well No: | B2: PLAN
A3: Diesel Engines
A4: Sr No | B4: Equipment | C4: Make/Model | D4: M/C Serial No | E4: Is in Use | F4: Hours Run | H4: Lube Oil Pressure | I4: Lube Oil Added | J4: Opning Running HRS | K4: Total Run Hours | L4: Closing HRS | M4: Last Service Hours | N4: Running HRS after last service | O4: Define hours | P4: Hours Remaining For Next Service. | Q4: Preventive /Predictive Maintenance Details | R4: Remarks | S4: LAST SERVICE DONE
E5: Yes/No | F5: DAY | G5: NIGHT | H5: psi/bar | I5: Liters
A6: 1 | B6: Rig Engine | C6: CAT 09 | D6: JSC08784 | E6: Yes | J6: ='3'!L6 -> #VALUE! | K6: =F6+G6 -> #VALUE! | L6: =J6+K6 -> #VALUE! | M6: 35028 | N6: =L6-M6 -> #VALUE! | O6: 500 | P6: =O6-N6 -> #VALUE! | S6: LAST SERVICE DONE @ 35028 HRS. DT- 2026-07-01
A7: 2 | B7: Rig Carrier Transmission | C7: CAT 09 | D7: 8620008307 | E7: Yes | J7: ='3'!L7 -> #VALUE! | K7: =F7+G7 -> #VALUE! | L7: =J7+K7 -> #VALUE! | M7: 35024 | N7: =L7-M7 -> #VALUE! | O7: 500 | P7: =O7-N7 -> #VALUE! | S7: LAST SERVICE DONE @ 35024 HRS. DT- 2026-07-01
A8: 3 | B8: Mud Pump Engine | C8: CAT 15 | D8: BEM00178 | E8: Yes | J8: ='3'!L8 -> #VALUE! | K8: =F8+G8 -> #VALUE! | L8: =J8+K8 -> #VALUE! | M8: 28330 | N8: =L8-M8 -> #VALUE! | O8: 1500 | P8: =O8-N8 -> #VALUE! | S8: LAST SERVICE DONE @ 28330 HRS. DT- 2026-07-01
A9: 4 | B9: Mud pump transmission | C9: CAT 15 | D9: 2901750 | E9: Yes | J9: ='3'!L9 -> #VALUE! | K9: =F9+G9 -> #VALUE! | L9: =J9+K9 -> #VALUE! | M9: 28330 | N9: =L9-M9 -> #VALUE! | O9: 1500 | P9: =O9-N9 -> #VALUE! | S9: LAST SERVICE DONE @ 28330 HRS. DT- 2026-07-01
A10: 5 | B10: Air Compressor Electrical | C10: KIRLOSKAR | D10: PT 300 T | E10: Yes | J10: ='3'!L10 -> #VALUE! | K10: =F10+G10 -> #VALUE! | L10: =J10+K10 -> #VALUE! | M10: -200 | N10: =L10-M10 -> #VALUE! | O10: 500 | P10: =O10-N10 -> #VALUE! | S10: LAST SERVICE DONE @ -200 HRS. DT- 2026-07-01
A11: 6 | B11: Air Compressor Mechanical | C11: KIRLOSKAR | D11: 02.1281/2420149 | E11: Yes | J11: ='3'!L11 -> #VALUE! | K11: =F11+G11 -> #VALUE! | L11: =J11+K11 -> #VALUE! | M11: 907 | N11: =L11-M11 -> #VALUE! | O11: 500 | P11: =O11-N11 -> #VALUE! | S11: LAST SERVICE DONE @ 907 HRS. DT- 2026-07-01
A12: 7 | B12: Fire Pump | C12: KIRLOSKAR | D12: 4H.2709.20/1220003 | E12: Yes | J12: ='3'!L12 -> #VALUE! | K12: =F12+G12 -> #VALUE! | L12: =J12+K12 -> #VALUE! | M12: 1553 | N12: =L12-M12 -> #VALUE! | O12: 1500 | P12: =O12-N12 -> #VALUE! | S12: LAST SERVICE DONE @ 1553 HRS. DT- 2026-07-01
A25: Generator
A26: Sr No | B26: Equipment | C26: Make/Model | D26: M/C Serial No | E26: Is in Use | F26: Hours Run | H26: Lube Oil Pressure | I26: Lube Oil Added | J26: Opning Running HRS | K26: Total Run Hours | L26: Closing HRS | M26: Last Service Hours | N26: Running HRS after last service | O26: Define hours | P26: Hours Remaining For Next Service. | Q26: Preventive /Predictive Maintenance Details | R26: Remarks | S26: LAST SERVICE DONE
E27: Yes/No | F27: DAY | G27: NIGHT | H27: psi/bar | I27: Liters
A28: 1 | B28: Rig Site Generator Set 1, 125 KVA | C28: Cummins | D28: P84089603 | E28: Yes | J28: ='3'!L28 -> #VALUE! | K28: =F28+G28 -> #VALUE! | L28: =J28+K28 -> #VALUE! | M28: 25366 | N28: =L28-M28 -> #VALUE! | O28: 500 | P28: =O28-N28 -> #VALUE! | S28: LAST SERVICE DONE @ 25366 HRS. DT- 2026-07-01
A29: 2 | B29: Rig Site Generator Set 2, 125 KVA | C29: Cummins | D29: P84089932 | E29: Yes | J29: ='3'!L29 -> #VALUE! | K29: =F29+G29 -> #VALUE! | L29: =J29+K29 -> #VALUE! | M29: 27383 | N29: =L29-M29 -> #VALUE! | O29: 500 | P29: =O29-N29 -> #VALUE! | S29: LAST SERVICE DONE @ 27383 HRS. DT- 2026-07-01
A30: 3 | B30: Rig Site Generator Set 3, 15 KVA | C30: Cummins | D30: 31295 | E30: Yes | J30: ='3'!L30 -> #VALUE! | K30: =F30+G30 -> #VALUE! | L30: =J30+K30 -> #VALUE! | M30: 637 | N30: =L30-M30 -> #VALUE! | O30: 500 | P30: =O30-N30 -> #VALUE! | S30: LAST SERVICE DONE @ 637 HRS. DT- 2026-07-01
A31: 4 | B31: DG-125 KVA SUPERNOVA | C31: SUPERNOVS | D31: SN-6003 | E31: Yes | J31: ='3'!L31 -> #VALUE! | K31: =F31+G31 -> #VALUE! | L31: =J31+K31 -> #VALUE! | M31: 1049 | N31: =L31-M31 -> #VALUE! | O31: 500 | P31: =O31-N31 -> #VALUE! | S31: LAST SERVICE DONE @ 1049 HRS. DT- 2026-07-01

Sheet 5
A1: Rig No: | B1: Rig 50-02 | C1: Daily Mechanical Report | P1: Date: | Q1: 05-08-2026
A2: Well No: | B2: PLAN
A3: Diesel Engines
A4: Sr No | B4: Equipment | C4: Make/Model | D4: M/C Serial No | E4: Is in Use | F4: Hours Run | H4: Lube Oil Pressure | I4: Lube Oil Added | J4: Opning Running HRS | K4: Total Run Hours | L4: Closing HRS | M4: Last Service Hours | N4: Running HRS after last service | O4: Define hours | P4: Hours Remaining For Next Service. | Q4: Preventive /Predictive Maintenance Details | R4: Remarks | S4: LAST SERVICE DONE
E5: Yes/No | F5: DAY | G5: NIGHT | H5: psi/bar | I5: Liters
A6: 1 | B6: Rig Engine | C6: CAT 09 | D6: JSC08784 | E6: Yes | J6: ='4'!L6 -> #VALUE! | K6: =F6+G6 -> #VALUE! | L6: =J6+K6 -> #VALUE! | M6: 35028 | N6: =L6-M6 -> #VALUE! | O6: 500 | P6: =O6-N6 -> #VALUE! | S6: LAST SERVICE DONE @ 35028 HRS. DT- 2026-07-01
A7: 2 | B7: Rig Carrier Transmission | C7: CAT 09 | D7: 8620008307 | E7: Yes | J7: ='4'!L7 -> #VALUE! | K7: =F7+G7 -> #VALUE! | L7: =J7+K7 -> #VALUE! | M7: 35024 | N7: =L7-M7 -> #VALUE! | O7: 500 | P7: =O7-N7 -> #VALUE! | S7: LAST SERVICE DONE @ 35024 HRS. DT- 2026-07-01
A8: 3 | B8: Mud Pump Engine | C8: CAT 15 | D8: BEM00178 | E8: Yes | J8: ='4'!L8 -> #VALUE! | K8: =F8+G8 -> #VALUE! | L8: =J8+K8 -> #VALUE! | M8: 28330 | N8: =L8-M8 -> #VALUE! | O8: 1500 | P8: =O8-N8 -> #VALUE! | S8: LAST SERVICE DONE @ 28330 HRS. DT- 2026-07-01
A9: 4 | B9: Mud pump transmission | C9: CAT 15 | D9: 2901750 | E9: Yes | J9: ='4'!L9 -> #VALUE! | K9: =F9+G9 -> #VALUE! | L9: =J9+K9 -> #VALUE! | M9: 28330 | N9: =L9-M9 -> #VALUE! | O9: 1500 | P9: =O9-N9 -> #VALUE! | S9: LAST SERVICE DONE @ 28330 HRS. DT- 2026-07-01
A10: 5 | B10: Air Compressor Electrical | C10: KIRLOSKAR | D10: PT 300 T | E10: Yes | J10: ='4'!L10 -> #VALUE! | K10: =F10+G10 -> #VALUE! | L10: =J10+K10 -> #VALUE! | M10: -200 | N10: =L10-M10 -> #VALUE! | O10: 500 | P10: =O10-N10 -> #VALUE! | S10: LAST SERVICE DONE @ -200 HRS. DT- 2026-07-01
A11: 6 | B11: Air Compressor Mechanical | C11: KIRLOSKAR | D11: 02.1281/2420149 | E11: Yes | J11: ='4'!L11 -> #VALUE! | K11: =F11+G11 -> #VALUE! | L11: =J11+K11 -> #VALUE! | M11: 907 | N11: =L11-M11 -> #VALUE! | O11: 500 | P11: =O11-N11 -> #VALUE! | S11: LAST SERVICE DONE @ 907 HRS. DT- 2026-07-01
A12: 7 | B12: Fire Pump | C12: KIRLOSKAR | D12: 4H.2709.20/1220003 | E12: Yes | J12: ='4'!L12 -> #VALUE! | K12: =F12+G12 -> #VALUE! | L12: =J12+K12 -> #VALUE! | M12: 1553 | N12: =L12-M12 -> #VALUE! | O12: 1500 | P12: =O12-N12 -> #VALUE! | S12: LAST SERVICE DONE @ 1553 HRS. DT- 2026-07-01
A25: Generator
A26: Sr No | B26: Equipment | C26: Make/Model | D26: M/C Serial No | E26: Is in Use | F26: Hours Run | H26: Lube Oil Pressure | I26: Lube Oil Added | J26: Opning Running HRS | K26: Total Run Hours | L26: Closing HRS | M26: Last Service Hours | N26: Running HRS after last service | O26: Define hours | P26: Hours Remaining For Next Service. | Q26: Preventive /Predictive Maintenance Details | R26: Remarks | S26: LAST SERVICE DONE
E27: Yes/No | F27: DAY | G27: NIGHT | H27: psi/bar | I27: Liters
A28: 1 | B28: Rig Site Generator Set 1, 125 KVA | C28: Cummins | D28: P84089603 | E28: Yes | J28: ='4'!L28 -> #VALUE! | K28: =F28+G28 -> #VALUE! | L28: =J28+K28 -> #VALUE! | M28: 25366 | N28: =L28-M28 -> #VALUE! | O28: 500 | P28: =O28-N28 -> #VALUE! | S28: LAST SERVICE DONE @ 25366 HRS. DT- 2026-07-01
A29: 2 | B29: Rig Site Generator Set 2, 125 KVA | C29: Cummins | D29: P84089932 | E29: Yes | J29: ='4'!L29 -> #VALUE! | K29: =F29+G29 -> #VALUE! | L29: =J29+K29 -> #VALUE! | M29: 27383 | N29: =L29-M29 -> #VALUE! | O29: 500 | P29: =O29-N29 -> #VALUE! | S29: LAST SERVICE DONE @ 27383 HRS. DT- 2026-07-01
A30: 3 | B30: Rig Site Generator Set 3, 15 KVA | C30: Cummins | D30: 31295 | E30: Yes | J30: ='4'!L30 -> #VALUE! | K30: =F30+G30 -> #VALUE! | L30: =J30+K30 -> #VALUE! | M30: 637 | N30: =L30-M30 -> #VALUE! | O30: 500 | P30: =O30-N30 -> #VALUE! | S30: LAST SERVICE DONE @ 637 HRS. DT- 2026-07-01
A31: 4 | B31: DG-125 KVA SUPERNOVA | C31: SUPERNOVS | D31: SN-6003 | E31: Yes | J31: ='4'!L31 -> #VALUE! | K31: =F31+G31 -> #VALUE! | L31: =J31+K31 -> #VALUE! | M31: 1049 | N31: =L31-M31 -> #VALUE! | O31: 500 | P31: =O31-N31 -> #VALUE! | S31: LAST SERVICE DONE @ 1049 HRS. DT- 2026-07-01

Sheet 6
A1: Rig No: | B1: Rig 50-02 | C1: Daily Mechanical Report | P1: Date: | Q1: 06-08-2026
A2: Well No: | B2: PLAN
A3: Diesel Engines
A4: Sr No | B4: Equipment | C4: Make/Model | D4: M/C Serial No | E4: Is in Use | F4: Hours Run | H4: Lube Oil Pressure | I4: Lube Oil Added | J4: Opning Running HRS | K4: Total Run Hours | L4: Closing HRS | M4: Last Service Hours | N4: Running HRS after last service | O4: Define hours | P4: Hours Remaining For Next Service. | Q4: Preventive /Predictive Maintenance Details | R4: Remarks | S4: LAST SERVICE DONE
E5: Yes/No | F5: DAY | G5: NIGHT | H5: psi/bar | I5: Liters
A6: 1 | B6: Rig Engine | C6: CAT 09 | D6: JSC08784 | E6: Yes | J6: ='5'!L6 -> #VALUE! | K6: =F6+G6 -> #VALUE! | L6: =J6+K6 -> #VALUE! | M6: 35028 | N6: =L6-M6 -> #VALUE! | O6: 500 | P6: =O6-N6 -> #VALUE! | S6: LAST SERVICE DONE @ 35028 HRS. DT- 2026-07-01
A7: 2 | B7: Rig Carrier Transmission | C7: CAT 09 | D7: 8620008307 | E7: Yes | J7: ='5'!L7 -> #VALUE! | K7: =F7+G7 -> #VALUE! | L7: =J7+K7 -> #VALUE! | M7: 35024 | N7: =L7-M7 -> #VALUE! | O7: 500 | P7: =O7-N7 -> #VALUE! | S7: LAST SERVICE DONE @ 35024 HRS. DT- 2026-07-01
A8: 3 | B8: Mud Pump Engine | C8: CAT 15 | D8: BEM00178 | E8: Yes | J8: ='5'!L8 -> #VALUE! | K8: =F8+G8 -> #VALUE! | L8: =J8+K8 -> #VALUE! | M8: 28330 | N8: =L8-M8 -> #VALUE! | O8: 1500 | P8: =O8-N8 -> #VALUE! | S8: LAST SERVICE DONE @ 28330 HRS. DT- 2026-07-01
A9: 4 | B9: Mud pump transmission | C9: CAT 15 | D9: 2901750 | E9: Yes | J9: ='5'!L9 -> #VALUE! | K9: =F9+G9 -> #VALUE! | L9: =J9+K9 -> #VALUE! | M9: 28330 | N9: =L9-M9 -> #VALUE! | O9: 1500 | P9: =O9-N9 -> #VALUE! | S9: LAST SERVICE DONE @ 28330 HRS. DT- 2026-07-01
A10: 5 | B10: Air Compressor Electrical | C10: KIRLOSKAR | D10: PT 300 T | E10: Yes | J10: ='5'!L10 -> #VALUE! | K10: =F10+G10 -> #VALUE! | L10: =J10+K10 -> #VALUE! | M10: -200 | N10: =L10-M10 -> #VALUE! | O10: 500 | P10: =O10-N10 -> #VALUE! | S10: LAST SERVICE DONE @ -200 HRS. DT- 2026-07-01
A11: 6 | B11: Air Compressor Mechanical | C11: KIRLOSKAR | D11: 02.1281/2420149 | E11: Yes | J11: ='5'!L11 -> #VALUE! | K11: =F11+G11 -> #VALUE! | L11: =J11+K11 -> #VALUE! | M11: 907 | N11: =L11-M11 -> #VALUE! | O11: 500 | P11: =O11-N11 -> #VALUE! | S11: LAST SERVICE DONE @ 907 HRS. DT- 2026-07-01
A12: 7 | B12: Fire Pump | C12: KIRLOSKAR | D12: 4H.2709.20/1220003 | E12: Yes | J12: ='5'!L12 -> #VALUE! | K12: =F12+G12 -> #VALUE! | L12: =J12+K12 -> #VALUE! | M12: 1553 | N12: =L12-M12 -> #VALUE! | O12: 1500 | P12: =O12-N12 -> #VALUE! | S12: LAST SERVICE DONE @ 1553 HRS. DT- 2026-07-01
A25: Generator
A26: Sr No | B26: Equipment | C26: Make/Model | D26: M/C Serial No | E26: Is in Use | F26: Hours Run | H26: Lube Oil Pressure | I26: Lube Oil Added | J26: Opning Running HRS | K26: Total Run Hours | L26: Closing HRS | M26: Last Service Hours | N26: Running HRS after last service | O26: Define hours | P26: Hours Remaining For Next Service. | Q26: Preventive /Predictive Maintenance Details | R26: Remarks | S26: LAST SERVICE DONE
E27: Yes/No | F27: DAY | G27: NIGHT | H27: psi/bar | I27: Liters
A28: 1 | B28: Rig Site Generator Set 1, 125 KVA | C28: Cummins | D28: P84089603 | E28: Yes | J28: ='5'!L28 -> #VALUE! | K28: =F28+G28 -> #VALUE! | L28: =J28+K28 -> #VALUE! | M28: 25366 | N28: =L28-M28 -> #VALUE! | O28: 500 | P28: =O28-N28 -> #VALUE! | S28: LAST SERVICE DONE @ 25366 HRS. DT- 2026-07-01
A29: 2 | B29: Rig Site Generator Set 2, 125 KVA | C29: Cummins | D29: P84089932 | E29: Yes | J29: ='5'!L29 -> #VALUE! | K29: =F29+G29 -> #VALUE! | L29: =J29+K29 -> #VALUE! | M29: 27383 | N29: =L29-M29 -> #VALUE! | O29: 500 | P29: =O29-N29 -> #VALUE! | S29: LAST SERVICE DONE @ 27383 HRS. DT- 2026-07-01
A30: 3 | B30: Rig Site Generator Set 3, 15 KVA | C30: Cummins | D30: 31295 | E30: Yes | J30: ='5'!L30 -> #VALUE! | K30: =F30+G30 -> #VALUE! | L30: =J30+K30 -> #VALUE! | M30: 637 | N30: =L30-M30 -> #VALUE! | O30: 500 | P30: =O30-N30 -> #VALUE! | S30: LAST SERVICE DONE @ 637 HRS. DT- 2026-07-01
A31: 4 | B31: DG-125 KVA SUPERNOVA | C31: SUPERNOVS | D31: SN-6003 | E31: Yes | J31: ='5'!L31 -> #VALUE! | K31: =F31+G31 -> #VALUE! | L31: =J31+K31 -> #VALUE! | M31: 1049 | N31: =L31-M31 -> #VALUE! | O31: 500 | P31: =O31-N31 -> #VALUE! | S31: LAST SERVICE DONE @ 1049 HRS. DT- 2026-07-01

Sheet 7
A1: Rig No: | B1: Rig 50-02 | C1: Daily Mechanical Report | P1: Date: | Q1: 07-08-2026
A2: Well No: | B2: PLAN
A3: Diesel Engines
A4: Sr No | B4: Equipment | C4: Make/Model | D4: M/C Serial No | E4: Is in Use | F4: Hours Run | H4: Lube Oil Pressure | I4: Lube Oil Added | J4: Opning Running HRS | K4: Total Run Hours | L4: Closing HRS | M4: Last Service Hours | N4: Running HRS after last service | O4: Define hours | P4: Hours Remaining For Next Service. | Q4: Preventive /Predictive Maintenance Details | R4: Remarks | S4: LAST SERVICE DONE
E5: Yes/No | F5: DAY | G5: NIGHT | H5: psi/bar | I5: Liters
A6: 1 | B6: Rig Engine | C6: CAT 09 | D6: JSC08784 | E6: Yes | J6: ='6'!L6 -> #VALUE! | K6: =F6+G6 -> #VALUE! | L6: =J6+K6 -> #VALUE! | M6: 35028 | N6: =L6-M6 -> #VALUE! | O6: 500 | P6: =O6-N6 -> #VALUE! | S6: LAST SERVICE DONE @ 35028 HRS. DT- 2026-07-01
A7: 2 | B7: Rig Carrier Transmission | C7: CAT 09 | D7: 8620008307 | E7: Yes | J7: ='6'!L7 -> #VALUE! | K7: =F7+G7 -> #VALUE! | L7: =J7+K7 -> #VALUE! | M7: 35024 | N7: =L7-M7 -> #VALUE! | O7: 500 | P7: =O7-N7 -> #VALUE! | S7: LAST SERVICE DONE @ 35024 HRS. DT- 2026-07-01
A8: 3 | B8: Mud Pump Engine | C8: CAT 15 | D8: BEM00178 | E8: Yes | J8: ='6'!L8 -> #VALUE! | K8: =F8+G8 -> #VALUE! | L8: =J8+K8 -> #VALUE! | M8: 28330 | N8: =L8-M8 -> #VALUE! | O8: 1500 | P8: =O8-N8 -> #VALUE! | S8: LAST SERVICE DONE @ 28330 HRS. DT- 2026-07-01
A9: 4 | B9: Mud pump transmission | C9: CAT 15 | D9: 2901750 | E9: Yes | J9: ='6'!L9 -> #VALUE! | K9: =F9+G9 -> #VALUE! | L9: =J9+K9 -> #VALUE! | M9: 28330 | N9: =L9-M9 -> #VALUE! | O9: 1500 | P9: =O9-N9 -> #VALUE! | S9: LAST SERVICE DONE @ 28330 HRS. DT- 2026-07-01
A10: 5 | B10: Air Compressor Electrical | C10: KIRLOSKAR | D10: PT 300 T | E10: Yes | J10: ='6'!L10 -> #VALUE! | K10: =F10+G10 -> #VALUE! | L10: =J10+K10 -> #VALUE! | M10: -200 | N10: =L10-M10 -> #VALUE! | O10: 500 | P10: =O10-N10 -> #VALUE! | S10: LAST SERVICE DONE @ -200 HRS. DT- 2026-07-01
A11: 6 | B11: Air Compressor Mechanical | C11: KIRLOSKAR | D11: 02.1281/2420149 | E11: Yes | J11: ='6'!L11 -> #VALUE! | K11: =F11+G11 -> #VALUE! | L11: =J11+K11 -> #VALUE! | M11: 907 | N11: =L11-M11 -> #VALUE! | O11: 500 | P11: =O11-N11 -> #VALUE! | S11: LAST SERVICE DONE @ 907 HRS. DT- 2026-07-01
A12: 7 | B12: Fire Pump | C12: KIRLOSKAR | D12: 4H.2709.20/1220003 | E12: Yes | J12: ='6'!L12 -> #VALUE! | K12: =F12+G12 -> #VALUE! | L12: =J12+K12 -> #VALUE! | M12: 1553 | N12: =L12-M12 -> #VALUE! | O12: 1500 | P12: =O12-N12 -> #VALUE! | S12: LAST SERVICE DONE @ 1553 HRS. DT- 2026-07-01
A25: Generator
A26: Sr No | B26: Equipment | C26: Make/Model | D26: M/C Serial No | E26: Is in Use | F26: Hours Run | H26: Lube Oil Pressure | I26: Lube Oil Added | J26: Opning Running HRS | K26: Total Run Hours | L26: Closing HRS | M26: Last Service Hours | N26: Running HRS after last service | O26: Define hours | P26: Hours Remaining For Next Service. | Q26: Preventive /Predictive Maintenance Details | R26: Remarks | S26: LAST SERVICE DONE
E27: Yes/No | F27: DAY | G27: NIGHT | H27: psi/bar | I27: Liters
A28: 1 | B28: Rig Site Generator Set 1, 125 KVA | C28: Cummins | D28: P84089603 | E28: Yes | J28: ='6'!L28 -> #VALUE! | K28: =F28+G28 -> #VALUE! | L28: =J28+K28 -> #VALUE! | M28: 25366 | N28: =L28-M28 -> #VALUE! | O28: 500 | P28: =O28-N28 -> #VALUE! | S28: LAST SERVICE DONE @ 25366 HRS. DT- 2026-07-01
A29: 2 | B29: Rig Site Generator Set 2, 125 KVA | C29: Cummins | D29: P84089932 | E29: Yes | J29: ='6'!L29 -> #VALUE! | K29: =F29+G29 -> #VALUE! | L29: =J29+K29 -> #VALUE! | M29: 27383 | N29: =L29-M29 -> #VALUE! | O29: 500 | P29: =O29-N29 -> #VALUE! | S29: LAST SERVICE DONE @ 27383 HRS. DT- 2026-07-01
A30: 3 | B30: Rig Site Generator Set 3, 15 KVA | C30: Cummins | D30: 31295 | E30: Yes | J30: ='6'!L30 -> #VALUE! | K30: =F30+G30 -> #VALUE! | L30: =J30+K30 -> #VALUE! | M30: 637 | N30: =L30-M30 -> #VALUE! | O30: 500 | P30: =O30-N30 -> #VALUE! | S30: LAST SERVICE DONE @ 637 HRS. DT- 2026-07-01
A31: 4 | B31: DG-125 KVA SUPERNOVA | C31: SUPERNOVS | D31: SN-6003 | E31: Yes | J31: ='6'!L31 -> #VALUE! | K31: =F31+G31 -> #VALUE! | L31: =J31+K31 -> #VALUE! | M31: 1049 | N31: =L31-M31 -> #VALUE! | O31: 500 | P31: =O31-N31 -> #VALUE! | S31: LAST SERVICE DONE @ 1049 HRS. DT- 2026-07-01

Sheet 8
A1: Rig No: | B1: Rig 50-02 | C1: Daily Mechanical Report | P1: Date: | Q1: 08-08-2026
A2: Well No: | B2: PLAN
A3: Diesel Engines
A4: Sr No | B4: Equipment | C4: Make/Model | D4: M/C Serial No | E4: Is in Use | F4: Hours Run | H4: Lube Oil Pressure | I4: Lube Oil Added | J4: Opning Running HRS | K4: Total Run Hours | L4: Closing HRS | M4: Last Service Hours | N4: Running HRS after last service | O4: Define hours | P4: Hours Remaining For Next Service. | Q4: Preventive /Predictive Maintenance Details | R4: Remarks | S4: LAST SERVICE DONE
E5: Yes/No | F5: DAY | G5: NIGHT | H5: psi/bar | I5: Liters
A6: 1 | B6: Rig Engine | C6: CAT 09 | D6: JSC08784 | E6: Yes | J6: ='7'!L6 -> #VALUE! | K6: =F6+G6 -> #VALUE! | L6: =J6+K6 -> #VALUE! | M6: 35028 | N6: =L6-M6 -> #VALUE! | O6: 500 | P6: =O6-N6 -> #VALUE! | S6: LAST SERVICE DONE @ 35028 HRS. DT- 2026-07-01
A7: 2 | B7: Rig Carrier Transmission | C7: CAT 09 | D7: 8620008307 | E7: Yes | J7: ='7'!L7 -> #VALUE! | K7: =F7+G7 -> #VALUE! | L7: =J7+K7 -> #VALUE! | M7: 35024 | N7: =L7-M7 -> #VALUE! | O7: 500 | P7: =O7-N7 -> #VALUE! | S7: LAST SERVICE DONE @ 35024 HRS. DT- 2026-07-01
A8: 3 | B8: Mud Pump Engine | C8: CAT 15 | D8: BEM00178 | E8: Yes | J8: ='7'!L8 -> #VALUE! | K8: =F8+G8 -> #VALUE! | L8: =J8+K8 -> #VALUE! | M8: 28330 | N8: =L8-M8 -> #VALUE! | O8: 1500 | P8: =O8-N8 -> #VALUE! | S8: LAST SERVICE DONE @ 28330 HRS. DT- 2026-07-01
A9: 4 | B9: Mud pump transmission | C9: CAT 15 | D9: 2901750 | E9: Yes | J9: ='7'!L9 -> #VALUE! | K9: =F9+G9 -> #VALUE! | L9: =J9+K9 -> #VALUE! | M9: 28330 | N9: =L9-M9 -> #VALUE! | O9: 1500 | P9: =O9-N9 -> #VALUE! | S9: LAST SERVICE DONE @ 28330 HRS. DT- 2026-07-01
A10: 5 | B10: Air Compressor Electrical | C10: KIRLOSKAR | D10: PT 300 T | E10: Yes | J10: ='7'!L10 -> #VALUE! | K10: =F10+G10 -> #VALUE! | L10: =J10+K10 -> #VALUE! | M10: -200 | N10: =L10-M10 -> #VALUE! | O10: 500 | P10: =O10-N10 -> #VALUE! | S10: LAST SERVICE DONE @ -200 HRS. DT- 2026-07-01
A11: 6 | B11: Air Compressor Mechanical | C11: KIRLOSKAR | D11: 02.1281/2420149 | E11: Yes | J11: ='7'!L11 -> #VALUE! | K11: =F11+G11 -> #VALUE! | L11: =J11+K11 -> #VALUE! | M11: 907 | N11: =L11-M11 -> #VALUE! | O11: 500 | P11: =O11-N11 -> #VALUE! | S11: LAST SERVICE DONE @ 907 HRS. DT- 2026-07-01
A12: 7 | B12: Fire Pump | C12: KIRLOSKAR | D12: 4H.2709.20/1220003 | E12: Yes | J12: ='7'!L12 -> #VALUE! | K12: =F12+G12 -> #VALUE! | L12: =J12+K12 -> #VALUE! | M12: 1553 | N12: =L12-M12 -> #VALUE! | O12: 1500 | P12: =O12-N12 -> #VALUE! | S12: LAST SERVICE DONE @ 1553 HRS. DT- 2026-07-01
A25: Generator
A26: Sr No | B26: Equipment | C26: Make/Model | D26: M/C Serial No | E26: Is in Use | F26: Hours Run | H26: Lube Oil Pressure | I26: Lube Oil Added | J26: Opning Running HRS | K26: Total Run Hours | L26: Closing HRS | M26: Last Service Hours | N26: Running HRS after last service | O26: Define hours | P26: Hours Remaining For Next Service. | Q26: Preventive /Predictive Maintenance Details | R26: Remarks | S26: LAST SERVICE DONE
E27: Yes/No | F27: DAY | G27: NIGHT | H27: psi/bar | I27: Liters
A28: 1 | B28: Rig Site Generator Set 1, 125 KVA | C28: Cummins | D28: P84089603 | E28: Yes | J28: ='7'!L28 -> #VALUE! | K28: =F28+G28 -> #VALUE! | L28: =J28+K28 -> #VALUE! | M28: 25366 | N28: =L28-M28 -> #VALUE! | O28: 500 | P28: =O28-N28 -> #VALUE! | S28: LAST SERVICE DONE @ 25366 HRS. DT- 2026-07-01
A29: 2 | B29: Rig Site Generator Set 2, 125 KVA | C29: Cummins | D29: P84089932 | E29: Yes | J29: ='7'!L29 -> #VALUE! | K29: =F29+G29 -> #VALUE! | L29: =J29+K29 -> #VALUE! | M29: 27383 | N29: =L29-M29 -> #VALUE! | O29: 500 | P29: =O29-N29 -> #VALUE! | S29: LAST SERVICE DONE @ 27383 HRS. DT- 2026-07-01
A30: 3 | B30: Rig Site Generator Set 3, 15 KVA | C30: Cummins | D30: 31295 | E30: Yes | J30: ='7'!L30 -> #VALUE! | K30: =F30+G30 -> #VALUE! | L30: =J30+K30 -> #VALUE! | M30: 637 | N30: =L30-M30 -> #VALUE! | O30: 500 | P30: =O30-N30 -> #VALUE! | S30: LAST SERVICE DONE @ 637 HRS. DT- 2026-07-01
A31: 4 | B31: DG-125 KVA SUPERNOVA | C31: SUPERNOVS | D31: SN-6003 | E31: Yes | J31: ='7'!L31 -> #VALUE! | K31: =F31+G31 -> #VALUE! | L31: =J31+K31 -> #VALUE! | M31: 1049 | N31: =L31-M31 -> #VALUE! | O31: 500 | P31: =O31-N31 -> #VALUE! | S31: LAST SERVICE DONE @ 1049 HRS. DT- 2026-07-01

Sheet 9
A1: Rig No: | B1: Rig 50-02 | C1: Daily Mechanical Report | P1: Date: | Q1: 09-08-2026
A2: Well No: | B2: PLAN
A3: Diesel Engines
A4: Sr No | B4: Equipment | C4: Make/Model | D4: M/C Serial No | E4: Is in Use | F4: Hours Run | H4: Lube Oil Pressure | I4: Lube Oil Added | J4: Opning Running HRS | K4: Total Run Hours | L4: Closing HRS | M4: Last Service Hours | N4: Running HRS after last service | O4: Define hours | P4: Hours Remaining For Next Service. | Q4: Preventive /Predictive Maintenance Details | R4: Remarks | S4: LAST SERVICE DONE
E5: Yes/No | F5: DAY | G5: NIGHT | H5: psi/bar | I5: Liters
A6: 1 | B6: Rig Engine | C6: CAT 09 | D6: JSC08784 | E6: Yes | J6: ='8'!L6 -> #VALUE! | K6: =F6+G6 -> #VALUE! | L6: =J6+K6 -> #VALUE! | M6: 35028 | N6: =L6-M6 -> #VALUE! | O6: 500 | P6: =O6-N6 -> #VALUE! | S6: LAST SERVICE DONE @ 35028 HRS. DT- 2026-07-01
A7: 2 | B7: Rig Carrier Transmission | C7: CAT 09 | D7: 8620008307 | E7: Yes | J7: ='8'!L7 -> #VALUE! | K7: =F7+G7 -> #VALUE! | L7: =J7+K7 -> #VALUE! | M7: 35024 | N7: =L7-M7 -> #VALUE! | O7: 500 | P7: =O7-N7 -> #VALUE! | S7: LAST SERVICE DONE @ 35024 HRS. DT- 2026-07-01
A8: 3 | B8: Mud Pump Engine | C8: CAT 15 | D8: BEM00178 | E8: Yes | J8: ='8'!L8 -> #VALUE! | K8: =F8+G8 -> #VALUE! | L8: =J8+K8 -> #VALUE! | M8: 28330 | N8: =L8-M8 -> #VALUE! | O8: 1500 | P8: =O8-N8 -> #VALUE! | S8: LAST SERVICE DONE @ 28330 HRS. DT- 2026-07-01
A9: 4 | B9: Mud pump transmission | C9: CAT 15 | D9: 2901750 | E9: Yes | J9: ='8'!L9 -> #VALUE! | K9: =F9+G9 -> #VALUE! | L9: =J9+K9 -> #VALUE! | M9: 28330 | N9: =L9-M9 -> #VALUE! | O9: 1500 | P9: =O9-N9 -> #VALUE! | S9: LAST SERVICE DONE @ 28330 HRS. DT- 2026-07-01
A10: 5 | B10: Air Compressor Electrical | C10: KIRLOSKAR | D10: PT 300 T | E10: Yes | J10: ='8'!L10 -> #VALUE! | K10: =F10+G10 -> #VALUE! | L10: =J10+K10 -> #VALUE! | M10: -200 | N10: =L10-M10 -> #VALUE! | O10: 500 | P10: =O10-N10 -> #VALUE! | S10: LAST SERVICE DONE @ -200 HRS. DT- 2026-07-01
A11: 6 | B11: Air Compressor Mechanical | C11: KIRLOSKAR | D11: 02.1281/2420149 | E11: Yes | J11: ='8'!L11 -> #VALUE! | K11: =F11+G11 -> #VALUE! | L11: =J11+K11 -> #VALUE! | M11: 907 | N11: =L11-M11 -> #VALUE! | O11: 500 | P11: =O11-N11 -> #VALUE! | S11: LAST SERVICE DONE @ 907 HRS. DT- 2026-07-01
A12: 7 | B12: Fire Pump | C12: KIRLOSKAR | D12: 4H.2709.20/1220003 | E12: Yes | J12: ='8'!L12 -> #VALUE! | K12: =F12+G12 -> #VALUE! | L12: =J12+K12 -> #VALUE! | M12: 1553 | N12: =L12-M12 -> #VALUE! | O12: 1500 | P12: =O12-N12 -> #VALUE! | S12: LAST SERVICE DONE @ 1553 HRS. DT- 2026-07-01
A25: Generator
A26: Sr No | B26: Equipment | C26: Make/Model | D26: M/C Serial No | E26: Is in Use | F26: Hours Run | H26: Lube Oil Pressure | I26: Lube Oil Added | J26: Opning Running HRS | K26: Total Run Hours | L26: Closing HRS | M26: Last Service Hours | N26: Running HRS after last service | O26: Define hours | P26: Hours Remaining For Next Service. | Q26: Preventive /Predictive Maintenance Details | R26: Remarks | S26: LAST SERVICE DONE
E27: Yes/No | F27: DAY | G27: NIGHT | H27: psi/bar | I27: Liters
A28: 1 | B28: Rig Site Generator Set 1, 125 KVA | C28: Cummins | D28: P84089603 | E28: Yes | J28: ='8'!L28 -> #VALUE! | K28: =F28+G28 -> #VALUE! | L28: =J28+K28 -> #VALUE! | M28: 25366 | N28: =L28-M28 -> #VALUE! | O28: 500 | P28: =O28-N28 -> #VALUE! | S28: LAST SERVICE DONE @ 25366 HRS. DT- 2026-07-01
A29: 2 | B29: Rig Site Generator Set 2, 125 KVA | C29: Cummins | D29: P84089932 | E29: Yes | J29: ='8'!L29 -> #VALUE! | K29: =F29+G29 -> #VALUE! | L29: =J29+K29 -> #VALUE! | M29: 27383 | N29: =L29-M29 -> #VALUE! | O29: 500 | P29: =O29-N29 -> #VALUE! | S29: LAST SERVICE DONE @ 27383 HRS. DT- 2026-07-01
A30: 3 | B30: Rig Site Generator Set 3, 15 KVA | C30: Cummins | D30: 31295 | E30: Yes | J30: ='8'!L30 -> #VALUE! | K30: =F30+G30 -> #VALUE! | L30: =J30+K30 -> #VALUE! | M30: 637 | N30: =L30-M30 -> #VALUE! | O30: 500 | P30: =O30-N30 -> #VALUE! | S30: LAST SERVICE DONE @ 637 HRS. DT- 2026-07-01
A31: 4 | B31: DG-125 KVA SUPERNOVA | C31: SUPERNOVS | D31: SN-6003 | E31: Yes | J31: ='8'!L31 -> #VALUE! | K31: =F31+G31 -> #VALUE! | L31: =J31+K31 -> #VALUE! | M31: 1049 | N31: =L31-M31 -> #VALUE! | O31: 500 | P31: =O31-N31 -> #VALUE! | S31: LAST SERVICE DONE @ 1049 HRS. DT- 2026-07-01

Sheet 10
A1: Rig No: | B1: Rig 50-02 | C1: Daily Mechanical Report | P1: Date: | Q1: 10-08-2026
A2: Well No: | B2: PLAN
A3: Diesel Engines
A4: Sr No | B4: Equipment | C4: Make/Model | D4: M/C Serial No | E4: Is in Use | F4: Hours Run | H4: Lube Oil Pressure | I4: Lube Oil Added | J4: Opning Running HRS | K4: Total Run Hours | L4: Closing HRS | M4: Last Service Hours | N4: Running HRS after last service | O4: Define hours | P4: Hours Remaining For Next Service. | Q4: Preventive /Predictive Maintenance Details | R4: Remarks | S4: LAST SERVICE DONE
E5: Yes/No | F5: DAY | G5: NIGHT | H5: psi/bar | I5: Liters
A6: 1 | B6: Rig Engine | C6: CAT 09 | D6: JSC08784 | E6: Yes | J6: ='9'!L6 -> #VALUE! | K6: =F6+G6 -> #VALUE! | L6: =J6+K6 -> #VALUE! | M6: 35028 | N6: =L6-M6 -> #VALUE! | O6: 500 | P6: =O6-N6 -> #VALUE! | S6: LAST SERVICE DONE @ 35028 HRS. DT- 2026-07-01
A7: 2 | B7: Rig Carrier Transmission | C7: CAT 09 | D7: 8620008307 | E7: Yes | J7: ='9'!L7 -> #VALUE! | K7: =F7+G7 -> #VALUE! | L7: =J7+K7 -> #VALUE! | M7: 35024 | N7: =L7-M7 -> #VALUE! | O7: 500 | P7: =O7-N7 -> #VALUE! | S7: LAST SERVICE DONE @ 35024 HRS. DT- 2026-07-01
A8: 3 | B8: Mud Pump Engine | C8: CAT 15 | D8: BEM00178 | E8: Yes | J8: ='9'!L8 -> #VALUE! | K8: =F8+G8 -> #VALUE! | L8: =J8+K8 -> #VALUE! | M8: 28330 | N8: =L8-M8 -> #VALUE! | O8: 1500 | P8: =O8-N8 -> #VALUE! | S8: LAST SERVICE DONE @ 28330 HRS. DT- 2026-07-01
A9: 4 | B9: Mud pump transmission | C9: CAT 15 | D9: 2901750 | E9: Yes | J9: ='9'!L9 -> #VALUE! | K9: =F9+G9 -> #VALUE! | L9: =J9+K9 -> #VALUE! | M9: 28330 | N9: =L9-M9 -> #VALUE! | O9: 1500 | P9: =O9-N9 -> #VALUE! | S9: LAST SERVICE DONE @ 28330 HRS. DT- 2026-07-01
A10: 5 | B10: Air Compressor Electrical | C10: KIRLOSKAR | D10: PT 300 T | E10: Yes | J10: ='9'!L10 -> #VALUE! | K10: =F10+G10 -> #VALUE! | L10: =J10+K10 -> #VALUE! | M10: -200 | N10: =L10-M10 -> #VALUE! | O10: 500 | P10: =O10-N10 -> #VALUE! | S10: LAST SERVICE DONE @ -200 HRS. DT- 2026-07-01
A11: 6 | B11: Air Compressor Mechanical | C11: KIRLOSKAR | D11: 02.1281/2420149 | E11: Yes | J11: ='9'!L11 -> #VALUE! | K11: =F11+G11 -> #VALUE! | L11: =J11+K11 -> #VALUE! | M11: 907 | N11: =L11-M11 -> #VALUE! | O11: 500 | P11: =O11-N11 -> #VALUE! | S11: LAST SERVICE DONE @ 907 HRS. DT- 2026-07-01
A12: 7 | B12: Fire Pump | C12: KIRLOSKAR | D12: 4H.2709.20/1220003 | E12: Yes | J12: ='9'!L12 -> #VALUE! | K12: =F12+G12 -> #VALUE! | L12: =J12+K12 -> #VALUE! | M12: 1553 | N12: =L12-M12 -> #VALUE! | O12: 1500 | P12: =O12-N12 -> #VALUE! | S12: LAST SERVICE DONE @ 1553 HRS. DT- 2026-07-01
A25: Generator
A26: Sr No | B26: Equipment | C26: Make/Model | D26: M/C Serial No | E26: Is in Use | F26: Hours Run | H26: Lube Oil Pressure | I26: Lube Oil Added | J26: Opning Running HRS | K26: Total Run Hours | L26: Closing HRS | M26: Last Service Hours | N26: Running HRS after last service | O26: Define hours | P26: Hours Remaining For Next Service. | Q26: Preventive /Predictive Maintenance Details | R26: Remarks | S26: LAST SERVICE DONE
E27: Yes/No | F27: DAY | G27: NIGHT | H27: psi/bar | I27: Liters
A28: 1 | B28: Rig Site Generator Set 1, 125 KVA | C28: Cummins | D28: P84089603 | E28: Yes | J28: ='9'!L28 -> #VALUE! | K28: =F28+G28 -> #VALUE! | L28: =J28+K28 -> #VALUE! | M28: 25366 | N28: =L28-M28 -> #VALUE! | O28: 500 | P28: =O28-N28 -> #VALUE! | S28: LAST SERVICE DONE @ 25366 HRS. DT- 2026-07-01
A29: 2 | B29: Rig Site Generator Set 2, 125 KVA | C29: Cummins | D29: P84089932 | E29: Yes | J29: ='9'!L29 -> #VALUE! | K29: =F29+G29 -> #VALUE! | L29: =J29+K29 -> #VALUE! | M29: 27383 | N29: =L29-M29 -> #VALUE! | O29: 500 | P29: =O29-N29 -> #VALUE! | S29: LAST SERVICE DONE @ 27383 HRS. DT- 2026-07-01
A30: 3 | B30: Rig Site Generator Set 3, 15 KVA | C30: Cummins | D30: 31295 | E30: Yes | J30: ='9'!L30 -> #VALUE! | K30: =F30+G30 -> #VALUE! | L30: =J30+K30 -> #VALUE! | M30: 637 | N30: =L30-M30 -> #VALUE! | O30: 500 | P30: =O30-N30 -> #VALUE! | S30: LAST SERVICE DONE @ 637 HRS. DT- 2026-07-01
A31: 4 | B31: DG-125 KVA SUPERNOVA | C31: SUPERNOVS | D31: SN-6003 | E31: Yes | J31: ='9'!L31 -> #VALUE! | K31: =F31+G31 -> #VALUE! | L31: =J31+K31 -> #VALUE! | M31: 1049 | N31: =L31-M31 -> #VALUE! | O31: 500 | P31: =O31-N31 -> #VALUE! | S31: LAST SERVICE DONE @ 1049 HRS. DT- 2026-07-01

Sheet 11
A1: Rig No: | B1: Rig 50-02 | C1: Daily Mechanical Report | P1: Date: | Q1: 11-08-2026
A2: Well No: | B2: PLAN
A3: Diesel Engines
A4: Sr No | B4: Equipment | C4: Make/Model | D4: M/C Serial No | E4: Is in Use | F4: Hours Run | H4: Lube Oil Pressure | I4: Lube Oil Added | J4: Opning Running HRS | K4: Total Run Hours | L4: Closing HRS | M4: Last Service Hours | N4: Running HRS after last service | O4: Define hours | P4: Hours Remaining For Next Service. | Q4: Preventive /Predictive Maintenance Details | R4: Remarks | S4: LAST SERVICE DONE
E5: Yes/No | F5: DAY | G5: NIGHT | H5: psi/bar | I5: Liters
A6: 1 | B6: Rig Engine | C6: CAT 09 | D6: JSC08784 | E6: Yes | J6: ='10'!L6 -> #VALUE! | K6: =F6+G6 -> #VALUE! | L6: =J6+K6 -> #VALUE! | M6: 35028 | N6: =L6-M6 -> #VALUE! | O6: 500 | P6: =O6-N6 -> #VALUE! | S6: LAST SERVICE DONE @ 35028 HRS. DT- 2026-07-01
A7: 2 | B7: Rig Carrier Transmission | C7: CAT 09 | D7: 8620008307 | E7: Yes | J7: ='10'!L7 -> #VALUE! | K7: =F7+G7 -> #VALUE! | L7: =J7+K7 -> #VALUE! | M7: 35024 | N7: =L7-M7 -> #VALUE! | O7: 500 | P7: =O7-N7 -> #VALUE! | S7: LAST SERVICE DONE @ 35024 HRS. DT- 2026-07-01
A8: 3 | B8: Mud Pump Engine | C8: CAT 15 | D8: BEM00178 | E8: Yes | J8: ='10'!L8 -> #VALUE! | K8: =F8+G8 -> #VALUE! | L8: =J8+K8 -> #VALUE! | M8: 28330 | N8: =L8-M8 -> #VALUE! | O8: 1500 | P8: =O8-N8 -> #VALUE! | S8: LAST SERVICE DONE @ 28330 HRS. DT- 2026-07-01
A9: 4 | B9: Mud pump transmission | C9: CAT 15 | D9: 2901750 | E9: Yes | J9: ='10'!L9 -> #VALUE! | K9: =F9+G9 -> #VALUE! | L9: =J9+K9 -> #VALUE! | M9: 28330 | N9: =L9-M9 -> #VALUE! | O9: 1500 | P9: =O9-N9 -> #VALUE! | S9: LAST SERVICE DONE @ 28330 HRS. DT- 2026-07-01
A10: 5 | B10: Air Compressor Electrical | C10: KIRLOSKAR | D10: PT 300 T | E10: Yes | J10: ='10'!L10 -> #VALUE! | K10: =F10+G10 -> #VALUE! | L10: =J10+K10 -> #VALUE! | M10: -200 | N10: =L10-M10 -> #VALUE! | O10: 500 | P10: =O10-N10 -> #VALUE! | S10: LAST SERVICE DONE @ -200 HRS. DT- 2026-07-01
A11: 6 | B11: Air Compressor Mechanical | C11: KIRLOSKAR | D11: 02.1281/2420149 | E11: Yes | J11: ='10'!L11 -> #VALUE! | K11: =F11+G11 -> #VALUE! | L11: =J11+K11 -> #VALUE! | M11: 907 | N11: =L11-M11 -> #VALUE! | O11: 500 | P11: =O11-N11 -> #VALUE! | S11: LAST SERVICE DONE @ 907 HRS. DT- 2026-07-01
A12: 7 | B12: Fire Pump | C12: KIRLOSKAR | D12: 4H.2709.20/1220003 | E12: Yes | J12: ='10'!L12 -> #VALUE! | K12: =F12+G12 -> #VALUE! | L12: =J12+K12 -> #VALUE! | M12: 1553 | N12: =L12-M12 -> #VALUE! | O12: 1500 | P12: =O12-N12 -> #VALUE! | S12: LAST SERVICE DONE @ 1553 HRS. DT- 2026-07-01
A25: Generator
A26: Sr No | B26: Equipment | C26: Make/Model | D26: M/C Serial No | E26: Is in Use | F26: Hours Run | H26: Lube Oil Pressure | I26: Lube Oil Added | J26: Opning Running HRS | K26: Total Run Hours | L26: Closing HRS | M26: Last Service Hours | N26: Running HRS after last service | O26: Define hours | P26: Hours Remaining For Next Service. | Q26: Preventive /Predictive Maintenance Details | R26: Remarks | S26: LAST SERVICE DONE
E27: Yes/No | F27: DAY | G27: NIGHT | H27: psi/bar | I27: Liters
A28: 1 | B28: Rig Site Generator Set 1, 125 KVA | C28: Cummins | D28: P84089603 | E28: Yes | J28: ='10'!L28 -> #VALUE! | K28: =F28+G28 -> #VALUE! | L28: =J28+K28 -> #VALUE! | M28: 25366 | N28: =L28-M28 -> #VALUE! | O28: 500 | P28: =O28-N28 -> #VALUE! | S28: LAST SERVICE DONE @ 25366 HRS. DT- 2026-07-01
A29: 2 | B29: Rig Site Generator Set 2, 125 KVA | C29: Cummins | D29: P84089932 | E29: Yes | J29: ='10'!L29 -> #VALUE! | K29: =F29+G29 -> #VALUE! | L29: =J29+K29 -> #VALUE! | M29: 27383 | N29: =L29-M29 -> #VALUE! | O29: 500 | P29: =O29-N29 -> #VALUE! | S29: LAST SERVICE DONE @ 27383 HRS. DT- 2026-07-01
A30: 3 | B30: Rig Site Generator Set 3, 15 KVA | C30: Cummins | D30: 31295 | E30: Yes | J30: ='10'!L30 -> #VALUE! | K30: =F30+G30 -> #VALUE! | L30: =J30+K30 -> #VALUE! | M30: 637 | N30: =L30-M30 -> #VALUE! | O30: 500 | P30: =O30-N30 -> #VALUE! | S30: LAST SERVICE DONE @ 637 HRS. DT- 2026-07-01
A31: 4 | B31: DG-125 KVA SUPERNOVA | C31: SUPERNOVS | D31: SN-6003 | E31: Yes | J31: ='10'!L31 -> #VALUE! | K31: =F31+G31 -> #VALUE! | L31: =J31+K31 -> #VALUE! | M31: 1049 | N31: =L31-M31 -> #VALUE! | O31: 500 | P31: =O31-N31 -> #VALUE! | S31: LAST SERVICE DONE @ 1049 HRS. DT- 2026-07-01

Sheet 12
A1: Rig No: | B1: Rig 50-02 | C1: Daily Mechanical Report | P1: Date: | Q1: 12-08-2026
A2: Well No: | B2: PLAN
A3: Diesel Engines
A4: Sr No | B4: Equipment | C4: Make/Model | D4: M/C Serial No | E4: Is in Use | F4: Hours Run | H4: Lube Oil Pressure | I4: Lube Oil Added | J4: Opning Running HRS | K4: Total Run Hours | L4: Closing HRS | M4: Last Service Hours | N4: Running HRS after last service | O4: Define hours | P4: Hours Remaining For Next Service. | Q4: Preventive /Predictive Maintenance Details | R4: Remarks | S4: LAST SERVICE DONE
E5: Yes/No | F5: DAY | G5: NIGHT | H5: psi/bar | I5: Liters
A6: 1 | B6: Rig Engine | C6: CAT 09 | D6: JSC08784 | E6: Yes | J6: ='11'!L6 -> #VALUE! | K6: =F6+G6 -> #VALUE! | L6: =J6+K6 -> #VALUE! | M6: 35028 | N6: =L6-M6 -> #VALUE! | O6: 500 | P6: =O6-N6 -> #VALUE! | S6: LAST SERVICE DONE @ 35028 HRS. DT- 2026-07-01
A7: 2 | B7: Rig Carrier Transmission | C7: CAT 09 | D7: 8620008307 | E7: Yes | J7: ='11'!L7 -> #VALUE! | K7: =F7+G7 -> #VALUE! | L7: =J7+K7 -> #VALUE! | M7: 35024 | N7: =L7-M7 -> #VALUE! | O7: 500 | P7: =O7-N7 -> #VALUE! | S7: LAST SERVICE DONE @ 35024 HRS. DT- 2026-07-01
A8: 3 | B8: Mud Pump Engine | C8: CAT 15 | D8: BEM00178 | E8: Yes | J8: ='11'!L8 -> #VALUE! | K8: =F8+G8 -> #VALUE! | L8: =J8+K8 -> #VALUE! | M8: 28330 | N8: =L8-M8 -> #VALUE! | O8: 1500 | P8: =O8-N8 -> #VALUE! | S8: LAST SERVICE DONE @ 28330 HRS. DT- 2026-07-01
A9: 4 | B9: Mud pump transmission | C9: CAT 15 | D9: 2901750 | E9: Yes | J9: ='11'!L9 -> #VALUE! | K9: =F9+G9 -> #VALUE! | L9: =J9+K9 -> #VALUE! | M9: 28330 | N9: =L9-M9 -> #VALUE! | O9: 1500 | P9: =O9-N9 -> #VALUE! | S9: LAST SERVICE DONE @ 28330 HRS. DT- 2026-07-01
A10: 5 | B10: Air Compressor Electrical | C10: KIRLOSKAR | D10: PT 300 T | E10: Yes | J10: ='11'!L10 -> #VALUE! | K10: =F10+G10 -> #VALUE! | L10: =J10+K10 -> #VALUE! | M10: -200 | N10: =L10-M10 -> #VALUE! | O10: 500 | P10: =O10-N10 -> #VALUE! | S10: LAST SERVICE DONE @ -200 HRS. DT- 2026-07-01
A11: 6 | B11: Air Compressor Mechanical | C11: KIRLOSKAR | D11: 02.1281/2420149 | E11: Yes | J11: ='11'!L11 -> #VALUE! | K11: =F11+G11 -> #VALUE! | L11: =J11+K11 -> #VALUE! | M11: 907 | N11: =L11-M11 -> #VALUE! | O11: 500 | P11: =O11-N11 -> #VALUE! | S11: LAST SERVICE DONE @ 907 HRS. DT- 2026-07-01
A12: 7 | B12: Fire Pump | C12: KIRLOSKAR | D12: 4H.2709.20/1220003 | E12: Yes | J12: ='11'!L12 -> #VALUE! | K12: =F12+G12 -> #VALUE! | L12: =J12+K12 -> #VALUE! | M12: 1553 | N12: =L12-M12 -> #VALUE! | O12: 1500 | P12: =O12-N12 -> #VALUE! | S12: LAST SERVICE DONE @ 1553 HRS. DT- 2026-07-01
A25: Generator
A26: Sr No | B26: Equipment | C26: Make/Model | D26: M/C Serial No | E26: Is in Use | F26: Hours Run | H26: Lube Oil Pressure | I26: Lube Oil Added | J26: Opning Running HRS | K26: Total Run Hours | L26: Closing HRS | M26: Last Service Hours | N26: Running HRS after last service | O26: Define hours | P26: Hours Remaining For Next Service. | Q26: Preventive /Predictive Maintenance Details | R26: Remarks | S26: LAST SERVICE DONE
E27: Yes/No | F27: DAY | G27: NIGHT | H27: psi/bar | I27: Liters
A28: 1 | B28: Rig Site Generator Set 1, 125 KVA | C28: Cummins | D28: P84089603 | E28: Yes | J28: ='11'!L28 -> #VALUE! | K28: =F28+G28 -> #VALUE! | L28: =J28+K28 -> #VALUE! | M28: 25366 | N28: =L28-M28 -> #VALUE! | O28: 500 | P28: =O28-N28 -> #VALUE! | S28: LAST SERVICE DONE @ 25366 HRS. DT- 2026-07-01
A29: 2 | B29: Rig Site Generator Set 2, 125 KVA | C29: Cummins | D29: P84089932 | E29: Yes | J29: ='11'!L29 -> #VALUE! | K29: =F29+G29 -> #VALUE! | L29: =J29+K29 -> #VALUE! | M29: 27383 | N29: =L29-M29 -> #VALUE! | O29: 500 | P29: =O29-N29 -> #VALUE! | S29: LAST SERVICE DONE @ 27383 HRS. DT- 2026-07-01
A30: 3 | B30: Rig Site Generator Set 3, 15 KVA | C30: Cummins | D30: 31295 | E30: Yes | J30: ='11'!L30 -> #VALUE! | K30: =F30+G30 -> #VALUE! | L30: =J30+K30 -> #VALUE! | M30: 637 | N30: =L30-M30 -> #VALUE! | O30: 500 | P30: =O30-N30 -> #VALUE! | S30: LAST SERVICE DONE @ 637 HRS. DT- 2026-07-01
A31: 4 | B31: DG-125 KVA SUPERNOVA | C31: SUPERNOVS | D31: SN-6003 | E31: Yes | J31: ='11'!L31 -> #VALUE! | K31: =F31+G31 -> #VALUE! | L31: =J31+K31 -> #VALUE! | M31: 1049 | N31: =L31-M31 -> #VALUE! | O31: 500 | P31: =O31-N31 -> #VALUE! | S31: LAST SERVICE DONE @ 1049 HRS. DT- 2026-07-01

Sheet 13
A1: Rig No: | B1: Rig 50-02 | C1: Daily Mechanical Report | P1: Date: | Q1: 13-08-2026
A2: Well No: | B2: PLAN
A3: Diesel Engines
A4: Sr No | B4: Equipment | C4: Make/Model | D4: M/C Serial No | E4: Is in Use | F4: Hours Run | H4: Lube Oil Pressure | I4: Lube Oil Added | J4: Opning Running HRS | K4: Total Run Hours | L4: Closing HRS | M4: Last Service Hours | N4: Running HRS after last service | O4: Define hours | P4: Hours Remaining For Next Service. | Q4: Preventive /Predictive Maintenance Details | R4: Remarks | S4: LAST SERVICE DONE
E5: Yes/No | F5: DAY | G5: NIGHT | H5: psi/bar | I5: Liters
A6: 1 | B6: Rig Engine | C6: CAT 09 | D6: JSC08784 | E6: Yes | J6: ='12'!L6 -> #VALUE! | K6: =F6+G6 -> #VALUE! | L6: =J6+K6 -> #VALUE! | M6: 35028 | N6: =L6-M6 -> #VALUE! | O6: 500 | P6: =O6-N6 -> #VALUE! | S6: LAST SERVICE DONE @ 35028 HRS. DT- 2026-07-01
A7: 2 | B7: Rig Carrier Transmission | C7: CAT 09 | D7: 8620008307 | E7: Yes | J7: ='12'!L7 -> #VALUE! | K7: =F7+G7 -> #VALUE! | L7: =J7+K7 -> #VALUE! | M7: 35024 | N7: =L7-M7 -> #VALUE! | O7: 500 | P7: =O7-N7 -> #VALUE! | S7: LAST SERVICE DONE @ 35024 HRS. DT- 2026-07-01
A8: 3 | B8: Mud Pump Engine | C8: CAT 15 | D8: BEM00178 | E8: Yes | J8: ='12'!L8 -> #VALUE! | K8: =F8+G8 -> #VALUE! | L8: =J8+K8 -> #VALUE! | M8: 28330 | N8: =L8-M8 -> #VALUE! | O8: 1500 | P8: =O8-N8 -> #VALUE! | S8: LAST SERVICE DONE @ 28330 HRS. DT- 2026-07-01
A9: 4 | B9: Mud pump transmission | C9: CAT 15 | D9: 2901750 | E9: Yes | J9: ='12'!L9 -> #VALUE! | K9: =F9+G9 -> #VALUE! | L9: =J9+K9 -> #VALUE! | M9: 28330 | N9: =L9-M9 -> #VALUE! | O9: 1500 | P9: =O9-N9 -> #VALUE! | S9: LAST SERVICE DONE @ 28330 HRS. DT- 2026-07-01
A10: 5 | B10: Air Compressor Electrical | C10: KIRLOSKAR | D10: PT 300 T | E10: Yes | J10: ='12'!L10 -> #VALUE! | K10: =F10+G10 -> #VALUE! | L10: =J10+K10 -> #VALUE! | M10: -200 | N10: =L10-M10 -> #VALUE! | O10: 500 | P10: =O10-N10 -> #VALUE! | S10: LAST SERVICE DONE @ -200 HRS. DT- 2026-07-01
A11: 6 | B11: Air Compressor Mechanical | C11: KIRLOSKAR | D11: 02.1281/2420149 | E11: Yes | J11: ='12'!L11 -> #VALUE! | K11: =F11+G11 -> #VALUE! | L11: =J11+K11 -> #VALUE! | M11: 907 | N11: =L11-M11 -> #VALUE! | O11: 500 | P11: =O11-N11 -> #VALUE! | S11: LAST SERVICE DONE @ 907 HRS. DT- 2026-07-01
A12: 7 | B12: Fire Pump | C12: KIRLOSKAR | D12: 4H.2709.20/1220003 | E12: Yes | J12: ='12'!L12 -> #VALUE! | K12: =F12+G12 -> #VALUE! | L12: =J12+K12 -> #VALUE! | M12: 1553 | N12: =L12-M12 -> #VALUE! | O12: 1500 | P12: =O12-N12 -> #VALUE! | S12: LAST SERVICE DONE @ 1553 HRS. DT- 2026-07-01
A25: Generator
A26: Sr No | B26: Equipment | C26: Make/Model | D26: M/C Serial No | E26: Is in Use | F26: Hours Run | H26: Lube Oil Pressure | I26: Lube Oil Added | J26: Opning Running HRS | K26: Total Run Hours | L26: Closing HRS | M26: Last Service Hours | N26: Running HRS after last service | O26: Define hours | P26: Hours Remaining For Next Service. | Q26: Preventive /Predictive Maintenance Details | R26: Remarks | S26: LAST SERVICE DONE
E27: Yes/No | F27: DAY | G27: NIGHT | H27: psi/bar | I27: Liters
A28: 1 | B28: Rig Site Generator Set 1, 125 KVA | C28: Cummins | D28: P84089603 | E28: Yes | J28: ='12'!L28 -> #VALUE! | K28: =F28+G28 -> #VALUE! | L28: =J28+K28 -> #VALUE! | M28: 25366 | N28: =L28-M28 -> #VALUE! | O28: 500 | P28: =O28-N28 -> #VALUE! | S28: LAST SERVICE DONE @ 25366 HRS. DT- 2026-07-01
A29: 2 | B29: Rig Site Generator Set 2, 125 KVA | C29: Cummins | D29: P84089932 | E29: Yes | J29: ='12'!L29 -> #VALUE! | K29: =F29+G29 -> #VALUE! | L29: =J29+K29 -> #VALUE! | M29: 27383 | N29: =L29-M29 -> #VALUE! | O29: 500 | P29: =O29-N29 -> #VALUE! | S29: LAST SERVICE DONE @ 27383 HRS. DT- 2026-07-01
A30: 3 | B30: Rig Site Generator Set 3, 15 KVA | C30: Cummins | D30: 31295 | E30: Yes | J30: ='12'!L30 -> #VALUE! | K30: =F30+G30 -> #VALUE! | L30: =J30+K30 -> #VALUE! | M30: 637 | N30: =L30-M30 -> #VALUE! | O30: 500 | P30: =O30-N30 -> #VALUE! | S30: LAST SERVICE DONE @ 637 HRS. DT- 2026-07-01
A31: 4 | B31: DG-125 KVA SUPERNOVA | C31: SUPERNOVS | D31: SN-6003 | E31: Yes | J31: ='12'!L31 -> #VALUE! | K31: =F31+G31 -> #VALUE! | L31: =J31+K31 -> #VALUE! | M31: 1049 | N31: =L31-M31 -> #VALUE! | O31: 500 | P31: =O31-N31 -> #VALUE! | S31: LAST SERVICE DONE @ 1049 HRS. DT- 2026-07-01

Sheet 14
A1: Rig No: | B1: Rig 50-02 | C1: Daily Mechanical Report | P1: Date: | Q1: 14-08-2026
A2: Well No: | B2: PLAN
A3: Diesel Engines
A4: Sr No | B4: Equipment | C4: Make/Model | D4: M/C Serial No | E4: Is in Use | F4: Hours Run | H4: Lube Oil Pressure | I4: Lube Oil Added | J4: Opning Running HRS | K4: Total Run Hours | L4: Closing HRS | M4: Last Service Hours | N4: Running HRS after last service | O4: Define hours | P4: Hours Remaining For Next Service. | Q4: Preventive /Predictive Maintenance Details | R4: Remarks | S4: LAST SERVICE DONE
E5: Yes/No | F5: DAY | G5: NIGHT | H5: psi/bar | I5: Liters
A6: 1 | B6: Rig Engine | C6: CAT 09 | D6: JSC08784 | E6: Yes | J6: ='13'!L6 -> #VALUE! | K6: =F6+G6 -> #VALUE! | L6: =J6+K6 -> #VALUE! | M6: 35028 | N6: =L6-M6 -> #VALUE! | O6: 500 | P6: =O6-N6 -> #VALUE! | S6: LAST SERVICE DONE @ 35028 HRS. DT- 2026-07-01
A7: 2 | B7: Rig Carrier Transmission | C7: CAT 09 | D7: 8620008307 | E7: Yes | J7: ='13'!L7 -> #VALUE! | K7: =F7+G7 -> #VALUE! | L7: =J7+K7 -> #VALUE! | M7: 35024 | N7: =L7-M7 -> #VALUE! | O7: 500 | P7: =O7-N7 -> #VALUE! | S7: LAST SERVICE DONE @ 35024 HRS. DT- 2026-07-01
A8: 3 | B8: Mud Pump Engine | C8: CAT 15 | D8: BEM00178 | E8: Yes | J8: ='13'!L8 -> #VALUE! | K8: =F8+G8 -> #VALUE! | L8: =J8+K8 -> #VALUE! | M8: 28330 | N8: =L8-M8 -> #VALUE! | O8: 1500 | P8: =O8-N8 -> #VALUE! | S8: LAST SERVICE DONE @ 28330 HRS. DT- 2026-07-01
A9: 4 | B9: Mud pump transmission | C9: CAT 15 | D9: 2901750 | E9: Yes | J9: ='13'!L9 -> #VALUE! | K9: =F9+G9 -> #VALUE! | L9: =J9+K9 -> #VALUE! | M9: 28330 | N9: =L9-M9 -> #VALUE! | O9: 1500 | P9: =O9-N9 -> #VALUE! | S9: LAST SERVICE DONE @ 28330 HRS. DT- 2026-07-01
A10: 5 | B10: Air Compressor Electrical | C10: KIRLOSKAR | D10: PT 300 T | E10: Yes | J10: ='13'!L10 -> #VALUE! | K10: =F10+G10 -> #VALUE! | L10: =J10+K10 -> #VALUE! | M10: -200 | N10: =L10-M10 -> #VALUE! | O10: 500 | P10: =O10-N10 -> #VALUE! | S10: LAST SERVICE DONE @ -200 HRS. DT- 2026-07-01
A11: 6 | B11: Air Compressor Mechanical | C11: KIRLOSKAR | D11: 02.1281/2420149 | E11: Yes | J11: ='13'!L11 -> #VALUE! | K11: =F11+G11 -> #VALUE! | L11: =J11+K11 -> #VALUE! | M11: 907 | N11: =L11-M11 -> #VALUE! | O11: 500 | P11: =O11-N11 -> #VALUE! | S11: LAST SERVICE DONE @ 907 HRS. DT- 2026-07-01
A12: 7 | B12: Fire Pump | C12: KIRLOSKAR | D12: 4H.2709.20/1220003 | E12: Yes | J12: ='13'!L12 -> #VALUE! | K12: =F12+G12 -> #VALUE! | L12: =J12+K12 -> #VALUE! | M12: 1553 | N12: =L12-M12 -> #VALUE! | O12: 1500 | P12: =O12-N12 -> #VALUE! | S12: LAST SERVICE DONE @ 1553 HRS. DT- 2026-07-01
A25: Generator
A26: Sr No | B26: Equipment | C26: Make/Model | D26: M/C Serial No | E26: Is in Use | F26: Hours Run | H26: Lube Oil Pressure | I26: Lube Oil Added | J26: Opning Running HRS | K26: Total Run Hours | L26: Closing HRS | M26: Last Service Hours | N26: Running HRS after last service | O26: Define hours | P26: Hours Remaining For Next Service. | Q26: Preventive /Predictive Maintenance Details | R26: Remarks | S26: LAST SERVICE DONE
E27: Yes/No | F27: DAY | G27: NIGHT | H27: psi/bar | I27: Liters
A28: 1 | B28: Rig Site Generator Set 1, 125 KVA | C28: Cummins | D28: P84089603 | E28: Yes | J28: ='13'!L28 -> #VALUE! | K28: =F28+G28 -> #VALUE! | L28: =J28+K28 -> #VALUE! | M28: 25366 | N28: =L28-M28 -> #VALUE! | O28: 500 | P28: =O28-N28 -> #VALUE! | S28: LAST SERVICE DONE @ 25366 HRS. DT- 2026-07-01
A29: 2 | B29: Rig Site Generator Set 2, 125 KVA | C29: Cummins | D29: P84089932 | E29: Yes | J29: ='13'!L29 -> #VALUE! | K29: =F29+G29 -> #VALUE! | L29: =J29+K29 -> #VALUE! | M29: 27383 | N29: =L29-M29 -> #VALUE! | O29: 500 | P29: =O29-N29 -> #VALUE! | S29: LAST SERVICE DONE @ 27383 HRS. DT- 2026-07-01
A30: 3 | B30: Rig Site Generator Set 3, 15 KVA | C30: Cummins | D30: 31295 | E30: Yes | J30: ='13'!L30 -> #VALUE! | K30: =F30+G30 -> #VALUE! | L30: =J30+K30 -> #VALUE! | M30: 637 | N30: =L30-M30 -> #VALUE! | O30: 500 | P30: =O30-N30 -> #VALUE! | S30: LAST SERVICE DONE @ 637 HRS. DT- 2026-07-01
A31: 4 | B31: DG-125 KVA SUPERNOVA | C31: SUPERNOVS | D31: SN-6003 | E31: Yes | J31: ='13'!L31 -> #VALUE! | K31: =F31+G31 -> #VALUE! | L31: =J31+K31 -> #VALUE! | M31: 1049 | N31: =L31-M31 -> #VALUE! | O31: 500 | P31: =O31-N31 -> #VALUE! | S31: LAST SERVICE DONE @ 1049 HRS. DT- 2026-07-01

Sheet 15
A1: Rig No: | B1: Rig 50-02 | C1: Daily Mechanical Report | P1: Date: | Q1: 15-08-2026
A2: Well No: | B2: PLAN
A3: Diesel Engines
A4: Sr No | B4: Equipment | C4: Make/Model | D4: M/C Serial No | E4: Is in Use | F4: Hours Run | H4: Lube Oil Pressure | I4: Lube Oil Added | J4: Opning Running HRS | K4: Total Run Hours | L4: Closing HRS | M4: Last Service Hours | N4: Running HRS after last service | O4: Define hours | P4: Hours Remaining For Next Service. | Q4: Preventive /Predictive Maintenance Details | R4: Remarks | S4: LAST SERVICE DONE
